Workbook

Sheet Guidance Sheet
B2: Malnutrition Risk Monitoring Tool Guidance Sheet
B3: 1 | C3: This tool has been created based off of BAPEN Guidance. For more details, please see: | I3: =HYPERLINK(Validation!A41,Validation!A42) -> BAPEN
B4: 2 | C4: The Malnutrition Risk Monitoring Tool is made up of 4 types of worksheets; Weight Overview, Monthly Data Tabs (Jan - Dec), an Action Plan tab, and a Trend Analysis tab.
B5: 3 | C5: The Weight Overview tab is for the adults weight from the previous years last 6 months to be recorded to allow for the "Highest Weight in the past 3-6 months" (Column H) comparison to work in the current years January to June Tabs. Once weights are entered into the January to December tabs, these will automatically populate the Current Year information on the Weight Overview tab. This allows for the and "Weight Difference Between [Current] & [Previous Month]" (Column F) and "Highest Weight in the past 3-6 months" (Column H). The Current Year information does not need any manual data entry and the cells are protected to ensure formulas are not accidently deleted. If the weight history if unknown, these cells can remain blank, or you can write "Unknown". The calculations for the following months weight comparisions will N/A. Without at least 3 months of weight history the MUST score will be calculated on BMI only
B6: 4 | C6: It is important that all adults are listed on the Weight Overview worksheet, even if they were not in the service for the previous year. This is due to how the names effect the formulas and they must be uniform across worksheets. The "Name" column (B) on the Monthly Data Tabs will offer a drop down selection of the names that exist on the Weight Overview tab. If you have 2 adults with the same name, please ensure there is something unique to each one, such as two John Smiths could include their room numbers e.g "John Smith Rm1" and "John Smith Rm7"
B7: 5 | C7: The Monthly Data Tabs have 1 tab for each month of the year. Each worksheet requires data to be entered into the following columns: - "Name" (Column B) (Selected via drop down list (see above note 3)) - "[Month] weight (kg)" (Column C) - "Date [Month] Weight Taken" (Column D) - "Is the adults weight stable? (Yes/No) (Column K) - "If Weight has been lost, is this Planned? (Yes/No)" (Column L) - "Is this BMI/Weight/MUST typical for the adult? (Yes/No)" (Column O) - "If Yes, what would indicate a concern/is atypical for this adult?" (Column P) - "Is there any explanation for BMI/Weight/MUST changes? (Yes/No)" (Column Q) - "If Yes, please detail" (Column R) - "Is the adult on a special/fortified diet? (e.g. cultural, dietary restrictions, fortified etc) (Yes/No)" (Column S) - "If Yes, give details" (Column T) - "If the adult has been assessed for texture-modified Fluid, please record the level below" (Column U) - "If the adult has been assessed for texture-modified Food, please record the level below" (Column V) - "Is action required? (Yes/No)" (Column W) - "Date Care Plan & Any Relevent Risk Assessments Last Updated" (Column X) - "Comments" (Column Y) Columns O, Q & S are validated to provide a "Yes" or "No" response. This is most important for Column L as it effects the "[Month] MUST Risk Score" (Column M) calculation and the calculations on the Trend Analysis tab. Columns U & V are validated to provide the IDDSI levels in a dropdown list. All other columns do not require editing as they contain formulas, which will populate them automatically based off of current & previous sheet inputs. These cells are protected and will not allow editing, this is to ensure the formulas are not accidently altered or deleted.
B8: 6 | C8: The monthly tabs are protected to ensure formulas are not accidently deleted or edited. If additional rows are needed the sheet needs to be unprotected. To do this, Right Click on the Tab > Select Unprotect Sheet. The protection does not include a password. Once the tab is unprotected please highlight an already existing row in the table > Right Click > 'Insert' > 'Table Rows Above'. Alternatively, you can highlight an already existing row in the table and select the 'Insert' option from the 'Home' ribbon at the top of the document. This method should ensure that any formulas copy down into the new rows appropriately. If this does not happen, please click the bottom right hand corner of the last cell with a formula present when you see a '+' cursor and drag down until all new cells are filled. Repeat this action for all columns that have a formula present. Once changes have been made, please remember to reportect the tabs by once again Right Click on the Tab > Select Protect Sheet > Select OK.
B9: 7 | C9: The "[Month] MUST Score" (Column M) has a formula in place to calculate the score. It is important for this to work correctly that the "Is this Weight Loss Planned? (Yes/No)" (Column L) contains appropriate "Yes" or "No" response. if a "Yes" response is recorded in Column L, this will give the Unplanned Weight Loss section of the below calculation a 0 score. If there is weight gain instead of loss, this column can be kept blank.
B10: 8 | C10: MUST Score Calculation Process
C11: BMI Score | F11: + | H11: Unplanned Weight Loss Score
C12: If BMI is greater than (>) 20 | E12: = 0 | H12: Is weight loss is less than (<) 5% | J12: = 0
C13: If BMI is between 18.5 and 20 | E13: = 1 | H13: If weight loss is between 5% and 10% | J13: = 1
C14: If BMI is less than (<) 18.5 | E14: = 2 | H14: If weight loss greater than (>) 10% | J14: = 2
B15: 9 | C15: The "[Month] MUST Risk" column (N) is formatted to automatically populate level of Risk based off of the "[Month] MUST Score" (M) Both "MUST Score" (M) and "MUST Risk" (N) have conditional formatting in place to RAG Rate the cells based on the calculated value as follows:
C16: Total Must Score | E16: MUST Risk | I16: RAG Rating
C17: 0 | E17: Low | I17: Green
C18: 1 | E18: Medium | I18: Amber
C19: 2 or More | E19: High | I19: Red
B20: 10 | C20: Actions to take based of MUST Risk Rating
C21: Low | D21: Routine Care | F21: Repeat screening - monthly
C22: Medium | D22: Observe | F22: Document dietary intake for 3 days: If Adequate – Little concern – Repeat screening at least monthly If Inadequate – Clinical concern – Follow local policy, set goals, improve and increase overall nutritional intake, monitor and review care plan regularly
C23: High | D23: Treat (Unless detrimental or no benefit is expected from nutritional support e.g. imminent death.) | F23: - Set goals, improve and increase overall nutritional intake. - Monitor and review care plan monthly - Implement local policy - Consider if referral to Nutritional Support Team or Dietican is appropriate: If Yes, complete referral and document. If No, document reasoning.
B24: 11 | C24: At the end of the tabs for all months of the year there is an Action Plan tab. This should be completed when a required action is identified, and later reviewed.
B25: 12 | C25: The last tab in this tool is the Trend Analysis Tab. This has been formulated to count, for each month: - The number of adults weighed - Those within the different BMI threseholds - Those within different MUST Risk Scores - Those with diet considerations in place - Those with unplanned weight loss meeting various criteria (BMI/MUST/Diet Considerations) The data for these is pulled from the corresponding columns on each Months tab. There is also a calulation of these catagories per Quater, to enable a greater timeframe reveiw of any potential trends. These formulas are designed only to count an adult once if they appear in more than one month of the Quater. The Trend Analaysis tab has 4 columns which the will need to be completed manually to show the Trend Analysis process is being completed and considered. These are: - "Are there any known considerations to be aware of that may have an effect on any weight loss seen? (Change of kitchen staff, menu, appitite, weather etc)" (Column W) - "What trends have been identied in any overall weight loss seen?" (Column X) - "What actions have been identifed as needed, to address any trends noted for unplanned weight loss" (Column Y) - "If last months/quarter trend anayslis had actions identifed, review these and comment on if they have had an effect or if further action is needed" (Column Z) Please note: Some of the Quarter formulas will show a #CALC! error, this should only show if there is no data in the applicable months tabs. Once data is entered, the formula should count the entered data. Any Column with a formula present is protected to ensure the formulas are not accidently deleted or edited.

Sheet Weight Overview
B2: Weight Overview | D2: Previous Year | J2: Current Year
B3: Name | C3: Height (cm) | D3: July Weight (kg) | E3: August Weight (kg) | F3: September Weight (kg) | G3: October Weight (kg) | H3: November Weight (kg) | I3: December Weight (kg) | J3: January Weight (kg) | K3: February Weight (kg) | L3: March Weight (kg) | M3: April Weight (kg) | N3: May Weight (kg) | O3: June Weight (kg) | P3: July Weight (kg) | Q3: August Weight (kg) | R3: September Weight (kg) | S3: October Weight (kg) | T3: November Weight (kg) | U3: December Weight (kg)
J4: =IF(Overview[[#This Row],[Name]]="","",_xlfn.XLOOKUP(Overview[[#This Row],[Name]],Jan!B:B,Jan!C:C,"")) | K4: =IF(Overview[[#This Row],[Name]]="","",_xlfn.XLOOKUP(Overview[[#This Row],[Name]],Feb!B:B,Feb!C:C,"")) | L4: =IF(Overview[[#This Row],[Name]]="","",_xlfn.XLOOKUP(Overview[[#This Row],[Name]],Mar!B:B,Mar!C:C,"")) | M4: =IF(Overview[[#This Row],[Name]]="","",_xlfn.XLOOKUP(Overview[[#This Row],[Name]],Apr!B:B,Apr!C:C,"")) | N4: =IF(Overview[[#This Row],[Name]]="","",_xlfn.XLOOKUP(Overview[[#This Row],[Name]],May!B:B,May!C:C,"")) | O4: =IF(Overview[[#This Row],[Name]]="","",_xlfn.XLOOKUP(Overview[[#This Row],[Name]],Jun!B:B,Jun!C:C,"")) | P4: =IF(Overview[[#This Row],[Name]]="","",_xlfn.XLOOKUP(Overview[[#This Row],[Name]],Jul!B:B,Jul!C:C,"")) | Q4: =IF(Overview[[#This Row],[Name]]="","",_xlfn.XLOOKUP(Overview[[#This Row],[Name]],Aug!B:B,Aug!C:C,"")) | R4: =IF(Overview[[#This Row],[Name]]="","",_xlfn.XLOOKUP(Overview[[#This Row],[Name]],Sep!B:B,Sep!C:C,"")) | S4: =IF(Overview[[#This Row],[Name]]="","",_xlfn.XLOOKUP(Overview[[#This Row],[Name]],Oct!B:B,Oct!C:C,"")) | T4: =IF(Overview[[#This Row],[Name]]="","",_xlfn.XLOOKUP(Overview[[#This Row],[Name]],Nov!B:B,Nov!C:C,"")) | U4: =IF(Overview[[#This Row],[Name]]="","",_xlfn.XLOOKUP(Overview[[#This Row],[Name]],Dec!B:B,Dec!C:C,""))
J5: =IF(Overview[[#This Row],[Name]]="","",_xlfn.XLOOKUP(Overview[[#This Row],[Name]],Jan!B:B,Jan!C:C,"")) | K5: =IF(Overview[[#This Row],[Name]]="","",_xlfn.XLOOKUP(Overview[[#This Row],[Name]],Feb!B:B,Feb!C:C,"")) | L5: =IF(Overview[[#This Row],[Name]]="","",_xlfn.XLOOKUP(Overview[[#This Row],[Name]],Mar!B:B,Mar!C:C,"")) | M5: =IF(Overview[[#This Row],[Name]]="","",_xlfn.XLOOKUP(Overview[[#This Row],[Name]],Apr!B:B,Apr!C:C,"")) | N5: =IF(Overview[[#This Row],[Name]]="","",_xlfn.XLOOKUP(Overview[[#This Row],[Name]],May!B:B,May!C:C,"")) | O5: =IF(Overview[[#This Row],[Name]]="","",_xlfn.XLOOKUP(Overview[[#This Row],[Name]],Jun!B:B,Jun!C:C,"")) | P5: =IF(Overview[[#This Row],[Name]]="","",_xlfn.XLOOKUP(Overview[[#This Row],[Name]],Jul!B:B,Jul!C:C,"")) | Q5: =IF(Overview[[#This Row],[Name]]="","",_xlfn.XLOOKUP(Overview[[#This Row],[Name]],Aug!B:B,Aug!C:C,"")) | R5: =IF(Overview[[#This Row],[Name]]="","",_xlfn.XLOOKUP(Overview[[#This Row],[Name]],Sep!B:B,Sep!C:C,"")) | S5: =IF(Overview[[#This Row],[Name]]="","",_xlfn.XLOOKUP(Overview[[#This Row],[Name]],Oct!B:B,Oct!C:C,"")) | T5: =IF(Overview[[#This Row],[Name]]="","",_xlfn.XLOOKUP(Overview[[#This Row],[Name]],Nov!B:B,Nov!C:C,"")) | U5: =IF(Overview[[#This Row],[Name]]="","",_xlfn.XLOOKUP(Overview[[#This Row],[Name]],Dec!B:B,Dec!C:C,""))
J6: =IF(Overview[[#This Row],[Name]]="","",_xlfn.XLOOKUP(Overview[[#This Row],[Name]],Jan!B:B,Jan!C:C,"")) | K6: =IF(Overview[[#This Row],[Name]]="","",_xlfn.XLOOKUP(Overview[[#This Row],[Name]],Feb!B:B,Feb!C:C,"")) | L6: =IF(Overview[[#This Row],[Name]]="","",_xlfn.XLOOKUP(Overview[[#This Row],[Name]],Mar!B:B,Mar!C:C,"")) | M6: =IF(Overview[[#This Row],[Name]]="","",_xlfn.XLOOKUP(Overview[[#This Row],[Name]],Apr!B:B,Apr!C:C,"")) | N6: =IF(Overview[[#This Row],[Name]]="","",_xlfn.XLOOKUP(Overview[[#This Row],[Name]],May!B:B,May!C:C,"")) | O6: =IF(Overview[[#This Row],[Name]]="","",_xlfn.XLOOKUP(Overview[[#This Row],[Name]],Jun!B:B,Jun!C:C,"")) | P6: =IF(Overview[[#This Row],[Name]]="","",_xlfn.XLOOKUP(Overview[[#This Row],[Name]],Jul!B:B,Jul!C:C,"")) | Q6: =IF(Overview[[#This Row],[Name]]="","",_xlfn.XLOOKUP(Overview[[#This Row],[Name]],Aug!B:B,Aug!C:C,"")) | R6: =IF(Overview[[#This Row],[Name]]="","",_xlfn.XLOOKUP(Overview[[#This Row],[Name]],Sep!B:B,Sep!C:C,"")) | S6: =IF(Overview[[#This Row],[Name]]="","",_xlfn.XLOOKUP(Overview[[#This Row],[Name]],Oct!B:B,Oct!C:C,"")) | T6: =IF(Overview[[#This Row],[Name]]="","",_xlfn.XLOOKUP(Overview[[#This Row],[Name]],Nov!B:B,Nov!C:C,"")) | U6: =IF(Overview[[#This Row],[Name]]="","",_xlfn.XLOOKUP(Overview[[#This Row],[Name]],Dec!B:B,Dec!C:C,""))
J7: =IF(Overview[[#This Row],[Name]]="","",_xlfn.XLOOKUP(Overview[[#This Row],[Name]],Jan!B:B,Jan!C:C,"")) | K7: =IF(Overview[[#This Row],[Name]]="","",_xlfn.XLOOKUP(Overview[[#This Row],[Name]],Feb!B:B,Feb!C:C,"")) | L7: =IF(Overview[[#This Row],[Name]]="","",_xlfn.XLOOKUP(Overview[[#This Row],[Name]],Mar!B:B,Mar!C:C,"")) | M7: =IF(Overview[[#This Row],[Name]]="","",_xlfn.XLOOKUP(Overview[[#This Row],[Name]],Apr!B:B,Apr!C:C,"")) | N7: =IF(Overview[[#This Row],[Name]]="","",_xlfn.XLOOKUP(Overview[[#This Row],[Name]],May!B:B,May!C:C,"")) | O7: =IF(Overview[[#This Row],[Name]]="","",_xlfn.XLOOKUP(Overview[[#This Row],[Name]],Jun!B:B,Jun!C:C,"")) | P7: =IF(Overview[[#This Row],[Name]]="","",_xlfn.XLOOKUP(Overview[[#This Row],[Name]],Jul!B:B,Jul!C:C,"")) | Q7: =IF(Overview[[#This Row],[Name]]="","",_xlfn.XLOOKUP(Overview[[#This Row],[Name]],Aug!B:B,Aug!C:C,"")) | R7: =IF(Overview[[#This Row],[Name]]="","",_xlfn.XLOOKUP(Overview[[#This Row],[Name]],Sep!B:B,Sep!C:C,"")) | S7: =IF(Overview[[#This Row],[Name]]="","",_xlfn.XLOOKUP(Overview[[#This Row],[Name]],Oct!B:B,Oct!C:C,"")) | T7: =IF(Overview[[#This Row],[Name]]="","",_xlfn.XLOOKUP(Overview[[#This Row],[Name]],Nov!B:B,Nov!C:C,"")) | U7: =IF(Overview[[#This Row],[Name]]="","",_xlfn.XLOOKUP(Overview[[#This Row],[Name]],Dec!B:B,Dec!C:C,""))
J8: =IF(Overview[[#This Row],[Name]]="","",_xlfn.XLOOKUP(Overview[[#This Row],[Name]],Jan!B:B,Jan!C:C,"")) | K8: =IF(Overview[[#This Row],[Name]]="","",_xlfn.XLOOKUP(Overview[[#This Row],[Name]],Feb!B:B,Feb!C:C,"")) | L8: =IF(Overview[[#This Row],[Name]]="","",_xlfn.XLOOKUP(Overview[[#This Row],[Name]],Mar!B:B,Mar!C:C,"")) | M8: =IF(Overview[[#This Row],[Name]]="","",_xlfn.XLOOKUP(Overview[[#This Row],[Name]],Apr!B:B,Apr!C:C,"")) | N8: =IF(Overview[[#This Row],[Name]]="","",_xlfn.XLOOKUP(Overview[[#This Row],[Name]],May!B:B,May!C:C,"")) | O8: =IF(Overview[[#This Row],[Name]]="","",_xlfn.XLOOKUP(Overview[[#This Row],[Name]],Jun!B:B,Jun!C:C,"")) | P8: =IF(Overview[[#This Row],[Name]]="","",_xlfn.XLOOKUP(Overview[[#This Row],[Name]],Jul!B:B,Jul!C:C,"")) | Q8: =IF(Overview[[#This Row],[Name]]="","",_xlfn.XLOOKUP(Overview[[#This Row],[Name]],Aug!B:B,Aug!C:C,"")) | R8: =IF(Overview[[#This Row],[Name]]="","",_xlfn.XLOOKUP(Overview[[#This Row],[Name]],Sep!B:B,Sep!C:C,"")) | S8: =IF(Overview[[#This Row],[Name]]="","",_xlfn.XLOOKUP(Overview[[#This Row],[Name]],Oct!B:B,Oct!C:C,"")) | T8: =IF(Overview[[#This Row],[Name]]="","",_xlfn.XLOOKUP(Overview[[#This Row],[Name]],Nov!B:B,Nov!C:C,"")) | U8: =IF(Overview[[#This Row],[Name]]="","",_xlfn.XLOOKUP(Overview[[#This Row],[Name]],Dec!B:B,Dec!C:C,""))
J9: =IF(Overview[[#This Row],[Name]]="","",_xlfn.XLOOKUP(Overview[[#This Row],[Name]],Jan!B:B,Jan!C:C,"")) | K9: =IF(Overview[[#This Row],[Name]]="","",_xlfn.XLOOKUP(Overview[[#This Row],[Name]],Feb!B:B,Feb!C:C,"")) | L9: =IF(Overview[[#This Row],[Name]]="","",_xlfn.XLOOKUP(Overview[[#This Row],[Name]],Mar!B:B,Mar!C:C,"")) | M9: =IF(Overview[[#This Row],[Name]]="","",_xlfn.XLOOKUP(Overview[[#This Row],[Name]],Apr!B:B,Apr!C:C,"")) | N9: =IF(Overview[[#This Row],[Name]]="","",_xlfn.XLOOKUP(Overview[[#This Row],[Name]],May!B:B,May!C:C,"")) | O9: =IF(Overview[[#This Row],[Name]]="","",_xlfn.XLOOKUP(Overview[[#This Row],[Name]],Jun!B:B,Jun!C:C,"")) | P9: =IF(Overview[[#This Row],[Name]]="","",_xlfn.XLOOKUP(Overview[[#This Row],[Name]],Jul!B:B,Jul!C:C,"")) | Q9: =IF(Overview[[#This Row],[Name]]="","",_xlfn.XLOOKUP(Overview[[#This Row],[Name]],Aug!B:B,Aug!C:C,"")) | R9: =IF(Overview[[#This Row],[Name]]="","",_xlfn.XLOOKUP(Overview[[#This Row],[Name]],Sep!B:B,Sep!C:C,"")) | S9: =IF(Overview[[#This Row],[Name]]="","",_xlfn.XLOOKUP(Overview[[#This Row],[Name]],Oct!B:B,Oct!C:C,"")) | T9: =IF(Overview[[#This Row],[Name]]="","",_xlfn.XLOOKUP(Overview[[#This Row],[Name]],Nov!B:B,Nov!C:C,"")) | U9: =IF(Overview[[#This Row],[Name]]="","",_xlfn.XLOOKUP(Overview[[#This Row],[Name]],Dec!B:B,Dec!C:C,""))
J10: =IF(Overview[[#This Row],[Name]]="","",_xlfn.XLOOKUP(Overview[[#This Row],[Name]],Jan!B:B,Jan!C:C,"")) | K10: =IF(Overview[[#This Row],[Name]]="","",_xlfn.XLOOKUP(Overview[[#This Row],[Name]],Feb!B:B,Feb!C:C,"")) | L10: =IF(Overview[[#This Row],[Name]]="","",_xlfn.XLOOKUP(Overview[[#This Row],[Name]],Mar!B:B,Mar!C:C,"")) | M10: =IF(Overview[[#This Row],[Name]]="","",_xlfn.XLOOKUP(Overview[[#This Row],[Name]],Apr!B:B,Apr!C:C,"")) | N10: =IF(Overview[[#This Row],[Name]]="","",_xlfn.XLOOKUP(Overview[[#This Row],[Name]],May!B:B,May!C:C,"")) | O10: =IF(Overview[[#This Row],[Name]]="","",_xlfn.XLOOKUP(Overview[[#This Row],[Name]],Jun!B:B,Jun!C:C,"")) | P10: =IF(Overview[[#This Row],[Name]]="","",_xlfn.XLOOKUP(Overview[[#This Row],[Name]],Jul!B:B,Jul!C:C,"")) | Q10: =IF(Overview[[#This Row],[Name]]="","",_xlfn.XLOOKUP(Overview[[#This Row],[Name]],Aug!B:B,Aug!C:C,"")) | R10: =IF(Overview[[#This Row],[Name]]="","",_xlfn.XLOOKUP(Overview[[#This Row],[Name]],Sep!B:B,Sep!C:C,"")) | S10: =IF(Overview[[#This Row],[Name]]="","",_xlfn.XLOOKUP(Overview[[#This Row],[Name]],Oct!B:B,Oct!C:C,"")) | T10: =IF(Overview[[#This Row],[Name]]="","",_xlfn.XLOOKUP(Overview[[#This Row],[Name]],Nov!B:B,Nov!C:C,"")) | U10: =IF(Overview[[#This Row],[Name]]="","",_xlfn.XLOOKUP(Overview[[#This Row],[Name]],Dec!B:B,Dec!C:C,""))
J11: =IF(Overview[[#This Row],[Name]]="","",_xlfn.XLOOKUP(Overview[[#This Row],[Name]],Jan!B:B,Jan!C:C,"")) | K11: =IF(Overview[[#This Row],[Name]]="","",_xlfn.XLOOKUP(Overview[[#This Row],[Name]],Feb!B:B,Feb!C:C,"")) | L11: =IF(Overview[[#This Row],[Name]]="","",_xlfn.XLOOKUP(Overview[[#This Row],[Name]],Mar!B:B,Mar!C:C,"")) | M11: =IF(Overview[[#This Row],[Name]]="","",_xlfn.XLOOKUP(Overview[[#This Row],[Name]],Apr!B:B,Apr!C:C,"")) | N11: =IF(Overview[[#This Row],[Name]]="","",_xlfn.XLOOKUP(Overview[[#This Row],[Name]],May!B:B,May!C:C,"")) | O11: =IF(Overview[[#This Row],[Name]]="","",_xlfn.XLOOKUP(Overview[[#This Row],[Name]],Jun!B:B,Jun!C:C,"")) | P11: =IF(Overview[[#This Row],[Name]]="","",_xlfn.XLOOKUP(Overview[[#This Row],[Name]],Jul!B:B,Jul!C:C,"")) | Q11: =IF(Overview[[#This Row],[Name]]="","",_xlfn.XLOOKUP(Overview[[#This Row],[Name]],Aug!B:B,Aug!C:C,"")) | R11: =IF(Overview[[#This Row],[Name]]="","",_xlfn.XLOOKUP(Overview[[#This Row],[Name]],Sep!B:B,Sep!C:C,"")) | S11: =IF(Overview[[#This Row],[Name]]="","",_xlfn.XLOOKUP(Overview[[#This Row],[Name]],Oct!B:B,Oct!C:C,"")) | T11: =IF(Overview[[#This Row],[Name]]="","",_xlfn.XLOOKUP(Overview[[#This Row],[Name]],Nov!B:B,Nov!C:C,"")) | U11: =IF(Overview[[#This Row],[Name]]="","",_xlfn.XLOOKUP(Overview[[#This Row],[Name]],Dec!B:B,Dec!C:C,""))
J12: =IF(Overview[[#This Row],[Name]]="","",_xlfn.XLOOKUP(Overview[[#This Row],[Name]],Jan!B:B,Jan!C:C,"")) | K12: =IF(Overview[[#This Row],[Name]]="","",_xlfn.XLOOKUP(Overview[[#This Row],[Name]],Feb!B:B,Feb!C:C,"")) | L12: =IF(Overview[[#This Row],[Name]]="","",_xlfn.XLOOKUP(Overview[[#This Row],[Name]],Mar!B:B,Mar!C:C,"")) | M12: =IF(Overview[[#This Row],[Name]]="","",_xlfn.XLOOKUP(Overview[[#This Row],[Name]],Apr!B:B,Apr!C:C,"")) | N12: =IF(Overview[[#This Row],[Name]]="","",_xlfn.XLOOKUP(Overview[[#This Row],[Name]],May!B:B,May!C:C,"")) | O12: =IF(Overview[[#This Row],[Name]]="","",_xlfn.XLOOKUP(Overview[[#This Row],[Name]],Jun!B:B,Jun!C:C,"")) | P12: =IF(Overview[[#This Row],[Name]]="","",_xlfn.XLOOKUP(Overview[[#This Row],[Name]],Jul!B:B,Jul!C:C,"")) | Q12: =IF(Overview[[#This Row],[Name]]="","",_xlfn.XLOOKUP(Overview[[#This Row],[Name]],Aug!B:B,Aug!C:C,"")) | R12: =IF(Overview[[#This Row],[Name]]="","",_xlfn.XLOOKUP(Overview[[#This Row],[Name]],Sep!B:B,Sep!C:C,"")) | S12: =IF(Overview[[#This Row],[Name]]="","",_xlfn.XLOOKUP(Overview[[#This Row],[Name]],Oct!B:B,Oct!C:C,"")) | T12: =IF(Overview[[#This Row],[Name]]="","",_xlfn.XLOOKUP(Overview[[#This Row],[Name]],Nov!B:B,Nov!C:C,"")) | U12: =IF(Overview[[#This Row],[Name]]="","",_xlfn.XLOOKUP(Overview[[#This Row],[Name]],Dec!B:B,Dec!C:C,""))
J13: =IF(Overview[[#This Row],[Name]]="","",_xlfn.XLOOKUP(Overview[[#This Row],[Name]],Jan!B:B,Jan!C:C,"")) | K13: =IF(Overview[[#This Row],[Name]]="","",_xlfn.XLOOKUP(Overview[[#This Row],[Name]],Feb!B:B,Feb!C:C,"")) | L13: =IF(Overview[[#This Row],[Name]]="","",_xlfn.XLOOKUP(Overview[[#This Row],[Name]],Mar!B:B,Mar!C:C,"")) | M13: =IF(Overview[[#This Row],[Name]]="","",_xlfn.XLOOKUP(Overview[[#This Row],[Name]],Apr!B:B,Apr!C:C,"")) | N13: =IF(Overview[[#This Row],[Name]]="","",_xlfn.XLOOKUP(Overview[[#This Row],[Name]],May!B:B,May!C:C,"")) | O13: =IF(Overview[[#This Row],[Name]]="","",_xlfn.XLOOKUP(Overview[[#This Row],[Name]],Jun!B:B,Jun!C:C,"")) | P13: =IF(Overview[[#This Row],[Name]]="","",_xlfn.XLOOKUP(Overview[[#This Row],[Name]],Jul!B:B,Jul!C:C,"")) | Q13: =IF(Overview[[#This Row],[Name]]="","",_xlfn.XLOOKUP(Overview[[#This Row],[Name]],Aug!B:B,Aug!C:C,"")) | R13: =IF(Overview[[#This Row],[Name]]="","",_xlfn.XLOOKUP(Overview[[#This Row],[Name]],Sep!B:B,Sep!C:C,"")) | S13: =IF(Overview[[#This Row],[Name]]="","",_xlfn.XLOOKUP(Overview[[#This Row],[Name]],Oct!B:B,Oct!C:C,"")) | T13: =IF(Overview[[#This Row],[Name]]="","",_xlfn.XLOOKUP(Overview[[#This Row],[Name]],Nov!B:B,Nov!C:C,"")) | U13: =IF(Overview[[#This Row],[Name]]="","",_xlfn.XLOOKUP(Overview[[#This Row],[Name]],Dec!B:B,Dec!C:C,""))
J14: =IF(Overview[[#This Row],[Name]]="","",_xlfn.XLOOKUP(Overview[[#This Row],[Name]],Jan!B:B,Jan!C:C,"")) | K14: =IF(Overview[[#This Row],[Name]]="","",_xlfn.XLOOKUP(Overview[[#This Row],[Name]],Feb!B:B,Feb!C:C,"")) | L14: =IF(Overview[[#This Row],[Name]]="","",_xlfn.XLOOKUP(Overview[[#This Row],[Name]],Mar!B:B,Mar!C:C,"")) | M14: =IF(Overview[[#This Row],[Name]]="","",_xlfn.XLOOKUP(Overview[[#This Row],[Name]],Apr!B:B,Apr!C:C,"")) | N14: =IF(Overview[[#This Row],[Name]]="","",_xlfn.XLOOKUP(Overview[[#This Row],[Name]],May!B:B,May!C:C,"")) | O14: =IF(Overview[[#This Row],[Name]]="","",_xlfn.XLOOKUP(Overview[[#This Row],[Name]],Jun!B:B,Jun!C:C,"")) | P14: =IF(Overview[[#This Row],[Name]]="","",_xlfn.XLOOKUP(Overview[[#This Row],[Name]],Jul!B:B,Jul!C:C,"")) | Q14: =IF(Overview[[#This Row],[Name]]="","",_xlfn.XLOOKUP(Overview[[#This Row],[Name]],Aug!B:B,Aug!C:C,"")) | R14: =IF(Overview[[#This Row],[Name]]="","",_xlfn.XLOOKUP(Overview[[#This Row],[Name]],Sep!B:B,Sep!C:C,"")) | S14: =IF(Overview[[#This Row],[Name]]="","",_xlfn.XLOOKUP(Overview[[#This Row],[Name]],Oct!B:B,Oct!C:C,"")) | T14: =IF(Overview[[#This Row],[Name]]="","",_xlfn.XLOOKUP(Overview[[#This Row],[Name]],Nov!B:B,Nov!C:C,"")) | U14: =IF(Overview[[#This Row],[Name]]="","",_xlfn.XLOOKUP(Overview[[#This Row],[Name]],Dec!B:B,Dec!C:C,""))
J15: =IF(Overview[[#This Row],[Name]]="","",_xlfn.XLOOKUP(Overview[[#This Row],[Name]],Jan!B:B,Jan!C:C,"")) | K15: =IF(Overview[[#This Row],[Name]]="","",_xlfn.XLOOKUP(Overview[[#This Row],[Name]],Feb!B:B,Feb!C:C,"")) | L15: =IF(Overview[[#This Row],[Name]]="","",_xlfn.XLOOKUP(Overview[[#This Row],[Name]],Mar!B:B,Mar!C:C,"")) | M15: =IF(Overview[[#This Row],[Name]]="","",_xlfn.XLOOKUP(Overview[[#This Row],[Name]],Apr!B:B,Apr!C:C,"")) | N15: =IF(Overview[[#This Row],[Name]]="","",_xlfn.XLOOKUP(Overview[[#This Row],[Name]],May!B:B,May!C:C,"")) | O15: =IF(Overview[[#This Row],[Name]]="","",_xlfn.XLOOKUP(Overview[[#This Row],[Name]],Jun!B:B,Jun!C:C,"")) | P15: =IF(Overview[[#This Row],[Name]]="","",_xlfn.XLOOKUP(Overview[[#This Row],[Name]],Jul!B:B,Jul!C:C,"")) | Q15: =IF(Overview[[#This Row],[Name]]="","",_xlfn.XLOOKUP(Overview[[#This Row],[Name]],Aug!B:B,Aug!C:C,"")) | R15: =IF(Overview[[#This Row],[Name]]="","",_xlfn.XLOOKUP(Overview[[#This Row],[Name]],Sep!B:B,Sep!C:C,"")) | S15: =IF(Overview[[#This Row],[Name]]="","",_xlfn.XLOOKUP(Overview[[#This Row],[Name]],Oct!B:B,Oct!C:C,"")) | T15: =IF(Overview[[#This Row],[Name]]="","",_xlfn.XLOOKUP(Overview[[#This Row],[Name]],Nov!B:B,Nov!C:C,"")) | U15: =IF(Overview[[#This Row],[Name]]="","",_xlfn.XLOOKUP(Overview[[#This Row],[Name]],Dec!B:B,Dec!C:C,""))
... J38: =IF(Overview[[#This Row],[Name]]="","",_xlfn.XLOOKUP(Overview[[#This Row],[Name]],Jan!B:B,Jan!C:C,"")) | K38: =IF(Overview[[#This Row],[Name]]="","",_xlfn.XLOOKUP(Overview[[#This Row],[Name]],Feb!B:B,Feb!C:C,"")) | L38: =IF(Overview[[#This Row],[Name]]="","",_xlfn.XLOOKUP(Overview[[#This Row],[Name]],Mar!B:B,Mar!C:C,"")) | M38: =IF(Overview[[#This Row],[Name]]="","",_xlfn.XLOOKUP(Overview[[#This Row],[Name]],Apr!B:B,Apr!C:C,"")) | N38: =IF(Overview[[#This Row],[Name]]="","",_xlfn.XLOOKUP(Overview[[#This Row],[Name]],May!B:B,May!C:C,"")) | O38: =IF(Overview[[#This Row],[Name]]="","",_xlfn.XLOOKUP(Overview[[#This Row],[Name]],Jun!B:B,Jun!C:C,"")) | P38: =IF(Overview[[#This Row],[Name]]="","",_xlfn.XLOOKUP(Overview[[#This Row],[Name]],Jul!B:B,Jul!C:C,"")) | Q38: =IF(Overview[[#This Row],[Name]]="","",_xlfn.XLOOKUP(Overview[[#This Row],[Name]],Aug!B:B,Aug!C:C,"")) | R38: =IF(Overview[[#This Row],[Name]]="","",_xlfn.XLOOKUP(Overview[[#This Row],[Name]],Sep!B:B,Sep!C:C,"")) | S38: =IF(Overview[[#This Row],[Name]]="","",_xlfn.XLOOKUP(Overview[[#This Row],[Name]],Oct!B:B,Oct!C:C,"")) | T38: =IF(Overview[[#This Row],[Name]]="","",_xlfn.XLOOKUP(Overview[[#This Row],[Name]],Nov!B:B,Nov!C:C,"")) | U38: =IF(Overview[[#This Row],[Name]]="","",_xlfn.XLOOKUP(Overview[[#This Row],[Name]],Dec!B:B,Dec!C:C,""))

Sheet Jan
B2: Malnutrition Risk Monitoring
B4: Month: | C4: January | D4: Year: | E4: Enter Year Here
C6: Current Weight | H6: Weight History | L6: MUST | O6: Weight Considerations | S6: Diet Considerations
B7: Name | C7: January Weight (kg) | D7: Date January Weight Taken | E7: January BMI (kg/m2) | F7: Weight (kg) Difference Between Dec & Jan | G7: Weight (kg) Difference Between Dec & Jan as % | H7: Highest Weight in the Past 3 - 6 Months | I7: Weight (kg) Difference from Highest Weight in Past 3 - 6 Months (Current Month - Highest Month) | J7: Weight (kg) Difference from Highest Weight in 3 - 6 months as % | K7: Is the adults weight stable? (Yes/No) | L7: If Weight has been lost, is this Planned? (Yes/No) | M7: January MUST Score | N7: January MUST Risk | O7: Is this BMI/Weight/MUST typical for the adult? (Yes/No) | P7: If Yes, what would indicate a concern/is atypical for this adult? | Q7: Is there any explanation for BMI/Weight/MUST changes? (Yes/No) | R7: If Yes, please detail | S7: Is the adult on a special/fortified diet? (e.g. cultural, dietary restrictions, fortified etc) (Yes/No) | T7: If Yes, give details | U7: If the adult has been assessed for texture-modified Food, please record the level below | V7: If the adult has been assessed for texture-modified Fluid, please record the level below | W7: Is Action Required? (Yes/No) (If Y, please complete Action Plan tab) | X7: Date Care Plan & Any Relevent Risk Assessments Last Updated | Y7: Comments
E8: =IF(Jan[[#This Row],[Name]]="","",Jan[[#This Row],[January Weight (kg)]]/(VLOOKUP(Jan[[#This Row],[Name]],Overview[],2,FALSE)/100)^2) | F8: =IF(Jan[[#This Row],[Name]]="","",IF(VLOOKUP(Jan[[#This Row],[Name]],Overview[],8,FALSE)="","N/A",Jan[[#This Row],[January Weight (kg)]]-VLOOKUP(Jan[[#This Row],[Name]],Overview[],8,FALSE))) | G8: =IF(Jan[[#This Row],[Name]]="","",IF(VLOOKUP(Jan[[#This Row],[Name]],Overview[],8,FALSE)="","N/A",(Jan[[#This Row],[January Weight (kg)]]-VLOOKUP(Jan[[#This Row],[Name]],Overview[],8,FALSE))/VLOOKUP(Jan[[#This Row],[Name]],Overview[],8,FALSE))) | H8: {=IF(Jan[[#This Row],[Name]]="","",IF(SUMPRODUCT((Overview[Name]=Jan[[#This Row],[Name]])*ISNUMBER(Overview[[July Weight (kg)]:[October Weight (kg)]]))=0,"N/A",MAX(IF((Overview[Name]=Jan[[#This Row],[Name]])*ISNUMBER(Overview[[July Weight (kg)]:[October Weight (kg)]]),Overview[[July Weight (kg)]:[October Weight (kg)]]))))} | I8: =IF(Jan[[#This Row],[Name]]="","",IF(NOT(ISNUMBER(Jan[[#This Row],[Highest Weight in the Past 3 - 6 Months]])),"N/A",IF(Jan[[#This Row],[January Weight (kg)]]=Jan[[#This Row],[Highest Weight in the Past 3 - 6 Months]],0,Jan[[#This Row],[January Weight (kg)]]-Jan[[#This Row],[Highest Weight in the Past 3 - 6 Months]]))) | J8: =IF(Jan[[#This Row],[Name]]="","",IF(OR(Jan[[#This Row],[Highest Weight in the Past 3 - 6 Months]]="",Jan[[#This Row],[Highest Weight in the Past 3 - 6 Months]]="N/A"),"N/A",IFERROR(Jan[[#This Row],[Weight (kg) Difference from Highest Weight in Past 3 - 6 Months (Current Month - Highest Month)]]/Jan[[#This Row],[Highest Weight in the Past 3 - 6 Months]],"N/A"))) | M8: =IF(Jan[[#This Row],[Name]]="","",IFERROR(IF(Jan[[#This Row],[January BMI (kg/m2)]]>20,0,IF(Jan[[#This Row],[January BMI (kg/m2)]]>=18.5,1,2))+IF(Jan[[#This Row],[If Weight has been lost, is this Planned? (Yes/No)]]="Yes",0,IF(Jan[[#This Row],[Weight (kg) Difference from Highest Weight in 3 - 6 months as %]]>-0.05,0,IF(Jan[[#This Row],[Weight (kg) Difference from Highest Weight in 3 - 6 months as %]]>=-0.1,1,2))),"")) | N8: =IF(Jan[[#This Row],[Name]]="","",IF(Jan[[#This Row],[January MUST Score ]]=0,"Low",IF(Jan[[#This Row],[January MUST Score ]]=1,"Medium","High")))
E9: =IF(Jan[[#This Row],[Name]]="","",Jan[[#This Row],[January Weight (kg)]]/(VLOOKUP(Jan[[#This Row],[Name]],Overview[],2,FALSE)/100)^2) | F9: =IF(Jan[[#This Row],[Name]]="","",IF(VLOOKUP(Jan[[#This Row],[Name]],Overview[],8,FALSE)="","N/A",Jan[[#This Row],[January Weight (kg)]]-VLOOKUP(Jan[[#This Row],[Name]],Overview[],8,FALSE))) | G9: =IF(Jan[[#This Row],[Name]]="","",IF(VLOOKUP(Jan[[#This Row],[Name]],Overview[],8,FALSE)="","N/A",(Jan[[#This Row],[January Weight (kg)]]-VLOOKUP(Jan[[#This Row],[Name]],Overview[],8,FALSE))/VLOOKUP(Jan[[#This Row],[Name]],Overview[],8,FALSE))) | H9: {=IF(Jan[[#This Row],[Name]]="","",IF(SUMPRODUCT((Overview[Name]=Jan[[#This Row],[Name]])*ISNUMBER(Overview[[July Weight (kg)]:[October Weight (kg)]]))=0,"N/A",MAX(IF((Overview[Name]=Jan[[#This Row],[Name]])*ISNUMBER(Overview[[July Weight (kg)]:[October Weight (kg)]]),Overview[[July Weight (kg)]:[October Weight (kg)]]))))} | I9: =IF(Jan[[#This Row],[Name]]="","",IF(NOT(ISNUMBER(Jan[[#This Row],[Highest Weight in the Past 3 - 6 Months]])),"N/A",IF(Jan[[#This Row],[January Weight (kg)]]=Jan[[#This Row],[Highest Weight in the Past 3 - 6 Months]],0,Jan[[#This Row],[January Weight (kg)]]-Jan[[#This Row],[Highest Weight in the Past 3 - 6 Months]]))) | J9: =IF(Jan[[#This Row],[Name]]="","",IF(OR(Jan[[#This Row],[Highest Weight in the Past 3 - 6 Months]]="",Jan[[#This Row],[Highest Weight in the Past 3 - 6 Months]]="N/A"),"N/A",IFERROR(Jan[[#This Row],[Weight (kg) Difference from Highest Weight in Past 3 - 6 Months (Current Month - Highest Month)]]/Jan[[#This Row],[Highest Weight in the Past 3 - 6 Months]],"N/A"))) | M9: =IF(Jan[[#This Row],[Name]]="","",IFERROR(IF(Jan[[#This Row],[January BMI (kg/m2)]]>20,0,IF(Jan[[#This Row],[January BMI (kg/m2)]]>=18.5,1,2))+IF(Jan[[#This Row],[If Weight has been lost, is this Planned? (Yes/No)]]="Yes",0,IF(Jan[[#This Row],[Weight (kg) Difference from Highest Weight in 3 - 6 months as %]]>-0.05,0,IF(Jan[[#This Row],[Weight (kg) Difference from Highest Weight in 3 - 6 months as %]]>=-0.1,1,2))),"")) | N9: =IF(Jan[[#This Row],[Name]]="","",IF(Jan[[#This Row],[January MUST Score ]]=0,"Low",IF(Jan[[#This Row],[January MUST Score ]]=1,"Medium","High")))
E10: =IF(Jan[[#This Row],[Name]]="","",Jan[[#This Row],[January Weight (kg)]]/(VLOOKUP(Jan[[#This Row],[Name]],Overview[],2,FALSE)/100)^2) | F10: =IF(Jan[[#This Row],[Name]]="","",IF(VLOOKUP(Jan[[#This Row],[Name]],Overview[],8,FALSE)="","N/A",Jan[[#This Row],[January Weight (kg)]]-VLOOKUP(Jan[[#This Row],[Name]],Overview[],8,FALSE))) | G10: =IF(Jan[[#This Row],[Name]]="","",IF(VLOOKUP(Jan[[#This Row],[Name]],Overview[],8,FALSE)="","N/A",(Jan[[#This Row],[January Weight (kg)]]-VLOOKUP(Jan[[#This Row],[Name]],Overview[],8,FALSE))/VLOOKUP(Jan[[#This Row],[Name]],Overview[],8,FALSE))) | H10: {=IF(Jan[[#This Row],[Name]]="","",IF(SUMPRODUCT((Overview[Name]=Jan[[#This Row],[Name]])*ISNUMBER(Overview[[July Weight (kg)]:[October Weight (kg)]]))=0,"N/A",MAX(IF((Overview[Name]=Jan[[#This Row],[Name]])*ISNUMBER(Overview[[July Weight (kg)]:[October Weight (kg)]]),Overview[[July Weight (kg)]:[October Weight (kg)]]))))} | I10: =IF(Jan[[#This Row],[Name]]="","",IF(NOT(ISNUMBER(Jan[[#This Row],[Highest Weight in the Past 3 - 6 Months]])),"N/A",IF(Jan[[#This Row],[January Weight (kg)]]=Jan[[#This Row],[Highest Weight in the Past 3 - 6 Months]],0,Jan[[#This Row],[January Weight (kg)]]-Jan[[#This Row],[Highest Weight in the Past 3 - 6 Months]]))) | J10: =IF(Jan[[#This Row],[Name]]="","",IF(OR(Jan[[#This Row],[Highest Weight in the Past 3 - 6 Months]]="",Jan[[#This Row],[Highest Weight in the Past 3 - 6 Months]]="N/A"),"N/A",IFERROR(Jan[[#This Row],[Weight (kg) Difference from Highest Weight in Past 3 - 6 Months (Current Month - Highest Month)]]/Jan[[#This Row],[Highest Weight in the Past 3 - 6 Months]],"N/A"))) | M10: =IF(Jan[[#This Row],[Name]]="","",IFERROR(IF(Jan[[#This Row],[January BMI (kg/m2)]]>20,0,IF(Jan[[#This Row],[January BMI (kg/m2)]]>=18.5,1,2))+IF(Jan[[#This Row],[If Weight has been lost, is this Planned? (Yes/No)]]="Yes",0,IF(Jan[[#This Row],[Weight (kg) Difference from Highest Weight in 3 - 6 months as %]]>-0.05,0,IF(Jan[[#This Row],[Weight (kg) Difference from Highest Weight in 3 - 6 months as %]]>=-0.1,1,2))),"")) | N10: =IF(Jan[[#This Row],[Name]]="","",IF(Jan[[#This Row],[January MUST Score ]]=0,"Low",IF(Jan[[#This Row],[January MUST Score ]]=1,"Medium","High")))
E13: =IF(Jan[[#This Row],[Name]]="","",Jan[[#This Row],[January Weight (kg)]]/(VLOOKUP(Jan[[#This Row],[Name]],Overview[],2,FALSE)/100)^2) | F13: =IF(Jan[[#This Row],[Name]]="","",IF(VLOOKUP(Jan[[#This Row],[Name]],Overview[],8,FALSE)="","N/A",Jan[[#This Row],[January Weight (kg)]]-VLOOKUP(Jan[[#This Row],[Name]],Overview[],8,FALSE))) | G13: =IF(Jan[[#This Row],[Name]]="","",IF(VLOOKUP(Jan[[#This Row],[Name]],Overview[],8,FALSE)="","N/A",(Jan[[#This Row],[January Weight (kg)]]-VLOOKUP(Jan[[#This Row],[Name]],Overview[],8,FALSE))/VLOOKUP(Jan[[#This Row],[Name]],Overview[],8,FALSE))) | H13: {=IF(Jan[[#This Row],[Name]]="","",IF(SUMPRODUCT((Overview[Name]=Jan[[#This Row],[Name]])*ISNUMBER(Overview[[July Weight (kg)]:[October Weight (kg)]]))=0,"N/A",MAX(IF((Overview[Name]=Jan[[#This Row],[Name]])*ISNUMBER(Overview[[July Weight (kg)]:[October Weight (kg)]]),Overview[[July Weight (kg)]:[October Weight (kg)]]))))} | I13: =IF(Jan[[#This Row],[Name]]="","",IF(NOT(ISNUMBER(Jan[[#This Row],[Highest Weight in the Past 3 - 6 Months]])),"N/A",IF(Jan[[#This Row],[January Weight (kg)]]=Jan[[#This Row],[Highest Weight in the Past 3 - 6 Months]],0,Jan[[#This Row],[January Weight (kg)]]-Jan[[#This Row],[Highest Weight in the Past 3 - 6 Months]]))) | J13: =IF(Jan[[#This Row],[Name]]="","",IF(OR(Jan[[#This Row],[Highest Weight in the Past 3 - 6 Months]]="",Jan[[#This Row],[Highest Weight in the Past 3 - 6 Months]]="N/A"),"N/A",IFERROR(Jan[[#This Row],[Weight (kg) Difference from Highest Weight in Past 3 - 6 Months (Current Month - Highest Month)]]/Jan[[#This Row],[Highest Weight in the Past 3 - 6 Months]],"N/A"))) | M13: =IF(Jan[[#This Row],[Name]]="","",IFERROR(IF(Jan[[#This Row],[January BMI (kg/m2)]]>20,0,IF(Jan[[#This Row],[January BMI (kg/m2)]]>=18.5,1,2))+IF(Jan[[#This Row],[If Weight has been lost, is this Planned? (Yes/No)]]="Yes",0,IF(Jan[[#This Row],[Weight (kg) Difference from Highest Weight in 3 - 6 months as %]]>-0.05,0,IF(Jan[[#This Row],[Weight (kg) Difference from Highest Weight in 3 - 6 months as %]]>=-0.1,1,2))),"")) | N13: =IF(Jan[[#This Row],[Name]]="","",IF(Jan[[#This Row],[January MUST Score ]]=0,"Low",IF(Jan[[#This Row],[January MUST Score ]]=1,"Medium","High")))
E14: =IF(Jan[[#This Row],[Name]]="","",Jan[[#This Row],[January Weight (kg)]]/(VLOOKUP(Jan[[#This Row],[Name]],Overview[],2,FALSE)/100)^2) | F14: =IF(Jan[[#This Row],[Name]]="","",IF(VLOOKUP(Jan[[#This Row],[Name]],Overview[],8,FALSE)="","N/A",Jan[[#This Row],[January Weight (kg)]]-VLOOKUP(Jan[[#This Row],[Name]],Overview[],8,FALSE))) | G14: =IF(Jan[[#This Row],[Name]]="","",IF(VLOOKUP(Jan[[#This Row],[Name]],Overview[],8,FALSE)="","N/A",(Jan[[#This Row],[January Weight (kg)]]-VLOOKUP(Jan[[#This Row],[Name]],Overview[],8,FALSE))/VLOOKUP(Jan[[#This Row],[Name]],Overview[],8,FALSE))) | H14: {=IF(Jan[[#This Row],[Name]]="","",IF(SUMPRODUCT((Overview[Name]=Jan[[#This Row],[Name]])*ISNUMBER(Overview[[July Weight (kg)]:[October Weight (kg)]]))=0,"N/A",MAX(IF((Overview[Name]=Jan[[#This Row],[Name]])*ISNUMBER(Overview[[July Weight (kg)]:[October Weight (kg)]]),Overview[[July Weight (kg)]:[October Weight (kg)]]))))} | I14: =IF(Jan[[#This Row],[Name]]="","",IF(NOT(ISNUMBER(Jan[[#This Row],[Highest Weight in the Past 3 - 6 Months]])),"N/A",IF(Jan[[#This Row],[January Weight (kg)]]=Jan[[#This Row],[Highest Weight in the Past 3 - 6 Months]],0,Jan[[#This Row],[January Weight (kg)]]-Jan[[#This Row],[Highest Weight in the Past 3 - 6 Months]]))) | J14: =IF(Jan[[#This Row],[Name]]="","",IF(OR(Jan[[#This Row],[Highest Weight in the Past 3 - 6 Months]]="",Jan[[#This Row],[Highest Weight in the Past 3 - 6 Months]]="N/A"),"N/A",IFERROR(Jan[[#This Row],[Weight (kg) Difference from Highest Weight in Past 3 - 6 Months (Current Month - Highest Month)]]/Jan[[#This Row],[Highest Weight in the Past 3 - 6 Months]],"N/A"))) | M14: =IF(Jan[[#This Row],[Name]]="","",IFERROR(IF(Jan[[#This Row],[January BMI (kg/m2)]]>20,0,IF(Jan[[#This Row],[January BMI (kg/m2)]]>=18.5,1,2))+IF(Jan[[#This Row],[If Weight has been lost, is this Planned? (Yes/No)]]="Yes",0,IF(Jan[[#This Row],[Weight (kg) Difference from Highest Weight in 3 - 6 months as %]]>-0.05,0,IF(Jan[[#This Row],[Weight (kg) Difference from Highest Weight in 3 - 6 months as %]]>=-0.1,1,2))),"")) | N14: =IF(Jan[[#This Row],[Name]]="","",IF(Jan[[#This Row],[January MUST Score ]]=0,"Low",IF(Jan[[#This Row],[January MUST Score ]]=1,"Medium","High")))
E15: =IF(Jan[[#This Row],[Name]]="","",Jan[[#This Row],[January Weight (kg)]]/(VLOOKUP(Jan[[#This Row],[Name]],Overview[],2,FALSE)/100)^2) | F15: =IF(Jan[[#This Row],[Name]]="","",IF(VLOOKUP(Jan[[#This Row],[Name]],Overview[],8,FALSE)="","N/A",Jan[[#This Row],[January Weight (kg)]]-VLOOKUP(Jan[[#This Row],[Name]],Overview[],8,FALSE))) | G15: =IF(Jan[[#This Row],[Name]]="","",IF(VLOOKUP(Jan[[#This Row],[Name]],Overview[],8,FALSE)="","N/A",(Jan[[#This Row],[January Weight (kg)]]-VLOOKUP(Jan[[#This Row],[Name]],Overview[],8,FALSE))/VLOOKUP(Jan[[#This Row],[Name]],Overview[],8,FALSE))) | H15: {=IF(Jan[[#This Row],[Name]]="","",IF(SUMPRODUCT((Overview[Name]=Jan[[#This Row],[Name]])*ISNUMBER(Overview[[July Weight (kg)]:[October Weight (kg)]]))=0,"N/A",MAX(IF((Overview[Name]=Jan[[#This Row],[Name]])*ISNUMBER(Overview[[July Weight (kg)]:[October Weight (kg)]]),Overview[[July Weight (kg)]:[October Weight (kg)]]))))} | I15: =IF(Jan[[#This Row],[Name]]="","",IF(NOT(ISNUMBER(Jan[[#This Row],[Highest Weight in the Past 3 - 6 Months]])),"N/A",IF(Jan[[#This Row],[January Weight (kg)]]=Jan[[#This Row],[Highest Weight in the Past 3 - 6 Months]],0,Jan[[#This Row],[January Weight (kg)]]-Jan[[#This Row],[Highest Weight in the Past 3 - 6 Months]]))) | J15: =IF(Jan[[#This Row],[Name]]="","",IF(OR(Jan[[#This Row],[Highest Weight in the Past 3 - 6 Months]]="",Jan[[#This Row],[Highest Weight in the Past 3 - 6 Months]]="N/A"),"N/A",IFERROR(Jan[[#This Row],[Weight (kg) Difference from Highest Weight in Past 3 - 6 Months (Current Month - Highest Month)]]/Jan[[#This Row],[Highest Weight in the Past 3 - 6 Months]],"N/A"))) | M15: =IF(Jan[[#This Row],[Name]]="","",IFERROR(IF(Jan[[#This Row],[January BMI (kg/m2)]]>20,0,IF(Jan[[#This Row],[January BMI (kg/m2)]]>=18.5,1,2))+IF(Jan[[#This Row],[If Weight has been lost, is this Planned? (Yes/No)]]="Yes",0,IF(Jan[[#This Row],[Weight (kg) Difference from Highest Weight in 3 - 6 months as %]]>-0.05,0,IF(Jan[[#This Row],[Weight (kg) Difference from Highest Weight in 3 - 6 months as %]]>=-0.1,1,2))),"")) | N15: =IF(Jan[[#This Row],[Name]]="","",IF(Jan[[#This Row],[January MUST Score ]]=0,"Low",IF(Jan[[#This Row],[January MUST Score ]]=1,"Medium","High")))
E16: =IF(Jan[[#This Row],[Name]]="","",Jan[[#This Row],[January Weight (kg)]]/(VLOOKUP(Jan[[#This Row],[Name]],Overview[],2,FALSE)/100)^2) | F16: =IF(Jan[[#This Row],[Name]]="","",IF(VLOOKUP(Jan[[#This Row],[Name]],Overview[],8,FALSE)="","N/A",Jan[[#This Row],[January Weight (kg)]]-VLOOKUP(Jan[[#This Row],[Name]],Overview[],8,FALSE))) | G16: =IF(Jan[[#This Row],[Name]]="","",IF(VLOOKUP(Jan[[#This Row],[Name]],Overview[],8,FALSE)="","N/A",(Jan[[#This Row],[January Weight (kg)]]-VLOOKUP(Jan[[#This Row],[Name]],Overview[],8,FALSE))/VLOOKUP(Jan[[#This Row],[Name]],Overview[],8,FALSE))) | H16: {=IF(Jan[[#This Row],[Name]]="","",IF(SUMPRODUCT((Overview[Name]=Jan[[#This Row],[Name]])*ISNUMBER(Overview[[July Weight (kg)]:[October Weight (kg)]]))=0,"N/A",MAX(IF((Overview[Name]=Jan[[#This Row],[Name]])*ISNUMBER(Overview[[July Weight (kg)]:[October Weight (kg)]]),Overview[[July Weight (kg)]:[October Weight (kg)]]))))} | I16: =IF(Jan[[#This Row],[Name]]="","",IF(NOT(ISNUMBER(Jan[[#This Row],[Highest Weight in the Past 3 - 6 Months]])),"N/A",IF(Jan[[#This Row],[January Weight (kg)]]=Jan[[#This Row],[Highest Weight in the Past 3 - 6 Months]],0,Jan[[#This Row],[January Weight (kg)]]-Jan[[#This Row],[Highest Weight in the Past 3 - 6 Months]]))) | J16: =IF(Jan[[#This Row],[Name]]="","",IF(OR(Jan[[#This Row],[Highest Weight in the Past 3 - 6 Months]]="",Jan[[#This Row],[Highest Weight in the Past 3 - 6 Months]]="N/A"),"N/A",IFERROR(Jan[[#This Row],[Weight (kg) Difference from Highest Weight in Past 3 - 6 Months (Current Month - Highest Month)]]/Jan[[#This Row],[Highest Weight in the Past 3 - 6 Months]],"N/A"))) | M16: =IF(Jan[[#This Row],[Name]]="","",IFERROR(IF(Jan[[#This Row],[January BMI (kg/m2)]]>20,0,IF(Jan[[#This Row],[January BMI (kg/m2)]]>=18.5,1,2))+IF(Jan[[#This Row],[If Weight has been lost, is this Planned? (Yes/No)]]="Yes",0,IF(Jan[[#This Row],[Weight (kg) Difference from Highest Weight in 3 - 6 months as %]]>-0.05,0,IF(Jan[[#This Row],[Weight (kg) Difference from Highest Weight in 3 - 6 months as %]]>=-0.1,1,2))),"")) | N16: =IF(Jan[[#This Row],[Name]]="","",IF(Jan[[#This Row],[January MUST Score ]]=0,"Low",IF(Jan[[#This Row],[January MUST Score ]]=1,"Medium","High")))
E17: =IF(Jan[[#This Row],[Name]]="","",Jan[[#This Row],[January Weight (kg)]]/(VLOOKUP(Jan[[#This Row],[Name]],Overview[],2,FALSE)/100)^2) | F17: =IF(Jan[[#This Row],[Name]]="","",IF(VLOOKUP(Jan[[#This Row],[Name]],Overview[],8,FALSE)="","N/A",Jan[[#This Row],[January Weight (kg)]]-VLOOKUP(Jan[[#This Row],[Name]],Overview[],8,FALSE))) | G17: =IF(Jan[[#This Row],[Name]]="","",IF(VLOOKUP(Jan[[#This Row],[Name]],Overview[],8,FALSE)="","N/A",(Jan[[#This Row],[January Weight (kg)]]-VLOOKUP(Jan[[#This Row],[Name]],Overview[],8,FALSE))/VLOOKUP(Jan[[#This Row],[Name]],Overview[],8,FALSE))) | H17: {=IF(Jan[[#This Row],[Name]]="","",IF(SUMPRODUCT((Overview[Name]=Jan[[#This Row],[Name]])*ISNUMBER(Overview[[July Weight (kg)]:[October Weight (kg)]]))=0,"N/A",MAX(IF((Overview[Name]=Jan[[#This Row],[Name]])*ISNUMBER(Overview[[July Weight (kg)]:[October Weight (kg)]]),Overview[[July Weight (kg)]:[October Weight (kg)]]))))} | I17: =IF(Jan[[#This Row],[Name]]="","",IF(NOT(ISNUMBER(Jan[[#This Row],[Highest Weight in the Past 3 - 6 Months]])),"N/A",IF(Jan[[#This Row],[January Weight (kg)]]=Jan[[#This Row],[Highest Weight in the Past 3 - 6 Months]],0,Jan[[#This Row],[January Weight (kg)]]-Jan[[#This Row],[Highest Weight in the Past 3 - 6 Months]]))) | J17: =IF(Jan[[#This Row],[Name]]="","",IF(OR(Jan[[#This Row],[Highest Weight in the Past 3 - 6 Months]]="",Jan[[#This Row],[Highest Weight in the Past 3 - 6 Months]]="N/A"),"N/A",IFERROR(Jan[[#This Row],[Weight (kg) Difference from Highest Weight in Past 3 - 6 Months (Current Month - Highest Month)]]/Jan[[#This Row],[Highest Weight in the Past 3 - 6 Months]],"N/A"))) | M17: =IF(Jan[[#This Row],[Name]]="","",IFERROR(IF(Jan[[#This Row],[January BMI (kg/m2)]]>20,0,IF(Jan[[#This Row],[January BMI (kg/m2)]]>=18.5,1,2))+IF(Jan[[#This Row],[If Weight has been lost, is this Planned? (Yes/No)]]="Yes",0,IF(Jan[[#This Row],[Weight (kg) Difference from Highest Weight in 3 - 6 months as %]]>-0.05,0,IF(Jan[[#This Row],[Weight (kg) Difference from Highest Weight in 3 - 6 months as %]]>=-0.1,1,2))),"")) | N17: =IF(Jan[[#This Row],[Name]]="","",IF(Jan[[#This Row],[January MUST Score ]]=0,"Low",IF(Jan[[#This Row],[January MUST Score ]]=1,"Medium","High")))
E18: =IF(Jan[[#This Row],[Name]]="","",Jan[[#This Row],[January Weight (kg)]]/(VLOOKUP(Jan[[#This Row],[Name]],Overview[],2,FALSE)/100)^2) | F18: =IF(Jan[[#This Row],[Name]]="","",IF(VLOOKUP(Jan[[#This Row],[Name]],Overview[],8,FALSE)="","N/A",Jan[[#This Row],[January Weight (kg)]]-VLOOKUP(Jan[[#This Row],[Name]],Overview[],8,FALSE))) | G18: =IF(Jan[[#This Row],[Name]]="","",IF(VLOOKUP(Jan[[#This Row],[Name]],Overview[],8,FALSE)="","N/A",(Jan[[#This Row],[January Weight (kg)]]-VLOOKUP(Jan[[#This Row],[Name]],Overview[],8,FALSE))/VLOOKUP(Jan[[#This Row],[Name]],Overview[],8,FALSE))) | H18: {=IF(Jan[[#This Row],[Name]]="","",IF(SUMPRODUCT((Overview[Name]=Jan[[#This Row],[Name]])*ISNUMBER(Overview[[July Weight (kg)]:[October Weight (kg)]]))=0,"N/A",MAX(IF((Overview[Name]=Jan[[#This Row],[Name]])*ISNUMBER(Overview[[July Weight (kg)]:[October Weight (kg)]]),Overview[[July Weight (kg)]:[October Weight (kg)]]))))} | I18: =IF(Jan[[#This Row],[Name]]="","",IF(NOT(ISNUMBER(Jan[[#This Row],[Highest Weight in the Past 3 - 6 Months]])),"N/A",IF(Jan[[#This Row],[January Weight (kg)]]=Jan[[#This Row],[Highest Weight in the Past 3 - 6 Months]],0,Jan[[#This Row],[January Weight (kg)]]-Jan[[#This Row],[Highest Weight in the Past 3 - 6 Months]]))) | J18: =IF(Jan[[#This Row],[Name]]="","",IF(OR(Jan[[#This Row],[Highest Weight in the Past 3 - 6 Months]]="",Jan[[#This Row],[Highest Weight in the Past 3 - 6 Months]]="N/A"),"N/A",IFERROR(Jan[[#This Row],[Weight (kg) Difference from Highest Weight in Past 3 - 6 Months (Current Month - Highest Month)]]/Jan[[#This Row],[Highest Weight in the Past 3 - 6 Months]],"N/A"))) | M18: =IF(Jan[[#This Row],[Name]]="","",IFERROR(IF(Jan[[#This Row],[January BMI (kg/m2)]]>20,0,IF(Jan[[#This Row],[January BMI (kg/m2)]]>=18.5,1,2))+IF(Jan[[#This Row],[If Weight has been lost, is this Planned? (Yes/No)]]="Yes",0,IF(Jan[[#This Row],[Weight (kg) Difference from Highest Weight in 3 - 6 months as %]]>-0.05,0,IF(Jan[[#This Row],[Weight (kg) Difference from Highest Weight in 3 - 6 months as %]]>=-0.1,1,2))),"")) | N18: =IF(Jan[[#This Row],[Name]]="","",IF(Jan[[#This Row],[January MUST Score ]]=0,"Low",IF(Jan[[#This Row],[January MUST Score ]]=1,"Medium","High")))
E19: =IF(Jan[[#This Row],[Name]]="","",Jan[[#This Row],[January Weight (kg)]]/(VLOOKUP(Jan[[#This Row],[Name]],Overview[],2,FALSE)/100)^2) | F19: =IF(Jan[[#This Row],[Name]]="","",IF(VLOOKUP(Jan[[#This Row],[Name]],Overview[],8,FALSE)="","N/A",Jan[[#This Row],[January Weight (kg)]]-VLOOKUP(Jan[[#This Row],[Name]],Overview[],8,FALSE))) | G19: =IF(Jan[[#This Row],[Name]]="","",IF(VLOOKUP(Jan[[#This Row],[Name]],Overview[],8,FALSE)="","N/A",(Jan[[#This Row],[January Weight (kg)]]-VLOOKUP(Jan[[#This Row],[Name]],Overview[],8,FALSE))/VLOOKUP(Jan[[#This Row],[Name]],Overview[],8,FALSE))) | H19: {=IF(Jan[[#This Row],[Name]]="","",IF(SUMPRODUCT((Overview[Name]=Jan[[#This Row],[Name]])*ISNUMBER(Overview[[July Weight (kg)]:[October Weight (kg)]]))=0,"N/A",MAX(IF((Overview[Name]=Jan[[#This Row],[Name]])*ISNUMBER(Overview[[July Weight (kg)]:[October Weight (kg)]]),Overview[[July Weight (kg)]:[October Weight (kg)]]))))} | I19: =IF(Jan[[#This Row],[Name]]="","",IF(NOT(ISNUMBER(Jan[[#This Row],[Highest Weight in the Past 3 - 6 Months]])),"N/A",IF(Jan[[#This Row],[January Weight (kg)]]=Jan[[#This Row],[Highest Weight in the Past 3 - 6 Months]],0,Jan[[#This Row],[January Weight (kg)]]-Jan[[#This Row],[Highest Weight in the Past 3 - 6 Months]]))) | J19: =IF(Jan[[#This Row],[Name]]="","",IF(OR(Jan[[#This Row],[Highest Weight in the Past 3 - 6 Months]]="",Jan[[#This Row],[Highest Weight in the Past 3 - 6 Months]]="N/A"),"N/A",IFERROR(Jan[[#This Row],[Weight (kg) Difference from Highest Weight in Past 3 - 6 Months (Current Month - Highest Month)]]/Jan[[#This Row],[Highest Weight in the Past 3 - 6 Months]],"N/A"))) | M19: =IF(Jan[[#This Row],[Name]]="","",IFERROR(IF(Jan[[#This Row],[January BMI (kg/m2)]]>20,0,IF(Jan[[#This Row],[January BMI (kg/m2)]]>=18.5,1,2))+IF(Jan[[#This Row],[If Weight has been lost, is this Planned? (Yes/No)]]="Yes",0,IF(Jan[[#This Row],[Weight (kg) Difference from Highest Weight in 3 - 6 months as %]]>-0.05,0,IF(Jan[[#This Row],[Weight (kg) Difference from Highest Weight in 3 - 6 months as %]]>=-0.1,1,2))),"")) | N19: =IF(Jan[[#This Row],[Name]]="","",IF(Jan[[#This Row],[January MUST Score ]]=0,"Low",IF(Jan[[#This Row],[January MUST Score ]]=1,"Medium","High")))
E20: =IF(Jan[[#This Row],[Name]]="","",Jan[[#This Row],[January Weight (kg)]]/(VLOOKUP(Jan[[#This Row],[Name]],Overview[],2,FALSE)/100)^2) | F20: =IF(Jan[[#This Row],[Name]]="","",IF(VLOOKUP(Jan[[#This Row],[Name]],Overview[],8,FALSE)="","N/A",Jan[[#This Row],[January Weight (kg)]]-VLOOKUP(Jan[[#This Row],[Name]],Overview[],8,FALSE))) | G20: =IF(Jan[[#This Row],[Name]]="","",IF(VLOOKUP(Jan[[#This Row],[Name]],Overview[],8,FALSE)="","N/A",(Jan[[#This Row],[January Weight (kg)]]-VLOOKUP(Jan[[#This Row],[Name]],Overview[],8,FALSE))/VLOOKUP(Jan[[#This Row],[Name]],Overview[],8,FALSE))) | H20: {=IF(Jan[[#This Row],[Name]]="","",IF(SUMPRODUCT((Overview[Name]=Jan[[#This Row],[Name]])*ISNUMBER(Overview[[July Weight (kg)]:[October Weight (kg)]]))=0,"N/A",MAX(IF((Overview[Name]=Jan[[#This Row],[Name]])*ISNUMBER(Overview[[July Weight (kg)]:[October Weight (kg)]]),Overview[[July Weight (kg)]:[October Weight (kg)]]))))} | I20: =IF(Jan[[#This Row],[Name]]="","",IF(NOT(ISNUMBER(Jan[[#This Row],[Highest Weight in the Past 3 - 6 Months]])),"N/A",IF(Jan[[#This Row],[January Weight (kg)]]=Jan[[#This Row],[Highest Weight in the Past 3 - 6 Months]],0,Jan[[#This Row],[January Weight (kg)]]-Jan[[#This Row],[Highest Weight in the Past 3 - 6 Months]]))) | J20: =IF(Jan[[#This Row],[Name]]="","",IF(OR(Jan[[#This Row],[Highest Weight in the Past 3 - 6 Months]]="",Jan[[#This Row],[Highest Weight in the Past 3 - 6 Months]]="N/A"),"N/A",IFERROR(Jan[[#This Row],[Weight (kg) Difference from Highest Weight in Past 3 - 6 Months (Current Month - Highest Month)]]/Jan[[#This Row],[Highest Weight in the Past 3 - 6 Months]],"N/A"))) | M20: =IF(Jan[[#This Row],[Name]]="","",IFERROR(IF(Jan[[#This Row],[January BMI (kg/m2)]]>20,0,IF(Jan[[#This Row],[January BMI (kg/m2)]]>=18.5,1,2))+IF(Jan[[#This Row],[If Weight has been lost, is this Planned? (Yes/No)]]="Yes",0,IF(Jan[[#This Row],[Weight (kg) Difference from Highest Weight in 3 - 6 months as %]]>-0.05,0,IF(Jan[[#This Row],[Weight (kg) Difference from Highest Weight in 3 - 6 months as %]]>=-0.1,1,2))),"")) | N20: =IF(Jan[[#This Row],[Name]]="","",IF(Jan[[#This Row],[January MUST Score ]]=0,"Low",IF(Jan[[#This Row],[January MUST Score ]]=1,"Medium","High")))
E21: =IF(Jan[[#This Row],[Name]]="","",Jan[[#This Row],[January Weight (kg)]]/(VLOOKUP(Jan[[#This Row],[Name]],Overview[],2,FALSE)/100)^2) | F21: =IF(Jan[[#This Row],[Name]]="","",IF(VLOOKUP(Jan[[#This Row],[Name]],Overview[],8,FALSE)="","N/A",Jan[[#This Row],[January Weight (kg)]]-VLOOKUP(Jan[[#This Row],[Name]],Overview[],8,FALSE))) | G21: =IF(Jan[[#This Row],[Name]]="","",IF(VLOOKUP(Jan[[#This Row],[Name]],Overview[],8,FALSE)="","N/A",(Jan[[#This Row],[January Weight (kg)]]-VLOOKUP(Jan[[#This Row],[Name]],Overview[],8,FALSE))/VLOOKUP(Jan[[#This Row],[Name]],Overview[],8,FALSE))) | H21: {=IF(Jan[[#This Row],[Name]]="","",IF(SUMPRODUCT((Overview[Name]=Jan[[#This Row],[Name]])*ISNUMBER(Overview[[July Weight (kg)]:[October Weight (kg)]]))=0,"N/A",MAX(IF((Overview[Name]=Jan[[#This Row],[Name]])*ISNUMBER(Overview[[July Weight (kg)]:[October Weight (kg)]]),Overview[[July Weight (kg)]:[October Weight (kg)]]))))} | I21: =IF(Jan[[#This Row],[Name]]="","",IF(NOT(ISNUMBER(Jan[[#This Row],[Highest Weight in the Past 3 - 6 Months]])),"N/A",IF(Jan[[#This Row],[January Weight (kg)]]=Jan[[#This Row],[Highest Weight in the Past 3 - 6 Months]],0,Jan[[#This Row],[January Weight (kg)]]-Jan[[#This Row],[Highest Weight in the Past 3 - 6 Months]]))) | J21: =IF(Jan[[#This Row],[Name]]="","",IF(OR(Jan[[#This Row],[Highest Weight in the Past 3 - 6 Months]]="",Jan[[#This Row],[Highest Weight in the Past 3 - 6 Months]]="N/A"),"N/A",IFERROR(Jan[[#This Row],[Weight (kg) Difference from Highest Weight in Past 3 - 6 Months (Current Month - Highest Month)]]/Jan[[#This Row],[Highest Weight in the Past 3 - 6 Months]],"N/A"))) | M21: =IF(Jan[[#This Row],[Name]]="","",IFERROR(IF(Jan[[#This Row],[January BMI (kg/m2)]]>20,0,IF(Jan[[#This Row],[January BMI (kg/m2)]]>=18.5,1,2))+IF(Jan[[#This Row],[If Weight has been lost, is this Planned? (Yes/No)]]="Yes",0,IF(Jan[[#This Row],[Weight (kg) Difference from Highest Weight in 3 - 6 months as %]]>-0.05,0,IF(Jan[[#This Row],[Weight (kg) Difference from Highest Weight in 3 - 6 months as %]]>=-0.1,1,2))),"")) | N21: =IF(Jan[[#This Row],[Name]]="","",IF(Jan[[#This Row],[January MUST Score ]]=0,"Low",IF(Jan[[#This Row],[January MUST Score ]]=1,"Medium","High")))
... E44: =IF(Jan[[#This Row],[Name]]="","",Jan[[#This Row],[January Weight (kg)]]/(VLOOKUP(Jan[[#This Row],[Name]],Overview[],2,FALSE)/100)^2) | F44: =IF(Jan[[#This Row],[Name]]="","",IF(VLOOKUP(Jan[[#This Row],[Name]],Overview[],8,FALSE)="","N/A",Jan[[#This Row],[January Weight (kg)]]-VLOOKUP(Jan[[#This Row],[Name]],Overview[],8,FALSE))) | G44: =IF(Jan[[#This Row],[Name]]="","",IF(VLOOKUP(Jan[[#This Row],[Name]],Overview[],8,FALSE)="","N/A",(Jan[[#This Row],[January Weight (kg)]]-VLOOKUP(Jan[[#This Row],[Name]],Overview[],8,FALSE))/VLOOKUP(Jan[[#This Row],[Name]],Overview[],8,FALSE))) | H44: {=IF(Jan[[#This Row],[Name]]="","",IF(SUMPRODUCT((Overview[Name]=Jan[[#This Row],[Name]])*ISNUMBER(Overview[[July Weight (kg)]:[October Weight (kg)]]))=0,"N/A",MAX(IF((Overview[Name]=Jan[[#This Row],[Name]])*ISNUMBER(Overview[[July Weight (kg)]:[October Weight (kg)]]),Overview[[July Weight (kg)]:[October Weight (kg)]]))))} | I44: =IF(Jan[[#This Row],[Name]]="","",IF(NOT(ISNUMBER(Jan[[#This Row],[Highest Weight in the Past 3 - 6 Months]])),"N/A",IF(Jan[[#This Row],[January Weight (kg)]]=Jan[[#This Row],[Highest Weight in the Past 3 - 6 Months]],0,Jan[[#This Row],[January Weight (kg)]]-Jan[[#This Row],[Highest Weight in the Past 3 - 6 Months]]))) | J44: =IF(Jan[[#This Row],[Name]]="","",IF(OR(Jan[[#This Row],[Highest Weight in the Past 3 - 6 Months]]="",Jan[[#This Row],[Highest Weight in the Past 3 - 6 Months]]="N/A"),"N/A",IFERROR(Jan[[#This Row],[Weight (kg) Difference from Highest Weight in Past 3 - 6 Months (Current Month - Highest Month)]]/Jan[[#This Row],[Highest Weight in the Past 3 - 6 Months]],"N/A"))) | M44: =IF(Jan[[#This Row],[Name]]="","",IFERROR(IF(Jan[[#This Row],[January BMI (kg/m2)]]>20,0,IF(Jan[[#This Row],[January BMI (kg/m2)]]>=18.5,1,2))+IF(Jan[[#This Row],[If Weight has been lost, is this Planned? (Yes/No)]]="Yes",0,IF(Jan[[#This Row],[Weight (kg) Difference from Highest Weight in 3 - 6 months as %]]>-0.05,0,IF(Jan[[#This Row],[Weight (kg) Difference from Highest Weight in 3 - 6 months as %]]>=-0.1,1,2))),"")) | N44: =IF(Jan[[#This Row],[Name]]="","",IF(Jan[[#This Row],[January MUST Score ]]=0,"Low",IF(Jan[[#This Row],[January MUST Score ]]=1,"Medium","High")))

Sheet Feb
B2: Malnutrition Risk Monitoring
B4: Month: | C4: February | D4: Year: | E4: Enter Year Here
C6: Current Weight | H6: Weight History | L6: MUST | O6: Weight Considerations | S6: Diet Considerations
B7: Name | C7: February Weight (kg) | D7: Date February Weight Taken | E7: February BMI (kg/m2) | F7: Weight (kg) Difference Between Jan & Feb | G7: Weight (kg) Difference Between Jan & Feb as % | H7: Highest Weight in the Past 3 - 6 Months | I7: Weight (kg) Difference from Highest Weight in Past 3 - 6 Months (Current Month - Highest Month) | J7: Weight (kg) Difference from Highest Weight in 3 - 6 months as % | K7: Is the adults weight stable? (Yes/No) | L7: If Weight has been lost, is this Planned? (Yes/No) | M7: February MUST Score | N7: February MUST Risk | O7: Is this BMI/Weight/MUST typical for the adult? (Yes/No) | P7: If Yes, what would indicate a concern/is atypical for this adult? | Q7: Is there any explanation for BMI/Weight/MUST changes? (Yes/No) | R7: If Yes, please detail | S7: Is the adult on a special/fortified diet? (e.g. cultural, dietary restrictions, fortified etc) (Yes/No) | T7: If Yes, give details | U7: If the adult has been assessed for texture-modified Food, please record the level below | V7: If the adult has been assessed for texture-modified Fluid, please record the level below | W7: Is Action Required? (Yes/No) (If Y, please complete Action Plan tab) | X7: Date Care Plan & Any Relevent Risk Assessments Last Updated | Y7: Comments
