Workbook

Sheet How to Use
A1: Residential Care Home Missing Audits – Annual Evidence Workbook
A3: Purpose
A4: Each audit has one tab and holds the whole year of evidence. Weekly tabs have Week 1–52. Monthly tabs have January–December. Input cells are pale yellow. Formula, RAG and header cells are locked only. There is no password.
A6: Scoring
A7: 2 = Fully compliant, 1 = Partially compliant, 0 = Non-compliant, NA = Not applicable. RAG and compliance percentages calculate automatically.

Sheet Annual Audit Schedule
A1: Annual Audit Schedule – Missing Audit Areas
A3: Audit Area | B3: Frequency | C3: Periods in Tab | D3: Evidence Location | E3: Lead Person | F3: Status | G3: Notes | H3: CQC Focus
A4: Equipment & Maintenance | B4: Weekly | C4: 52 weekly sections | D4: Equipment & Maintenance tab | F4: Not Started | H4: Regulations and Quality Statements mapped in audit
A5: Water & Legionella | B5: Weekly | C5: 52 weekly sections | D5: Water & Legionella tab | F5: Not Started | H5: Regulations and Quality Statements mapped in audit
A6: Infection Surveillance | B6: Weekly | C6: 52 weekly sections | D6: Infection Surveillance tab | F6: Not Started | H6: Regulations and Quality Statements mapped in audit
A7: Resident Dignity | B7: Monthly | C7: 12 monthly sections | D7: Resident Dignity tab | F7: Not Started | H7: Regulations and Quality Statements mapped in audit
A8: Personnel & Workforce | B8: Monthly | C8: 12 monthly sections | D8: Personnel & Workforce tab | F8: Not Started | H8: Regulations and Quality Statements mapped in audit
A9: Environmental | B9: Monthly | C9: 12 monthly sections | D9: Environmental tab | F9: Not Started | H9: Regulations and Quality Statements mapped in audit
A10: Nutrition & Hydration | B10: Monthly | C10: 12 monthly sections | D10: Nutrition & Hydration tab | F10: Not Started | H10: Regulations and Quality Statements mapped in audit
A11: Safeguarding & Incidents | B11: Monthly | C11: 12 monthly sections | D11: Safeguarding & Incidents tab | F11: Not Started | H11: Regulations and Quality Statements mapped in audit
A12: Business Continuity | B12: Monthly | C12: 12 monthly sections | D12: Business Continuity tab | F12: Not Started | H12: Regulations and Quality Statements mapped in audit
A13: End of Life | B13: Monthly | C13: 12 monthly sections | D13: End of Life tab | F13: Not Started | H13: Regulations and Quality Statements mapped in audit
A14: Finance & Property | B14: Monthly | C14: 12 monthly sections | D14: Finance & Property tab | F14: Not Started | H14: Regulations and Quality Statements mapped in audit
A15: Consent & Documentation | B15: Monthly | C15: 12 monthly sections | D15: Consent & Documentation tab | F15: Not Started | H15: Regulations and Quality Statements mapped in audit
A16: Falls Audit | B16: Monthly | C16: Manager / Lead | D16: Reg 12/17 | E16: Evidence, action and verification
A17: Pressure Cushion Audit | B17: Monthly | C17: Manager / Lead | D17: Reg 12/17 | E17: Evidence, action and verification
A18: Controlled Drugs Audit | B18: Monthly | C18: Manager / Lead | D18: Reg 12/17 | E18: Evidence, action and verification
A19: PRN Protocol Audit | B19: Monthly | C19: Manager / Lead | D19: Reg 12/17 | E19: Evidence, action and verification
A20: Homely Remedies Audit | B20: Monthly | C20: Manager / Lead | D20: Reg 12/17 | E20: Evidence, action and verification
A21: Medication Fridge Audit | B21: Monthly | C21: Manager / Lead | D21: Reg 12/17 | E21: Evidence, action and verification

Sheet Missing Audits Dashboard
A1: Missing Audits Dashboard – Annual Compliance, RAG and Actions
A3: Audit Area | B3: Frequency | C3: Periods Expected | D3: Periods Completed | E3: Completion % | F3: Average Compliance | G3: Current RAG | H3: High Risk Periods | I3: Open Actions | J3: Overdue Actions | K3: Latest Audit Date | L3: Lowest Period % | M3: Highest Period % | N3: Notes
A4: Equipment & Maintenance | B4: Weekly | C4: 52 | D4: =COUNTIF('Equipment & Maintenance'!H5:H56,"Green")+COUNTIF('Equipment & Maintenance'!H5:H56,"Amber")+COUNTIF('Equipment & Maintenance'!H5:H56,"Red") -> 0 | E4: =IF(C4=0,"",D4/C4) -> 0 | F4: =IFERROR(AVERAGE('Equipment & Maintenance'!G5:G56),"") | G4: =IF(F4="","Not Started",IF(F4>=0.9,"Green",IF(F4>=0.75,"Amber","Red"))) -> Not Started | H4: =SUM('Equipment & Maintenance'!I5:I56) -> 0 | I4: =SUM('Equipment & Maintenance'!J5:J56) -> 0 | J4: =SUM('Equipment & Maintenance'!K5:K56) -> 0 | K4: =MAX('Equipment & Maintenance'!C5:C56) -> 0 | L4: =IFERROR(MIN('Equipment & Maintenance'!G5:G56),"") -> 0 | M4: =IFERROR(MAX('Equipment & Maintenance'!G5:G56),"") -> 0
A5: Water & Legionella | B5: Weekly | C5: 52 | D5: =COUNTIF('Water & Legionella'!H5:H56,"Green")+COUNTIF('Water & Legionella'!H5:H56,"Amber")+COUNTIF('Water & Legionella'!H5:H56,"Red") -> 0 | E5: =IF(C5=0,"",D5/C5) -> 0 | F5: =IFERROR(AVERAGE('Water & Legionella'!G5:G56),"") | G5: =IF(F5="","Not Started",IF(F5>=0.9,"Green",IF(F5>=0.75,"Amber","Red"))) -> Not Started | H5: =SUM('Water & Legionella'!I5:I56) -> 0 | I5: =SUM('Water & Legionella'!J5:J56) -> 0 | J5: =SUM('Water & Legionella'!K5:K56) -> 0 | K5: =MAX('Water & Legionella'!C5:C56) -> 0 | L5: =IFERROR(MIN('Water & Legionella'!G5:G56),"") -> 0 | M5: =IFERROR(MAX('Water & Legionella'!G5:G56),"") -> 0
A6: Infection Surveillance | B6: Weekly | C6: 52 | D6: =COUNTIF('Infection Surveillance'!H5:H56,"Green")+COUNTIF('Infection Surveillance'!H5:H56,"Amber")+COUNTIF('Infection Surveillance'!H5:H56,"Red") -> 0 | E6: =IF(C6=0,"",D6/C6) -> 0 | F6: =IFERROR(AVERAGE('Infection Surveillance'!G5:G56),"") | G6: =IF(F6="","Not Started",IF(F6>=0.9,"Green",IF(F6>=0.75,"Amber","Red"))) -> Not Started | H6: =SUM('Infection Surveillance'!I5:I56) -> 0 | I6: =SUM('Infection Surveillance'!J5:J56) -> 0 | J6: =SUM('Infection Surveillance'!K5:K56) -> 0 | K6: =MAX('Infection Surveillance'!C5:C56) -> 0 | L6: =IFERROR(MIN('Infection Surveillance'!G5:G56),"") -> 0 | M6: =IFERROR(MAX('Infection Surveillance'!G5:G56),"") -> 0
A7: Resident Dignity | B7: Monthly | C7: 12 | D7: =COUNTIF('Resident Dignity'!H5:H16,"Green")+COUNTIF('Resident Dignity'!H5:H16,"Amber")+COUNTIF('Resident Dignity'!H5:H16,"Red") -> 0 | E7: =IF(C7=0,"",D7/C7) -> 0 | F7: =IFERROR(AVERAGE('Resident Dignity'!G5:G16),"") | G7: =IF(F7="","Not Started",IF(F7>=0.9,"Green",IF(F7>=0.75,"Amber","Red"))) -> Not Started | H7: =SUM('Resident Dignity'!I5:I16) -> 0 | I7: =SUM('Resident Dignity'!J5:J16) -> 0 | J7: =SUM('Resident Dignity'!K5:K16) -> 0 | K7: =MAX('Resident Dignity'!C5:C16) -> 0 | L7: =IFERROR(MIN('Resident Dignity'!G5:G16),"") -> 0 | M7: =IFERROR(MAX('Resident Dignity'!G5:G16),"") -> 0
A8: Personnel & Workforce | B8: Monthly | C8: 12 | D8: =COUNTIF('Personnel & Workforce'!H5:H16,"Green")+COUNTIF('Personnel & Workforce'!H5:H16,"Amber")+COUNTIF('Personnel & Workforce'!H5:H16,"Red") -> 0 | E8: =IF(C8=0,"",D8/C8) -> 0 | F8: =IFERROR(AVERAGE('Personnel & Workforce'!G5:G16),"") | G8: =IF(F8="","Not Started",IF(F8>=0.9,"Green",IF(F8>=0.75,"Amber","Red"))) -> Not Started | H8: =SUM('Personnel & Workforce'!I5:I16) -> 0 | I8: =SUM('Personnel & Workforce'!J5:J16) -> 0 | J8: =SUM('Personnel & Workforce'!K5:K16) -> 0 | K8: =MAX('Personnel & Workforce'!C5:C16) -> 0 | L8: =IFERROR(MIN('Personnel & Workforce'!G5:G16),"") -> 0 | M8: =IFERROR(MAX('Personnel & Workforce'!G5:G16),"") -> 0
A9: Environmental | B9: Monthly | C9: 12 | D9: =COUNTIF(Environmental!H5:H16,"Green")+COUNTIF(Environmental!H5:H16,"Amber")+COUNTIF(Environmental!H5:H16,"Red") -> 0 | E9: =IF(C9=0,"",D9/C9) -> 0 | F9: =IFERROR(AVERAGE(Environmental!G5:G16),"") | G9: =IF(F9="","Not Started",IF(F9>=0.9,"Green",IF(F9>=0.75,"Amber","Red"))) -> Not Started | H9: =SUM(Environmental!I5:I16) -> 0 | I9: =SUM(Environmental!J5:J16) -> 0 | J9: =SUM(Environmental!K5:K16) -> 0 | K9: =MAX(Environmental!C5:C16) -> 0 | L9: =IFERROR(MIN(Environmental!G5:G16),"") -> 0 | M9: =IFERROR(MAX(Environmental!G5:G16),"") -> 0
A10: Nutrition & Hydration | B10: Monthly | C10: 12 | D10: =COUNTIF('Nutrition & Hydration'!H5:H16,"Green")+COUNTIF('Nutrition & Hydration'!H5:H16,"Amber")+COUNTIF('Nutrition & Hydration'!H5:H16,"Red") -> 0 | E10: =IF(C10=0,"",D10/C10) -> 0 | F10: =IFERROR(AVERAGE('Nutrition & Hydration'!G5:G16),"") | G10: =IF(F10="","Not Started",IF(F10>=0.9,"Green",IF(F10>=0.75,"Amber","Red"))) -> Not Started | H10: =SUM('Nutrition & Hydration'!I5:I16) -> 0 | I10: =SUM('Nutrition & Hydration'!J5:J16) -> 0 | J10: =SUM('Nutrition & Hydration'!K5:K16) -> 0 | K10: =MAX('Nutrition & Hydration'!C5:C16) -> 0 | L10: =IFERROR(MIN('Nutrition & Hydration'!G5:G16),"") -> 0 | M10: =IFERROR(MAX('Nutrition & Hydration'!G5:G16),"") -> 0
A11: Safeguarding & Incidents | B11: Monthly | C11: 12 | D11: =COUNTIF('Safeguarding & Incidents'!H5:H16,"Green")+COUNTIF('Safeguarding & Incidents'!H5:H16,"Amber")+COUNTIF('Safeguarding & Incidents'!H5:H16,"Red") -> 0 | E11: =IF(C11=0,"",D11/C11) -> 0 | F11: =IFERROR(AVERAGE('Safeguarding & Incidents'!G5:G16),"") | G11: =IF(F11="","Not Started",IF(F11>=0.9,"Green",IF(F11>=0.75,"Amber","Red"))) -> Not Started | H11: =SUM('Safeguarding & Incidents'!I5:I16) -> 0 | I11: =SUM('Safeguarding & Incidents'!J5:J16) -> 0 | J11: =SUM('Safeguarding & Incidents'!K5:K16) -> 0 | K11: =MAX('Safeguarding & Incidents'!C5:C16) -> 0 | L11: =IFERROR(MIN('Safeguarding & Incidents'!G5:G16),"") -> 0 | M11: =IFERROR(MAX('Safeguarding & Incidents'!G5:G16),"") -> 0
A12: Business Continuity | B12: Monthly | C12: 12 | D12: =COUNTIF('Business Continuity'!H5:H16,"Green")+COUNTIF('Business Continuity'!H5:H16,"Amber")+COUNTIF('Business Continuity'!H5:H16,"Red") -> 0 | E12: =IF(C12=0,"",D12/C12) -> 0 | F12: =IFERROR(AVERAGE('Business Continuity'!G5:G16),"") | G12: =IF(F12="","Not Started",IF(F12>=0.9,"Green",IF(F12>=0.75,"Amber","Red"))) -> Not Started | H12: =SUM('Business Continuity'!I5:I16) -> 0 | I12: =SUM('Business Continuity'!J5:J16) -> 0 | J12: =SUM('Business Continuity'!K5:K16) -> 0 | K12: =MAX('Business Continuity'!C5:C16) -> 0 | L12: =IFERROR(MIN('Business Continuity'!G5:G16),"") -> 0 | M12: =IFERROR(MAX('Business Continuity'!G5:G16),"") -> 0
A13: End of Life | B13: Monthly | C13: 12 | D13: =COUNTIF('End of Life'!H5:H16,"Green")+COUNTIF('End of Life'!H5:H16,"Amber")+COUNTIF('End of Life'!H5:H16,"Red") -> 0 | E13: =IF(C13=0,"",D13/C13) -> 0 | F13: =IFERROR(AVERAGE('End of Life'!G5:G16),"") | G13: =IF(F13="","Not Started",IF(F13>=0.9,"Green",IF(F13>=0.75,"Amber","Red"))) -> Not Started | H13: =SUM('End of Life'!I5:I16) -> 0 | I13: =SUM('End of Life'!J5:J16) -> 0 | J13: =SUM('End of Life'!K5:K16) -> 0 | K13: =MAX('End of Life'!C5:C16) -> 0 | L13: =IFERROR(MIN('End of Life'!G5:G16),"") -> 0 | M13: =IFERROR(MAX('End of Life'!G5:G16),"") -> 0
A14: Finance & Property | B14: Monthly | C14: 12 | D14: =COUNTIF('Finance & Property'!H5:H16,"Green")+COUNTIF('Finance & Property'!H5:H16,"Amber")+COUNTIF('Finance & Property'!H5:H16,"Red") -> 0 | E14: =IF(C14=0,"",D14/C14) -> 0 | F14: =IFERROR(AVERAGE('Finance & Property'!G5:G16),"") | G14: =IF(F14="","Not Started",IF(F14>=0.9,"Green",IF(F14>=0.75,"Amber","Red"))) -> Not Started | H14: =SUM('Finance & Property'!I5:I16) -> 0 | I14: =SUM('Finance & Property'!J5:J16) -> 0 | J14: =SUM('Finance & Property'!K5:K16) -> 0 | K14: =MAX('Finance & Property'!C5:C16) -> 0 | L14: =IFERROR(MIN('Finance & Property'!G5:G16),"") -> 0 | M14: =IFERROR(MAX('Finance & Property'!G5:G16),"") -> 0
A15: Consent & Documentation | B15: Monthly | C15: 12 | D15: =COUNTIF('Consent & Documentation'!H5:H16,"Green")+COUNTIF('Consent & Documentation'!H5:H16,"Amber")+COUNTIF('Consent & Documentation'!H5:H16,"Red") -> 0 | E15: =IF(C15=0,"",D15/C15) -> 0 | F15: =IFERROR(AVERAGE('Consent & Documentation'!G5:G16),"") | G15: =IF(F15="","Not Started",IF(F15>=0.9,"Green",IF(F15>=0.75,"Amber","Red"))) -> Not Started | H15: =SUM('Consent & Documentation'!I5:I16) -> 0 | I15: =SUM('Consent & Documentation'!J5:J16) -> 0 | J15: =SUM('Consent & Documentation'!K5:K16) -> 0 | K15: =MAX('Consent & Documentation'!C5:C16) -> 0 | L15: =IFERROR(MIN('Consent & Documentation'!G5:G16),"") -> 0 | M15: =IFERROR(MAX('Consent & Documentation'!G5:G16),"") -> 0

Sheet Master Action Tracker
A1: Master Action Tracker – Issues Raised From Audit Tabs
A3: Action No. | B3: Source Audit | C3: Period | D3: Question/Issue | E3: Risk | F3: Root Cause / 5 Whys | G3: Immediate Action | H3: Corrective / Preventative Action | I3: Responsible | J3: Due Date | K3: Completed Date | L3: Verified By | M3: Status | N3: RAG
A5: =IF(D5="","","ACT-"&TEXT(ROW()-3,"0000")) | N5: =IF(M5="Closed","Green",IF(AND(J5<>"",J5<TODAY(),K5=""),"Red",IF(M5="In Progress","Amber","Grey"))) -> Grey
A6: =IF(D6="","","ACT-"&TEXT(ROW()-3,"0000")) | N6: =IF(M6="Closed","Green",IF(AND(J6<>"",J6<TODAY(),K6=""),"Red",IF(M6="In Progress","Amber","Grey"))) -> Grey
A7: =IF(D7="","","ACT-"&TEXT(ROW()-3,"0000")) | N7: =IF(M7="Closed","Green",IF(AND(J7<>"",J7<TODAY(),K7=""),"Red",IF(M7="In Progress","Amber","Grey"))) -> Grey
A8: =IF(D8="","","ACT-"&TEXT(ROW()-3,"0000")) | N8: =IF(M8="Closed","Green",IF(AND(J8<>"",J8<TODAY(),K8=""),"Red",IF(M8="In Progress","Amber","Grey"))) -> Grey
A9: =IF(D9="","","ACT-"&TEXT(ROW()-3,"0000")) | N9: =IF(M9="Closed","Green",IF(AND(J9<>"",J9<TODAY(),K9=""),"Red",IF(M9="In Progress","Amber","Grey"))) -> Grey
A10: =IF(D10="","","ACT-"&TEXT(ROW()-3,"0000")) | N10: =IF(M10="Closed","Green",IF(AND(J10<>"",J10<TODAY(),K10=""),"Red",IF(M10="In Progress","Amber","Grey"))) -> Grey
A11: =IF(D11="","","ACT-"&TEXT(ROW()-3,"0000")) | N11: =IF(M11="Closed","Green",IF(AND(J11<>"",J11<TODAY(),K11=""),"Red",IF(M11="In Progress","Amber","Grey"))) -> Grey
A12: =IF(D12="","","ACT-"&TEXT(ROW()-3,"0000")) | N12: =IF(M12="Closed","Green",IF(AND(J12<>"",J12<TODAY(),K12=""),"Red",IF(M12="In Progress","Amber","Grey"))) -> Grey
A13: =IF(D13="","","ACT-"&TEXT(ROW()-3,"0000")) | N13: =IF(M13="Closed","Green",IF(AND(J13<>"",J13<TODAY(),K13=""),"Red",IF(M13="In Progress","Amber","Grey"))) -> Grey
A14: =IF(D14="","","ACT-"&TEXT(ROW()-3,"0000")) | N14: =IF(M14="Closed","Green",IF(AND(J14<>"",J14<TODAY(),K14=""),"Red",IF(M14="In Progress","Amber","Grey"))) -> Grey
A15: =IF(D15="","","ACT-"&TEXT(ROW()-3,"0000")) | N15: =IF(M15="Closed","Green",IF(AND(J15<>"",J15<TODAY(),K15=""),"Red",IF(M15="In Progress","Amber","Grey"))) -> Grey
A16: =IF(D16="","","ACT-"&TEXT(ROW()-3,"0000")) | N16: =IF(M16="Closed","Green",IF(AND(J16<>"",J16<TODAY(),K16=""),"Red",IF(M16="In Progress","Amber","Grey"))) -> Grey
... A204: =IF(D204="","","ACT-"&TEXT(ROW()-3,"0000")) | N204: =IF(M204="Closed","Green",IF(AND(J204<>"",J204<TODAY(),K204=""),"Red",IF(M204="In Progress","Amber","Grey"))) -> Grey

Sheet Inspection Evidence Matrix
A1: Inspection Evidence Matrix – CQC Quality Statement Mapping
A3: CQC Area / Quality Statement | B3: Primary Audit Evidence | C3: Secondary Evidence | D3: Latest Compliance | E3: Current RAG | F3: Outstanding Actions | G3: Evidence Folder Reference | H3: Manager Assurance | I3: Provider Assurance
A4: Safe environments | B4: Equipment & Maintenance; Water & Legionella; Environmental | C4: Health & Safety/Fire in main workbook | D4: Linked via dashboard | E4: RAG in dashboard
A5: Safe systems | B5: Safeguarding & Incidents; Infection Surveillance; Nutrition & Hydration | C5: Care Plan Audit in main workbook | D5: Linked via dashboard | E5: RAG in dashboard
A6: Safeguarding | B6: Safeguarding & Incidents | C6: MCA/DoLS and training evidence | D6: Linked via dashboard | E6: RAG in dashboard
A7: Safe staffing | B7: Personnel & Workforce | C7: Training matrix/supervision tracker | D7: Linked via dashboard | E7: RAG in dashboard
A8: Person-centred care | B8: Resident Dignity; End of Life; Consent & Documentation | C8: Care plan audit | D8: Linked via dashboard | E8: RAG in dashboard
A9: Governance | B9: All missing audits | C9: Dashboard/action tracker | D9: Linked via dashboard | E9: RAG in dashboard

Sheet Equipment & Maintenance
A1: Equipment & Maintenance Audit – Annual Evidence (Weekly)
A2: Instruction: | B2: Complete each period on this tab so the full year is held in one evidence location. Pale yellow cells are editable. Formula/RAG/header cells are locked only, with no password.
A4: Period | B4: Due Date | C4: Audit Date | D4: Auditor | E4: Total Score | F4: Max Score | G4: Compliance % | H4: RAG | I4: Critical/High Risks | J4: Open Actions | K4: Overdue Actions | L4: Manager Sign-Off | M4: Provider Sign-Off | N4: Evidence Folder Ref | O4: Summary / Key Findings
A5: Week 1 | B5: 46023 | E5: =SUMIF(I64:I80,">=0",I64:I80) -> 0 | F5: =COUNT(I64:I80)*2 -> 0 | G5: =IF(F5=0,"",E5/F5) | H5: =IF(G5="","Not Started",IF(G5>=0.9,"Green",IF(G5>=0.75,"Amber","Red"))) -> Not Started | I5: =COUNTIFS(H64:H80,"Critical",I64:I80,"<2")+COUNTIFS(H64:H80,"High",I64:I80,"<2") -> 0 | J5: =COUNTIF(T64:T80,"In Progress")+COUNTIF(T64:T80,"Not Started") -> 0 | K5: =COUNTIFS(P64:P80,"<"&TODAY(),Q64:Q80,"") -> 0
A6: Week 2 | B6: 46030 | E6: =SUMIF(I86:I102,">=0",I86:I102) -> 0 | F6: =COUNT(I86:I102)*2 -> 0 | G6: =IF(F6=0,"",E6/F6) | H6: =IF(G6="","Not Started",IF(G6>=0.9,"Green",IF(G6>=0.75,"Amber","Red"))) -> Not Started | I6: =COUNTIFS(H86:H102,"Critical",I86:I102,"<2")+COUNTIFS(H86:H102,"High",I86:I102,"<2") -> 0 | J6: =COUNTIF(T86:T102,"In Progress")+COUNTIF(T86:T102,"Not Started") -> 0 | K6: =COUNTIFS(P86:P102,"<"&TODAY(),Q86:Q102,"") -> 0
A7: Week 3 | B7: 46037 | E7: =SUMIF(I108:I124,">=0",I108:I124) -> 0 | F7: =COUNT(I108:I124)*2 -> 0 | G7: =IF(F7=0,"",E7/F7) | H7: =IF(G7="","Not Started",IF(G7>=0.9,"Green",IF(G7>=0.75,"Amber","Red"))) -> Not Started | I7: =COUNTIFS(H108:H124,"Critical",I108:I124,"<2")+COUNTIFS(H108:H124,"High",I108:I124,"<2") -> 0 | J7: =COUNTIF(T108:T124,"In Progress")+COUNTIF(T108:T124,"Not Started") -> 0 | K7: =COUNTIFS(P108:P124,"<"&TODAY(),Q108:Q124,"") -> 0
A8: Week 4 | B8: 46044 | E8: =SUMIF(I130:I146,">=0",I130:I146) -> 0 | F8: =COUNT(I130:I146)*2 -> 0 | G8: =IF(F8=0,"",E8/F8) | H8: =IF(G8="","Not Started",IF(G8>=0.9,"Green",IF(G8>=0.75,"Amber","Red"))) -> Not Started | I8: =COUNTIFS(H130:H146,"Critical",I130:I146,"<2")+COUNTIFS(H130:H146,"High",I130:I146,"<2") -> 0 | J8: =COUNTIF(T130:T146,"In Progress")+COUNTIF(T130:T146,"Not Started") -> 0 | K8: =COUNTIFS(P130:P146,"<"&TODAY(),Q130:Q146,"") -> 0
A9: Week 5 | B9: 46051 | E9: =SUMIF(I152:I168,">=0",I152:I168) -> 0 | F9: =COUNT(I152:I168)*2 -> 0 | G9: =IF(F9=0,"",E9/F9) | H9: =IF(G9="","Not Started",IF(G9>=0.9,"Green",IF(G9>=0.75,"Amber","Red"))) -> Not Started | I9: =COUNTIFS(H152:H168,"Critical",I152:I168,"<2")+COUNTIFS(H152:H168,"High",I152:I168,"<2") -> 0 | J9: =COUNTIF(T152:T168,"In Progress")+COUNTIF(T152:T168,"Not Started") -> 0 | K9: =COUNTIFS(P152:P168,"<"&TODAY(),Q152:Q168,"") -> 0
A10: Week 6 | B10: 46058 | E10: =SUMIF(I174:I190,">=0",I174:I190) -> 0 | F10: =COUNT(I174:I190)*2 -> 0 | G10: =IF(F10=0,"",E10/F10) | H10: =IF(G10="","Not Started",IF(G10>=0.9,"Green",IF(G10>=0.75,"Amber","Red"))) -> Not Started | I10: =COUNTIFS(H174:H190,"Critical",I174:I190,"<2")+COUNTIFS(H174:H190,"High",I174:I190,"<2") -> 0 | J10: =COUNTIF(T174:T190,"In Progress")+COUNTIF(T174:T190,"Not Started") -> 0 | K10: =COUNTIFS(P174:P190,"<"&TODAY(),Q174:Q190,"") -> 0
A11: Week 7 | B11: 46065 | E11: =SUMIF(I196:I212,">=0",I196:I212) -> 0 | F11: =COUNT(I196:I212)*2 -> 0 | G11: =IF(F11=0,"",E11/F11) | H11: =IF(G11="","Not Started",IF(G11>=0.9,"Green",IF(G11>=0.75,"Amber","Red"))) -> Not Started | I11: =COUNTIFS(H196:H212,"Critical",I196:I212,"<2")+COUNTIFS(H196:H212,"High",I196:I212,"<2") -> 0 | J11: =COUNTIF(T196:T212,"In Progress")+COUNTIF(T196:T212,"Not Started") -> 0 | K11: =COUNTIFS(P196:P212,"<"&TODAY(),Q196:Q212,"") -> 0
A12: Week 8 | B12: 46072 | E12: =SUMIF(I218:I234,">=0",I218:I234) -> 0 | F12: =COUNT(I218:I234)*2 -> 0 | G12: =IF(F12=0,"",E12/F12) | H12: =IF(G12="","Not Started",IF(G12>=0.9,"Green",IF(G12>=0.75,"Amber","Red"))) -> Not Started | I12: =COUNTIFS(H218:H234,"Critical",I218:I234,"<2")+COUNTIFS(H218:H234,"High",I218:I234,"<2") -> 0 | J12: =COUNTIF(T218:T234,"In Progress")+COUNTIF(T218:T234,"Not Started") -> 0 | K12: =COUNTIFS(P218:P234,"<"&TODAY(),Q218:Q234,"") -> 0
A13: Week 9 | B13: 46079 | E13: =SUMIF(I240:I256,">=0",I240:I256) -> 0 | F13: =COUNT(I240:I256)*2 -> 0 | G13: =IF(F13=0,"",E13/F13) | H13: =IF(G13="","Not Started",IF(G13>=0.9,"Green",IF(G13>=0.75,"Amber","Red"))) -> Not Started | I13: =COUNTIFS(H240:H256,"Critical",I240:I256,"<2")+COUNTIFS(H240:H256,"High",I240:I256,"<2") -> 0 | J13: =COUNTIF(T240:T256,"In Progress")+COUNTIF(T240:T256,"Not Started") -> 0 | K13: =COUNTIFS(P240:P256,"<"&TODAY(),Q240:Q256,"") -> 0
A14: Week 10 | B14: 46086 | E14: =SUMIF(I262:I278,">=0",I262:I278) -> 0 | F14: =COUNT(I262:I278)*2 -> 0 | G14: =IF(F14=0,"",E14/F14) | H14: =IF(G14="","Not Started",IF(G14>=0.9,"Green",IF(G14>=0.75,"Amber","Red"))) -> Not Started | I14: =COUNTIFS(H262:H278,"Critical",I262:I278,"<2")+COUNTIFS(H262:H278,"High",I262:I278,"<2") -> 0 | J14: =COUNTIF(T262:T278,"In Progress")+COUNTIF(T262:T278,"Not Started") -> 0 | K14: =COUNTIFS(P262:P278,"<"&TODAY(),Q262:Q278,"") -> 0
A15: Week 11 | B15: 46093 | E15: =SUMIF(I284:I300,">=0",I284:I300) -> 0 | F15: =COUNT(I284:I300)*2 -> 0 | G15: =IF(F15=0,"",E15/F15) | H15: =IF(G15="","Not Started",IF(G15>=0.9,"Green",IF(G15>=0.75,"Amber","Red"))) -> Not Started | I15: =COUNTIFS(H284:H300,"Critical",I284:I300,"<2")+COUNTIFS(H284:H300,"High",I284:I300,"<2") -> 0 | J15: =COUNTIF(T284:T300,"In Progress")+COUNTIF(T284:T300,"Not Started") -> 0 | K15: =COUNTIFS(P284:P300,"<"&TODAY(),Q284:Q300,"") -> 0
A16: Week 12 | B16: 46100 | E16: =SUMIF(I306:I322,">=0",I306:I322) -> 0 | F16: =COUNT(I306:I322)*2 -> 0 | G16: =IF(F16=0,"",E16/F16) | H16: =IF(G16="","Not Started",IF(G16>=0.9,"Green",IF(G16>=0.75,"Amber","Red"))) -> Not Started | I16: =COUNTIFS(H306:H322,"Critical",I306:I322,"<2")+COUNTIFS(H306:H322,"High",I306:I322,"<2") -> 0 | J16: =COUNTIF(T306:T322,"In Progress")+COUNTIF(T306:T322,"Not Started") -> 0 | K16: =COUNTIFS(P306:P322,"<"&TODAY(),Q306:Q322,"") -> 0
A17: Week 13 | B17: 46107 | E17: =SUMIF(I328:I344,">=0",I328:I344) -> 0 | F17: =COUNT(I328:I344)*2 -> 0 | G17: =IF(F17=0,"",E17/F17) | H17: =IF(G17="","Not Started",IF(G17>=0.9,"Green",IF(G17>=0.75,"Amber","Red"))) -> Not Started | I17: =COUNTIFS(H328:H344,"Critical",I328:I344,"<2")+COUNTIFS(H328:H344,"High",I328:I344,"<2") -> 0 | J17: =COUNTIF(T328:T344,"In Progress")+COUNTIF(T328:T344,"Not Started") -> 0 | K17: =COUNTIFS(P328:P344,"<"&TODAY(),Q328:Q344,"") -> 0
A18: Week 14 | B18: 46114 | E18: =SUMIF(I350:I366,">=0",I350:I366) -> 0 | F18: =COUNT(I350:I366)*2 -> 0 | G18: =IF(F18=0,"",E18/F18) | H18: =IF(G18="","Not Started",IF(G18>=0.9,"Green",IF(G18>=0.75,"Amber","Red"))) -> Not Started | I18: =COUNTIFS(H350:H366,"Critical",I350:I366,"<2")+COUNTIFS(H350:H366,"High",I350:I366,"<2") -> 0 | J18: =COUNTIF(T350:T366,"In Progress")+COUNTIF(T350:T366,"Not Started") -> 0 | K18: =COUNTIFS(P350:P366,"<"&TODAY(),Q350:Q366,"") -> 0
A19: Week 15 | B19: 46121 | E19: =SUMIF(I372:I388,">=0",I372:I388) -> 0 | F19: =COUNT(I372:I388)*2 -> 0 | G19: =IF(F19=0,"",E19/F19) | H19: =IF(G19="","Not Started",IF(G19>=0.9,"Green",IF(G19>=0.75,"Amber","Red"))) -> Not Started | I19: =COUNTIFS(H372:H388,"Critical",I372:I388,"<2")+COUNTIFS(H372:H388,"High",I372:I388,"<2") -> 0 | J19: =COUNTIF(T372:T388,"In Progress")+COUNTIF(T372:T388,"Not Started") -> 0 | K19: =COUNTIFS(P372:P388,"<"&TODAY(),Q372:Q388,"") -> 0
A20: Week 16 | B20: 46128 | E20: =SUMIF(I394:I410,">=0",I394:I410) -> 0 | F20: =COUNT(I394:I410)*2 -> 0 | G20: =IF(F20=0,"",E20/F20) | H20: =IF(G20="","Not Started",IF(G20>=0.9,"Green",IF(G20>=0.75,"Amber","Red"))) -> Not Started | I20: =COUNTIFS(H394:H410,"Critical",I394:I410,"<2")+COUNTIFS(H394:H410,"High",I394:I410,"<2") -> 0 | J20: =COUNTIF(T394:T410,"In Progress")+COUNTIF(T394:T410,"Not Started") -> 0 | K20: =COUNTIFS(P394:P410,"<"&TODAY(),Q394:Q410,"") -> 0
A21: Week 17 | B21: 46135 | E21: =SUMIF(I416:I432,">=0",I416:I432) -> 0 | F21: =COUNT(I416:I432)*2 -> 0 | G21: =IF(F21=0,"",E21/F21) | H21: =IF(G21="","Not Started",IF(G21>=0.9,"Green",IF(G21>=0.75,"Amber","Red"))) -> Not Started | I21: =COUNTIFS(H416:H432,"Critical",I416:I432,"<2")+COUNTIFS(H416:H432,"High",I416:I432,"<2") -> 0 | J21: =COUNTIF(T416:T432,"In Progress")+COUNTIF(T416:T432,"Not Started") -> 0 | K21: =COUNTIFS(P416:P432,"<"&TODAY(),Q416:Q432,"") -> 0
A22: Week 18 | B22: 46142 | E22: =SUMIF(I438:I454,">=0",I438:I454) -> 0 | F22: =COUNT(I438:I454)*2 -> 0 | G22: =IF(F22=0,"",E22/F22) | H22: =IF(G22="","Not Started",IF(G22>=0.9,"Green",IF(G22>=0.75,"Amber","Red"))) -> Not Started | I22: =COUNTIFS(H438:H454,"Critical",I438:I454,"<2")+COUNTIFS(H438:H454,"High",I438:I454,"<2") -> 0 | J22: =COUNTIF(T438:T454,"In Progress")+COUNTIF(T438:T454,"Not Started") -> 0 | K22: =COUNTIFS(P438:P454,"<"&TODAY(),Q438:Q454,"") -> 0
A23: Week 19 | B23: 46149 | E23: =SUMIF(I460:I476,">=0",I460:I476) -> 0 | F23: =COUNT(I460:I476)*2 -> 0 | G23: =IF(F23=0,"",E23/F23) | H23: =IF(G23="","Not Started",IF(G23>=0.9,"Green",IF(G23>=0.75,"Amber","Red"))) -> Not Started | I23: =COUNTIFS(H460:H476,"Critical",I460:I476,"<2")+COUNTIFS(H460:H476,"High",I460:I476,"<2") -> 0 | J23: =COUNTIF(T460:T476,"In Progress")+COUNTIF(T460:T476,"Not Started") -> 0 | K23: =COUNTIFS(P460:P476,"<"&TODAY(),Q460:Q476,"") -> 0
A24: Week 20 | B24: 46156 | E24: =SUMIF(I482:I498,">=0",I482:I498) -> 0 | F24: =COUNT(I482:I498)*2 -> 0 | G24: =IF(F24=0,"",E24/F24) | H24: =IF(G24="","Not Started",IF(G24>=0.9,"Green",IF(G24>=0.75,"Amber","Red"))) -> Not Started | I24: =COUNTIFS(H482:H498,"Critical",I482:I498,"<2")+COUNTIFS(H482:H498,"High",I482:I498,"<2") -> 0 | J24: =COUNTIF(T482:T498,"In Progress")+COUNTIF(T482:T498,"Not Started") -> 0 | K24: =COUNTIFS(P482:P498,"<"&TODAY(),Q482:Q498,"") -> 0
A25: Week 21 | B25: 46163 | E25: =SUMIF(I504:I520,">=0",I504:I520) -> 0 | F25: =COUNT(I504:I520)*2 -> 0 | G25: =IF(F25=0,"",E25/F25) | H25: =IF(G25="","Not Started",IF(G25>=0.9,"Green",IF(G25>=0.75,"Amber","Red"))) -> Not Started | I25: =COUNTIFS(H504:H520,"Critical",I504:I520,"<2")+COUNTIFS(H504:H520,"High",I504:I520,"<2") -> 0 | J25: =COUNTIF(T504:T520,"In Progress")+COUNTIF(T504:T520,"Not Started") -> 0 | K25: =COUNTIFS(P504:P520,"<"&TODAY(),Q504:Q520,"") -> 0
A26: Week 22 | B26: 46170 | E26: =SUMIF(I526:I542,">=0",I526:I542) -> 0 | F26: =COUNT(I526:I542)*2 -> 0 | G26: =IF(F26=0,"",E26/F26) | H26: =IF(G26="","Not Started",IF(G26>=0.9,"Green",IF(G26>=0.75,"Amber","Red"))) -> Not Started | I26: =COUNTIFS(H526:H542,"Critical",I526:I542,"<2")+COUNTIFS(H526:H542,"High",I526:I542,"<2") -> 0 | J26: =COUNTIF(T526:T542,"In Progress")+COUNTIF(T526:T542,"Not Started") -> 0 | K26: =COUNTIFS(P526:P542,"<"&TODAY(),Q526:Q542,"") -> 0
A27: Week 23 | B27: 46177 | E27: =SUMIF(I548:I564,">=0",I548:I564) -> 0 | F27: =COUNT(I548:I564)*2 -> 0 | G27: =IF(F27=0,"",E27/F27) | H27: =IF(G27="","Not Started",IF(G27>=0.9,"Green",IF(G27>=0.75,"Amber","Red"))) -> Not Started | I27: =COUNTIFS(H548:H564,"Critical",I548:I564,"<2")+COUNTIFS(H548:H564,"High",I548:I564,"<2") -> 0 | J27: =COUNTIF(T548:T564,"In Progress")+COUNTIF(T548:T564,"Not Started") -> 0 | K27: =COUNTIFS(P548:P564,"<"&TODAY(),Q548:Q564,"") -> 0
A28: Week 24 | B28: 46184 | E28: =SUMIF(I570:I586,">=0",I570:I586) -> 0 | F28: =COUNT(I570:I586)*2 -> 0 | G28: =IF(F28=0,"",E28/F28) | H28: =IF(G28="","Not Started",IF(G28>=0.9,"Green",IF(G28>=0.75,"Amber","Red"))) -> Not Started | I28: =COUNTIFS(H570:H586,"Critical",I570:I586,"<2")+COUNTIFS(H570:H586,"High",I570:I586,"<2") -> 0 | J28: =COUNTIF(T570:T586,"In Progress")+COUNTIF(T570:T586,"Not Started") -> 0 | K28: =COUNTIFS(P570:P586,"<"&TODAY(),Q570:Q586,"") -> 0
A29: Week 25 | B29: 46191 | E29: =SUMIF(I592:I608,">=0",I592:I608) -> 0 | F29: =COUNT(I592:I608)*2 -> 0 | G29: =IF(F29=0,"",E29/F29) | H29: =IF(G29="","Not Started",IF(G29>=0.9,"Green",IF(G29>=0.75,"Amber","Red"))) -> Not Started | I29: =COUNTIFS(H592:H608,"Critical",I592:I608,"<2")+COUNTIFS(H592:H608,"High",I592:I608,"<2") -> 0 | J29: =COUNTIF(T592:T608,"In Progress")+COUNTIF(T592:T608,"Not Started") -> 0 | K29: =COUNTIFS(P592:P608,"<"&TODAY(),Q592:Q608,"") -> 0
A30: Week 26 | B30: 46198 | E30: =SUMIF(I614:I630,">=0",I614:I630) -> 0 | F30: =COUNT(I614:I630)*2 -> 0 | G30: =IF(F30=0,"",E30/F30) | H30: =IF(G30="","Not Started",IF(G30>=0.9,"Green",IF(G30>=0.75,"Amber","Red"))) -> Not Started | I30: =COUNTIFS(H614:H630,"Critical",I614:I630,"<2")+COUNTIFS(H614:H630,"High",I614:I630,"<2") -> 0 | J30: =COUNTIF(T614:T630,"In Progress")+COUNTIF(T614:T630,"Not Started") -> 0 | K30: =COUNTIFS(P614:P630,"<"&TODAY(),Q614:Q630,"") -> 0
A31: Week 27 | B31: 46205 | E31: =SUMIF(I636:I652,">=0",I636:I652) -> 0 | F31: =COUNT(I636:I652)*2 -> 0 | G31: =IF(F31=0,"",E31/F31) | H31: =IF(G31="","Not Started",IF(G31>=0.9,"Green",IF(G31>=0.75,"Amber","Red"))) -> Not Started | I31: =COUNTIFS(H636:H652,"Critical",I636:I652,"<2")+COUNTIFS(H636:H652,"High",I636:I652,"<2") -> 0 | J31: =COUNTIF(T636:T652,"In Progress")+COUNTIF(T636:T652,"Not Started") -> 0 | K31: =COUNTIFS(P636:P652,"<"&TODAY(),Q636:Q652,"") -> 0
A32: Week 28 | B32: 46212 | E32: =SUMIF(I658:I674,">=0",I658:I674) -> 0 | F32: =COUNT(I658:I674)*2 -> 0 | G32: =IF(F32=0,"",E32/F32) | H32: =IF(G32="","Not Started",IF(G32>=0.9,"Green",IF(G32>=0.75,"Amber","Red"))) -> Not Started | I32: =COUNTIFS(H658:H674,"Critical",I658:I674,"<2")+COUNTIFS(H658:H674,"High",I658:I674,"<2") -> 0 | J32: =COUNTIF(T658:T674,"In Progress")+COUNTIF(T658:T674,"Not Started") -> 0 | K32: =COUNTIFS(P658:P674,"<"&TODAY(),Q658:Q674,"") -> 0
A33: Week 29 | B33: 46219 | E33: =SUMIF(I680:I696,">=0",I680:I696) -> 0 | F33: =COUNT(I680:I696)*2 -> 0 | G33: =IF(F33=0,"",E33/F33) | H33: =IF(G33="","Not Started",IF(G33>=0.9,"Green",IF(G33>=0.75,"Amber","Red"))) -> Not Started | I33: =COUNTIFS(H680:H696,"Critical",I680:I696,"<2")+COUNTIFS(H680:H696,"High",I680:I696,"<2") -> 0 | J33: =COUNTIF(T680:T696,"In Progress")+COUNTIF(T680:T696,"Not Started") -> 0 | K33: =COUNTIFS(P680:P696,"<"&TODAY(),Q680:Q696,"") -> 0
A34: Week 30 | B34: 46226 | E34: =SUMIF(I702:I718,">=0",I702:I718) -> 0 | F34: =COUNT(I702:I718)*2 -> 0 | G34: =IF(F34=0,"",E34/F34) | H34: =IF(G34="","Not Started",IF(G34>=0.9,"Green",IF(G34>=0.75,"Amber","Red"))) -> Not Started | I34: =COUNTIFS(H702:H718,"Critical",I702:I718,"<2")+COUNTIFS(H702:H718,"High",I702:I718,"<2") -> 0 | J34: =COUNTIF(T702:T718,"In Progress")+COUNTIF(T702:T718,"Not Started") -> 0 | K34: =COUNTIFS(P702:P718,"<"&TODAY(),Q702:Q718,"") -> 0
A35: Week 31 | B35: 46233 | E35: =SUMIF(I724:I740,">=0",I724:I740) -> 0 | F35: =COUNT(I724:I740)*2 -> 0 | G35: =IF(F35=0,"",E35/F35) | H35: =IF(G35="","Not Started",IF(G35>=0.9,"Green",IF(G35>=0.75,"Amber","Red"))) -> Not Started | I35: =COUNTIFS(H724:H740,"Critical",I724:I740,"<2")+COUNTIFS(H724:H740,"High",I724:I740,"<2") -> 0 | J35: =COUNTIF(T724:T740,"In Progress")+COUNTIF(T724:T740,"Not Started") -> 0 | K35: =COUNTIFS(P724:P740,"<"&TODAY(),Q724:Q740,"") -> 0
A36: Week 32 | B36: 46240 | E36: =SUMIF(I746:I762,">=0",I746:I762) -> 0 | F36: =COUNT(I746:I762)*2 -> 0 | G36: =IF(F36=0,"",E36/F36) | H36: =IF(G36="","Not Started",IF(G36>=0.9,"Green",IF(G36>=0.75,"Amber","Red"))) -> Not Started | I36: =COUNTIFS(H746:H762,"Critical",I746:I762,"<2")+COUNTIFS(H746:H762,"High",I746:I762,"<2") -> 0 | J36: =COUNTIF(T746:T762,"In Progress")+COUNTIF(T746:T762,"Not Started") -> 0 | K36: =COUNTIFS(P746:P762,"<"&TODAY(),Q746:Q762,"") -> 0
A37: Week 33 | B37: 46247 | E37: =SUMIF(I768:I784,">=0",I768:I784) -> 0 | F37: =COUNT(I768:I784)*2 -> 0 | G37: =IF(F37=0,"",E37/F37) | H37: =IF(G37="","Not Started",IF(G37>=0.9,"Green",IF(G37>=0.75,"Amber","Red"))) -> Not Started | I37: =COUNTIFS(H768:H784,"Critical",I768:I784,"<2")+COUNTIFS(H768:H784,"High",I768:I784,"<2") -> 0 | J37: =COUNTIF(T768:T784,"In Progress")+COUNTIF(T768:T784,"Not Started") -> 0 | K37: =COUNTIFS(P768:P784,"<"&TODAY(),Q768:Q784,"") -> 0
A38: Week 34 | B38: 46254 | E38: =SUMIF(I790:I806,">=0",I790:I806) -> 0 | F38: =COUNT(I790:I806)*2 -> 0 | G38: =IF(F38=0,"",E38/F38) | H38: =IF(G38="","Not Started",IF(G38>=0.9,"Green",IF(G38>=0.75,"Amber","Red"))) -> Not Started | I38: =COUNTIFS(H790:H806,"Critical",I790:I806,"<2")+COUNTIFS(H790:H806,"High",I790:I806,"<2") -> 0 | J38: =COUNTIF(T790:T806,"In Progress")+COUNTIF(T790:T806,"Not Started") -> 0 | K38: =COUNTIFS(P790:P806,"<"&TODAY(),Q790:Q806,"") -> 0
A39: Week 35 | B39: 46261 | E39: =SUMIF(I812:I828,">=0",I812:I828) -> 0 | F39: =COUNT(I812:I828)*2 -> 0 | G39: =IF(F39=0,"",E39/F39) | H39: =IF(G39="","Not Started",IF(G39>=0.9,"Green",IF(G39>=0.75,"Amber","Red"))) -> Not Started | I39: =COUNTIFS(H812:H828,"Critical",I812:I828,"<2")+COUNTIFS(H812:H828,"High",I812:I828,"<2") -> 0 | J39: =COUNTIF(T812:T828,"In Progress")+COUNTIF(T812:T828,"Not Started") -> 0 | K39: =COUNTIFS(P812:P828,"<"&TODAY(),Q812:Q828,"") -> 0
A40: Week 36 | B40: 46268 | E40: =SUMIF(I834:I850,">=0",I834:I850) -> 0 | F40: =COUNT(I834:I850)*2 -> 0 | G40: =IF(F40=0,"",E40/F40) | H40: =IF(G40="","Not Started",IF(G40>=0.9,"Green",IF(G40>=0.75,"Amber","Red"))) -> Not Started | I40: =COUNTIFS(H834:H850,"Critical",I834:I850,"<2")+COUNTIFS(H834:H850,"High",I834:I850,"<2") -> 0 | J40: =COUNTIF(T834:T850,"In Progress")+COUNTIF(T834:T850,"Not Started") -> 0 | K40: =COUNTIFS(P834:P850,"<"&TODAY(),Q834:Q850,"") -> 0
A41: Week 37 | B41: 46275 | E41: =SUMIF(I856:I872,">=0",I856:I872) -> 0 | F41: =COUNT(I856:I872)*2 -> 0 | G41: =IF(F41=0,"",E41/F41) | H41: =IF(G41="","Not Started",IF(G41>=0.9,"Green",IF(G41>=0.75,"Amber","Red"))) -> Not Started | I41: =COUNTIFS(H856:H872,"Critical",I856:I872,"<2")+COUNTIFS(H856:H872,"High",I856:I872,"<2") -> 0 | J41: =COUNTIF(T856:T872,"In Progress")+COUNTIF(T856:T872,"Not Started") -> 0 | K41: =COUNTIFS(P856:P872,"<"&TODAY(),Q856:Q872,"") -> 0
...

Sheet Water & Legionella
A1: Water & Legionella Audit – Annual Evidence (Weekly)
A2: Instruction: | B2: Complete each period on this tab so the full year is held in one evidence location. Pale yellow cells are editable. Formula/RAG/header cells are locked only, with no password.
A4: Period | B4: Due Date | C4: Audit Date | D4: Auditor | E4: Total Score | F4: Max Score | G4: Compliance % | H4: RAG | I4: Critical/High Risks | J4: Open Actions | K4: Overdue Actions | L4: Manager Sign-Off | M4: Provider Sign-Off | N4: Evidence Folder Ref | O4: Summary / Key Findings
A5: Week 1 | B5: 46023 | E5: =SUMIF(I64:I75,">=0",I64:I75) -> 0 | F5: =COUNT(I64:I75)*2 -> 0 | G5: =IF(F5=0,"",E5/F5) | H5: =IF(G5="","Not Started",IF(G5>=0.9,"Green",IF(G5>=0.75,"Amber","Red"))) -> Not Started | I5: =COUNTIFS(H64:H75,"Critical",I64:I75,"<2")+COUNTIFS(H64:H75,"High",I64:I75,"<2") -> 0 | J5: =COUNTIF(T64:T75,"In Progress")+COUNTIF(T64:T75,"Not Started") -> 0 | K5: =COUNTIFS(P64:P75,"<"&TODAY(),Q64:Q75,"") -> 0
A6: Week 2 | B6: 46030 | E6: =SUMIF(I81:I92,">=0",I81:I92) -> 0 | F6: =COUNT(I81:I92)*2 -> 0 | G6: =IF(F6=0,"",E6/F6) | H6: =IF(G6="","Not Started",IF(G6>=0.9,"Green",IF(G6>=0.75,"Amber","Red"))) -> Not Started | I6: =COUNTIFS(H81:H92,"Critical",I81:I92,"<2")+COUNTIFS(H81:H92,"High",I81:I92,"<2") -> 0 | J6: =COUNTIF(T81:T92,"In Progress")+COUNTIF(T81:T92,"Not Started") -> 0 | K6: =COUNTIFS(P81:P92,"<"&TODAY(),Q81:Q92,"") -> 0
A7: Week 3 | B7: 46037 | E7: =SUMIF(I98:I109,">=0",I98:I109) -> 0 | F7: =COUNT(I98:I109)*2 -> 0 | G7: =IF(F7=0,"",E7/F7) | H7: =IF(G7="","Not Started",IF(G7>=0.9,"Green",IF(G7>=0.75,"Amber","Red"))) -> Not Started | I7: =COUNTIFS(H98:H109,"Critical",I98:I109,"<2")+COUNTIFS(H98:H109,"High",I98:I109,"<2") -> 0 | J7: =COUNTIF(T98:T109,"In Progress")+COUNTIF(T98:T109,"Not Started") -> 0 | K7: =COUNTIFS(P98:P109,"<"&TODAY(),Q98:Q109,"") -> 0
A8: Week 4 | B8: 46044 | E8: =SUMIF(I115:I126,">=0",I115:I126) -> 0 | F8: =COUNT(I115:I126)*2 -> 0 | G8: =IF(F8=0,"",E8/F8) | H8: =IF(G8="","Not Started",IF(G8>=0.9,"Green",IF(G8>=0.75,"Amber","Red"))) -> Not Started | I8: =COUNTIFS(H115:H126,"Critical",I115:I126,"<2")+COUNTIFS(H115:H126,"High",I115:I126,"<2") -> 0 | J8: =COUNTIF(T115:T126,"In Progress")+COUNTIF(T115:T126,"Not Started") -> 0 | K8: =COUNTIFS(P115:P126,"<"&TODAY(),Q115:Q126,"") -> 0
A9: Week 5 | B9: 46051 | E9: =SUMIF(I132:I143,">=0",I132:I143) -> 0 | F9: =COUNT(I132:I143)*2 -> 0 | G9: =IF(F9=0,"",E9/F9) | H9: =IF(G9="","Not Started",IF(G9>=0.9,"Green",IF(G9>=0.75,"Amber","Red"))) -> Not Started | I9: =COUNTIFS(H132:H143,"Critical",I132:I143,"<2")+COUNTIFS(H132:H143,"High",I132:I143,"<2") -> 0 | J9: =COUNTIF(T132:T143,"In Progress")+COUNTIF(T132:T143,"Not Started") -> 0 | K9: =COUNTIFS(P132:P143,"<"&TODAY(),Q132:Q143,"") -> 0
A10: Week 6 | B10: 46058 | E10: =SUMIF(I149:I160,">=0",I149:I160) -> 0 | F10: =COUNT(I149:I160)*2 -> 0 | G10: =IF(F10=0,"",E10/F10) | H10: =IF(G10="","Not Started",IF(G10>=0.9,"Green",IF(G10>=0.75,"Amber","Red"))) -> Not Started | I10: =COUNTIFS(H149:H160,"Critical",I149:I160,"<2")+COUNTIFS(H149:H160,"High",I149:I160,"<2") -> 0 | J10: =COUNTIF(T149:T160,"In Progress")+COUNTIF(T149:T160,"Not Started") -> 0 | K10: =COUNTIFS(P149:P160,"<"&TODAY(),Q149:Q160,"") -> 0
A11: Week 7 | B11: 46065 | E11: =SUMIF(I166:I177,">=0",I166:I177) -> 0 | F11: =COUNT(I166:I177)*2 -> 0 | G11: =IF(F11=0,"",E11/F11) | H11: =IF(G11="","Not Started",IF(G11>=0.9,"Green",IF(G11>=0.75,"Amber","Red"))) -> Not Started | I11: =COUNTIFS(H166:H177,"Critical",I166:I177,"<2")+COUNTIFS(H166:H177,"High",I166:I177,"<2") -> 0 | J11: =COUNTIF(T166:T177,"In Progress")+COUNTIF(T166:T177,"Not Started") -> 0 | K11: =COUNTIFS(P166:P177,"<"&TODAY(),Q166:Q177,"") -> 0
A12: Week 8 | B12: 46072 | E12: =SUMIF(I183:I194,">=0",I183:I194) -> 0 | F12: =COUNT(I183:I194)*2 -> 0 | G12: =IF(F12=0,"",E12/F12) | H12: =IF(G12="","Not Started",IF(G12>=0.9,"Green",IF(G12>=0.75,"Amber","Red"))) -> Not Started | I12: =COUNTIFS(H183:H194,"Critical",I183:I194,"<2")+COUNTIFS(H183:H194,"High",I183:I194,"<2") -> 0 | J12: =COUNTIF(T183:T194,"In Progress")+COUNTIF(T183:T194,"Not Started") -> 0 | K12: =COUNTIFS(P183:P194,"<"&TODAY(),Q183:Q194,"") -> 0
A13: Week 9 | B13: 46079 | E13: =SUMIF(I200:I211,">=0",I200:I211) -> 0 | F13: =COUNT(I200:I211)*2 -> 0 | G13: =IF(F13=0,"",E13/F13) | H13: =IF(G13="","Not Started",IF(G13>=0.9,"Green",IF(G13>=0.75,"Amber","Red"))) -> Not Started | I13: =COUNTIFS(H200:H211,"Critical",I200:I211,"<2")+COUNTIFS(H200:H211,"High",I200:I211,"<2") -> 0 | J13: =COUNTIF(T200:T211,"In Progress")+COUNTIF(T200:T211,"Not Started") -> 0 | K13: =COUNTIFS(P200:P211,"<"&TODAY(),Q200:Q211,"") -> 0
A14: Week 10 | B14: 46086 | E14: =SUMIF(I217:I228,">=0",I217:I228) -> 0 | F14: =COUNT(I217:I228)*2 -> 0 | G14: =IF(F14=0,"",E14/F14) | H14: =IF(G14="","Not Started",IF(G14>=0.9,"Green",IF(G14>=0.75,"Amber","Red"))) -> Not Started | I14: =COUNTIFS(H217:H228,"Critical",I217:I228,"<2")+COUNTIFS(H217:H228,"High",I217:I228,"<2") -> 0 | J14: =COUNTIF(T217:T228,"In Progress")+COUNTIF(T217:T228,"Not Started") -> 0 | K14: =COUNTIFS(P217:P228,"<"&TODAY(),Q217:Q228,"") -> 0
A15: Week 11 | B15: 46093 | E15: =SUMIF(I234:I245,">=0",I234:I245) -> 0 | F15: =COUNT(I234:I245)*2 -> 0 | G15: =IF(F15=0,"",E15/F15) | H15: =IF(G15="","Not Started",IF(G15>=0.9,"Green",IF(G15>=0.75,"Amber","Red"))) -> Not Started | I15: =COUNTIFS(H234:H245,"Critical",I234:I245,"<2")+COUNTIFS(H234:H245,"High",I234:I245,"<2") -> 0 | J15: =COUNTIF(T234:T245,"In Progress")+COUNTIF(T234:T245,"Not Started") -> 0 | K15: =COUNTIFS(P234:P245,"<"&TODAY(),Q234:Q245,"") -> 0
A16: Week 12 | B16: 46100 | E16: =SUMIF(I251:I262,">=0",I251:I262) -> 0 | F16: =COUNT(I251:I262)*2 -> 0 | G16: =IF(F16=0,"",E16/F16) | H16: =IF(G16="","Not Started",IF(G16>=0.9,"Green",IF(G16>=0.75,"Amber","Red"))) -> Not Started | I16: =COUNTIFS(H251:H262,"Critical",I251:I262,"<2")+COUNTIFS(H251:H262,"High",I251:I262,"<2") -> 0 | J16: =COUNTIF(T251:T262,"In Progress")+COUNTIF(T251:T262,"Not Started") -> 0 | K16: =COUNTIFS(P251:P262,"<"&TODAY(),Q251:Q262,"") -> 0
A17: Week 13 | B17: 46107 | E17: =SUMIF(I268:I279,">=0",I268:I279) -> 0 | F17: =COUNT(I268:I279)*2 -> 0 | G17: =IF(F17=0,"",E17/F17) | H17: =IF(G17="","Not Started",IF(G17>=0.9,"Green",IF(G17>=0.75,"Amber","Red"))) -> Not Started | I17: =COUNTIFS(H268:H279,"Critical",I268:I279,"<2")+COUNTIFS(H268:H279,"High",I268:I279,"<2") -> 0 | J17: =COUNTIF(T268:T279,"In Progress")+COUNTIF(T268:T279,"Not Started") -> 0 | K17: =COUNTIFS(P268:P279,"<"&TODAY(),Q268:Q279,"") -> 0
A18: Week 14 | B18: 46114 | E18: =SUMIF(I285:I296,">=0",I285:I296) -> 0 | F18: =COUNT(I285:I296)*2 -> 0 | G18: =IF(F18=0,"",E18/F18) | H18: =IF(G18="","Not Started",IF(G18>=0.9,"Green",IF(G18>=0.75,"Amber","Red"))) -> Not Started | I18: =COUNTIFS(H285:H296,"Critical",I285:I296,"<2")+COUNTIFS(H285:H296,"High",I285:I296,"<2") -> 0 | J18: =COUNTIF(T285:T296,"In Progress")+COUNTIF(T285:T296,"Not Started") -> 0 | K18: =COUNTIFS(P285:P296,"<"&TODAY(),Q285:Q296,"") -> 0
A19: Week 15 | B19: 46121 | E19: =SUMIF(I302:I313,">=0",I302:I313) -> 0 | F19: =COUNT(I302:I313)*2 -> 0 | G19: =IF(F19=0,"",E19/F19) | H19: =IF(G19="","Not Started",IF(G19>=0.9,"Green",IF(G19>=0.75,"Amber","Red"))) -> Not Started | I19: =COUNTIFS(H302:H313,"Critical",I302:I313,"<2")+COUNTIFS(H302:H313,"High",I302:I313,"<2") -> 0 | J19: =COUNTIF(T302:T313,"In Progress")+COUNTIF(T302:T313,"Not Started") -> 0 | K19: =COUNTIFS(P302:P313,"<"&TODAY(),Q302:Q313,"") -> 0
A20: Week 16 | B20: 46128 | E20: =SUMIF(I319:I330,">=0",I319:I330) -> 0 | F20: =COUNT(I319:I330)*2 -> 0 | G20: =IF(F20=0,"",E20/F20) | H20: =IF(G20="","Not Started",IF(G20>=0.9,"Green",IF(G20>=0.75,"Amber","Red"))) -> Not Started | I20: =COUNTIFS(H319:H330,"Critical",I319:I330,"<2")+COUNTIFS(H319:H330,"High",I319:I330,"<2") -> 0 | J20: =COUNTIF(T319:T330,"In Progress")+COUNTIF(T319:T330,"Not Started") -> 0 | K20: =COUNTIFS(P319:P330,"<"&TODAY(),Q319:Q330,"") -> 0
A21: Week 17 | B21: 46135 | E21: =SUMIF(I336:I347,">=0",I336:I347) -> 0 | F21: =COUNT(I336:I347)*2 -> 0 | G21: =IF(F21=0,"",E21/F21) | H21: =IF(G21="","Not Started",IF(G21>=0.9,"Green",IF(G21>=0.75,"Amber","Red"))) -> Not Started | I21: =COUNTIFS(H336:H347,"Critical",I336:I347,"<2")+COUNTIFS(H336:H347,"High",I336:I347,"<2") -> 0 | J21: =COUNTIF(T336:T347,"In Progress")+COUNTIF(T336:T347,"Not Started") -> 0 | K21: =COUNTIFS(P336:P347,"<"&TODAY(),Q336:Q347,"") -> 0
A22: Week 18 | B22: 46142 | E22: =SUMIF(I353:I364,">=0",I353:I364) -> 0 | F22: =COUNT(I353:I364)*2 -> 0 | G22: =IF(F22=0,"",E22/F22) | H22: =IF(G22="","Not Started",IF(G22>=0.9,"Green",IF(G22>=0.75,"Amber","Red"))) -> Not Started | I22: =COUNTIFS(H353:H364,"Critical",I353:I364,"<2")+COUNTIFS(H353:H364,"High",I353:I364,"<2") -> 0 | J22: =COUNTIF(T353:T364,"In Progress")+COUNTIF(T353:T364,"Not Started") -> 0 | K22: =COUNTIFS(P353:P364,"<"&TODAY(),Q353:Q364,"") -> 0
A23: Week 19 | B23: 46149 | E23: =SUMIF(I370:I381,">=0",I370:I381) -> 0 | F23: =COUNT(I370:I381)*2 -> 0 | G23: =IF(F23=0,"",E23/F23) | H23: =IF(G23="","Not Started",IF(G23>=0.9,"Green",IF(G23>=0.75,"Amber","Red"))) -> Not Started | I23: =COUNTIFS(H370:H381,"Critical",I370:I381,"<2")+COUNTIFS(H370:H381,"High",I370:I381,"<2") -> 0 | J23: =COUNTIF(T370:T381,"In Progress")+COUNTIF(T370:T381,"Not Started") -> 0 | K23: =COUNTIFS(P370:P381,"<"&TODAY(),Q370:Q381,"") -> 0
A24: Week 20 | B24: 46156 | E24: =SUMIF(I387:I398,">=0",I387:I398) -> 0 | F24: =COUNT(I387:I398)*2 -> 0 | G24: =IF(F24=0,"",E24/F24) | H24: =IF(G24="","Not Started",IF(G24>=0.9,"Green",IF(G24>=0.75,"Amber","Red"))) -> Not Started | I24: =COUNTIFS(H387:H398,"Critical",I387:I398,"<2")+COUNTIFS(H387:H398,"High",I387:I398,"<2") -> 0 | J24: =COUNTIF(T387:T398,"In Progress")+COUNTIF(T387:T398,"Not Started") -> 0 | K24: =COUNTIFS(P387:P398,"<"&TODAY(),Q387:Q398,"") -> 0
A25: Week 21 | B25: 46163 | E25: =SUMIF(I404:I415,">=0",I404:I415) -> 0 | F25: =COUNT(I404:I415)*2 -> 0 | G25: =IF(F25=0,"",E25/F25) | H25: =IF(G25="","Not Started",IF(G25>=0.9,"Green",IF(G25>=0.75,"Amber","Red"))) -> Not Started | I25: =COUNTIFS(H404:H415,"Critical",I404:I415,"<2")+COUNTIFS(H404:H415,"High",I404:I415,"<2") -> 0 | J25: =COUNTIF(T404:T415,"In Progress")+COUNTIF(T404:T415,"Not Started") -> 0 | K25: =COUNTIFS(P404:P415,"<"&TODAY(),Q404:Q415,"") -> 0
A26: Week 22 | B26: 46170 | E26: =SUMIF(I421:I432,">=0",I421:I432) -> 0 | F26: =COUNT(I421:I432)*2 -> 0 | G26: =IF(F26=0,"",E26/F26) | H26: =IF(G26="","Not Started",IF(G26>=0.9,"Green",IF(G26>=0.75,"Amber","Red"))) -> Not Started | I26: =COUNTIFS(H421:H432,"Critical",I421:I432,"<2")+COUNTIFS(H421:H432,"High",I421:I432,"<2") -> 0 | J26: =COUNTIF(T421:T432,"In Progress")+COUNTIF(T421:T432,"Not Started") -> 0 | K26: =COUNTIFS(P421:P432,"<"&TODAY(),Q421:Q432,"") -> 0
A27: Week 23 | B27: 46177 | E27: =SUMIF(I438:I449,">=0",I438:I449) -> 0 | F27: =COUNT(I438:I449)*2 -> 0 | G27: =IF(F27=0,"",E27/F27) | H27: =IF(G27="","Not Started",IF(G27>=0.9,"Green",IF(G27>=0.75,"Amber","Red"))) -> Not Started | I27: =COUNTIFS(H438:H449,"Critical",I438:I449,"<2")+COUNTIFS(H438:H449,"High",I438:I449,"<2") -> 0 | J27: =COUNTIF(T438:T449,"In Progress")+COUNTIF(T438:T449,"Not Started") -> 0 | K27: =COUNTIFS(P438:P449,"<"&TODAY(),Q438:Q449,"") -> 0
A28: Week 24 | B28: 46184 | E28: =SUMIF(I455:I466,">=0",I455:I466) -> 0 | F28: =COUNT(I455:I466)*2 -> 0 | G28: =IF(F28=0,"",E28/F28) | H28: =IF(G28="","Not Started",IF(G28>=0.9,"Green",IF(G28>=0.75,"Amber","Red"))) -> Not Started | I28: =COUNTIFS(H455:H466,"Critical",I455:I466,"<2")+COUNTIFS(H455:H466,"High",I455:I466,"<2") -> 0 | J28: =COUNTIF(T455:T466,"In Progress")+COUNTIF(T455:T466,"Not Started") -> 0 | K28: =COUNTIFS(P455:P466,"<"&TODAY(),Q455:Q466,"") -> 0
A29: Week 25 | B29: 46191 | E29: =SUMIF(I472:I483,">=0",I472:I483) -> 0 | F29: =COUNT(I472:I483)*2 -> 0 | G29: =IF(F29=0,"",E29/F29) | H29: =IF(G29="","Not Started",IF(G29>=0.9,"Green",IF(G29>=0.75,"Amber","Red"))) -> Not Started | I29: =COUNTIFS(H472:H483,"Critical",I472:I483,"<2")+COUNTIFS(H472:H483,"High",I472:I483,"<2") -> 0 | J29: =COUNTIF(T472:T483,"In Progress")+COUNTIF(T472:T483,"Not Started") -> 0 | K29: =COUNTIFS(P472:P483,"<"&TODAY(),Q472:Q483,"") -> 0
A30: Week 26 | B30: 46198 | E30: =SUMIF(I489:I500,">=0",I489:I500) -> 0 | F30: =COUNT(I489:I500)*2 -> 0 | G30: =IF(F30=0,"",E30/F30) | H30: =IF(G30="","Not Started",IF(G30>=0.9,"Green",IF(G30>=0.75,"Amber","Red"))) -> Not Started | I30: =COUNTIFS(H489:H500,"Critical",I489:I500,"<2")+COUNTIFS(H489:H500,"High",I489:I500,"<2") -> 0 | J30: =COUNTIF(T489:T500,"In Progress")+COUNTIF(T489:T500,"Not Started") -> 0 | K30: =COUNTIFS(P489:P500,"<"&TODAY(),Q489:Q500,"") -> 0
A31: Week 27 | B31: 46205 | E31: =SUMIF(I506:I517,">=0",I506:I517) -> 0 | F31: =COUNT(I506:I517)*2 -> 0 | G31: =IF(F31=0,"",E31/F31) | H31: =IF(G31="","Not Started",IF(G31>=0.9,"Green",IF(G31>=0.75,"Amber","Red"))) -> Not Started | I31: =COUNTIFS(H506:H517,"Critical",I506:I517,"<2")+COUNTIFS(H506:H517,"High",I506:I517,"<2") -> 0 | J31: =COUNTIF(T506:T517,"In Progress")+COUNTIF(T506:T517,"Not Started") -> 0 | K31: =COUNTIFS(P506:P517,"<"&TODAY(),Q506:Q517,"") -> 0
A32: Week 28 | B32: 46212 | E32: =SUMIF(I523:I534,">=0",I523:I534) -> 0 | F32: =COUNT(I523:I534)*2 -> 0 | G32: =IF(F32=0,"",E32/F32) | H32: =IF(G32="","Not Started",IF(G32>=0.9,"Green",IF(G32>=0.75,"Amber","Red"))) -> Not Started | I32: =COUNTIFS(H523:H534,"Critical",I523:I534,"<2")+COUNTIFS(H523:H534,"High",I523:I534,"<2") -> 0 | J32: =COUNTIF(T523:T534,"In Progress")+COUNTIF(T523:T534,"Not Started") -> 0 | K32: =COUNTIFS(P523:P534,"<"&TODAY(),Q523:Q534,"") -> 0
A33: Week 29 | B33: 46219 | E33: =SUMIF(I540:I551,">=0",I540:I551) -> 0 | F33: =COUNT(I540:I551)*2 -> 0 | G33: =IF(F33=0,"",E33/F33) | H33: =IF(G33="","Not Started",IF(G33>=0.9,"Green",IF(G33>=0.75,"Amber","Red"))) -> Not Started | I33: =COUNTIFS(H540:H551,"Critical",I540:I551,"<2")+COUNTIFS(H540:H551,"High",I540:I551,"<2") -> 0 | J33: =COUNTIF(T540:T551,"In Progress")+COUNTIF(T540:T551,"Not Started") -> 0 | K33: =COUNTIFS(P540:P551,"<"&TODAY(),Q540:Q551,"") -> 0
A34: Week 30 | B34: 46226 | E34: =SUMIF(I557:I568,">=0",I557:I568) -> 0 | F34: =COUNT(I557:I568)*2 -> 0 | G34: =IF(F34=0,"",E34/F34) | H34: =IF(G34="","Not Started",IF(G34>=0.9,"Green",IF(G34>=0.75,"Amber","Red"))) -> Not Started | I34: =COUNTIFS(H557:H568,"Critical",I557:I568,"<2")+COUNTIFS(H557:H568,"High",I557:I568,"<2") -> 0 | J34: =COUNTIF(T557:T568,"In Progress")+COUNTIF(T557:T568,"Not Started") -> 0 | K34: =COUNTIFS(P557:P568,"<"&TODAY(),Q557:Q568,"") -> 0
A35: Week 31 | B35: 46233 | E35: =SUMIF(I574:I585,">=0",I574:I585) -> 0 | F35: =COUNT(I574:I585)*2 -> 0 | G35: =IF(F35=0,"",E35/F35) | H35: =IF(G35="","Not Started",IF(G35>=0.9,"Green",IF(G35>=0.75,"Amber","Red"))) -> Not Started | I35: =COUNTIFS(H574:H585,"Critical",I574:I585,"<2")+COUNTIFS(H574:H585,"High",I574:I585,"<2") -> 0 | J35: =COUNTIF(T574:T585,"In Progress")+COUNTIF(T574:T585,"Not Started") -> 0 | K35: =COUNTIFS(P574:P585,"<"&TODAY(),Q574:Q585,"") -> 0
A36: Week 32 | B36: 46240 | E36: =SUMIF(I591:I602,">=0",I591:I602) -> 0 | F36: =COUNT(I591:I602)*2 -> 0 | G36: =IF(F36=0,"",E36/F36) | H36: =IF(G36="","Not Started",IF(G36>=0.9,"Green",IF(G36>=0.75,"Amber","Red"))) -> Not Started | I36: =COUNTIFS(H591:H602,"Critical",I591:I602,"<2")+COUNTIFS(H591:H602,"High",I591:I602,"<2") -> 0 | J36: =COUNTIF(T591:T602,"In Progress")+COUNTIF(T591:T602,"Not Started") -> 0 | K36: =COUNTIFS(P591:P602,"<"&TODAY(),Q591:Q602,"") -> 0
A37: Week 33 | B37: 46247 | E37: =SUMIF(I608:I619,">=0",I608:I619) -> 0 | F37: =COUNT(I608:I619)*2 -> 0 | G37: =IF(F37=0,"",E37/F37) | H37: =IF(G37="","Not Started",IF(G37>=0.9,"Green",IF(G37>=0.75,"Amber","Red"))) -> Not Started | I37: =COUNTIFS(H608:H619,"Critical",I608:I619,"<2")+COUNTIFS(H608:H619,"High",I608:I619,"<2") -> 0 | J37: =COUNTIF(T608:T619,"In Progress")+COUNTIF(T608:T619,"Not Started") -> 0 | K37: =COUNTIFS(P608:P619,"<"&TODAY(),Q608:Q619,"") -> 0
A38: Week 34 | B38: 46254 | E38: =SUMIF(I625:I636,">=0",I625:I636) -> 0 | F38: =COUNT(I625:I636)*2 -> 0 | G38: =IF(F38=0,"",E38/F38) | H38: =IF(G38="","Not Started",IF(G38>=0.9,"Green",IF(G38>=0.75,"Amber","Red"))) -> Not Started | I38: =COUNTIFS(H625:H636,"Critical",I625:I636,"<2")+COUNTIFS(H625:H636,"High",I625:I636,"<2") -> 0 | J38: =COUNTIF(T625:T636,"In Progress")+COUNTIF(T625:T636,"Not Started") -> 0 | K38: =COUNTIFS(P625:P636,"<"&TODAY(),Q625:Q636,"") -> 0
A39: Week 35 | B39: 46261 | E39: =SUMIF(I642:I653,">=0",I642:I653) -> 0 | F39: =COUNT(I642:I653)*2 -> 0 | G39: =IF(F39=0,"",E39/F39) | H39: =IF(G39="","Not Started",IF(G39>=0.9,"Green",IF(G39>=0.75,"Amber","Red"))) -> Not Started | I39: =COUNTIFS(H642:H653,"Critical",I642:I653,"<2")+COUNTIFS(H642:H653,"High",I642:I653,"<2") -> 0 | J39: =COUNTIF(T642:T653,"In Progress")+COUNTIF(T642:T653,"Not Started") -> 0 | K39: =COUNTIFS(P642:P653,"<"&TODAY(),Q642:Q653,"") -> 0
A40: Week 36 | B40: 46268 | E40: =SUMIF(I659:I670,">=0",I659:I670) -> 0 | F40: =COUNT(I659:I670)*2 -> 0 | G40: =IF(F40=0,"",E40/F40) | H40: =IF(G40="","Not Started",IF(G40>=0.9,"Green",IF(G40>=0.75,"Amber","Red"))) -> Not Started | I40: =COUNTIFS(H659:H670,"Critical",I659:I670,"<2")+COUNTIFS(H659:H670,"High",I659:I670,"<2") -> 0 | J40: =COUNTIF(T659:T670,"In Progress")+COUNTIF(T659:T670,"Not Started") -> 0 | K40: =COUNTIFS(P659:P670,"<"&TODAY(),Q659:Q670,"") -> 0
A41: Week 37 | B41: 46275 | E41: =SUMIF(I676:I687,">=0",I676:I687) -> 0 | F41: =COUNT(I676:I687)*2 -> 0 | G41: =IF(F41=0,"",E41/F41) | H41: =IF(G41="","Not Started",IF(G41>=0.9,"Green",IF(G41>=0.75,"Amber","Red"))) -> Not Started | I41: =COUNTIFS(H676:H687,"Critical",I676:I687,"<2")+COUNTIFS(H676:H687,"High",I676:I687,"<2") -> 0 | J41: =COUNTIF(T676:T687,"In Progress")+COUNTIF(T676:T687,"Not Started") -> 0 | K41: =COUNTIFS(P676:P687,"<"&TODAY(),Q676:Q687,"") -> 0
...

Sheet Infection Surveillance
A1: Infection Surveillance Audit – Annual Evidence (Weekly)
A2: Instruction: | B2: Complete each period on this tab so the full year is held in one evidence location. Pale yellow cells are editable. Formula/RAG/header cells are locked only, with no password.
A4: Period | B4: Due Date | C4: Audit Date | D4: Auditor | E4: Total Score | F4: Max Score | G4: Compliance % | H4: RAG | I4: Critical/High Risks | J4: Open Actions | K4: Overdue Actions | L4: Manager Sign-Off | M4: Provider Sign-Off | N4: Evidence Folder Ref | O4: Summary / Key Findings
A5: Week 1 | B5: 46023 | E5: =SUMIF(I64:I75,">=0",I64:I75) -> 0 | F5: =COUNT(I64:I75)*2 -> 0 | G5: =IF(F5=0,"",E5/F5) | H5: =IF(G5="","Not Started",IF(G5>=0.9,"Green",IF(G5>=0.75,"Amber","Red"))) -> Not Started | I5: =COUNTIFS(H64:H75,"Critical",I64:I75,"<2")+COUNTIFS(H64:H75,"High",I64:I75,"<2") -> 0 | J5: =COUNTIF(T64:T75,"In Progress")+COUNTIF(T64:T75,"Not Started") -> 0 | K5: =COUNTIFS(P64:P75,"<"&TODAY(),Q64:Q75,"") -> 0
A6: Week 2 | B6: 46030 | E6: =SUMIF(I81:I92,">=0",I81:I92) -> 0 | F6: =COUNT(I81:I92)*2 -> 0 | G6: =IF(F6=0,"",E6/F6) | H6: =IF(G6="","Not Started",IF(G6>=0.9,"Green",IF(G6>=0.75,"Amber","Red"))) -> Not Started | I6: =COUNTIFS(H81:H92,"Critical",I81:I92,"<2")+COUNTIFS(H81:H92,"High",I81:I92,"<2") -> 0 | J6: =COUNTIF(T81:T92,"In Progress")+COUNTIF(T81:T92,"Not Started") -> 0 | K6: =COUNTIFS(P81:P92,"<"&TODAY(),Q81:Q92,"") -> 0
A7: Week 3 | B7: 46037 | E7: =SUMIF(I98:I109,">=0",I98:I109) -> 0 | F7: =COUNT(I98:I109)*2 -> 0 | G7: =IF(F7=0,"",E7/F7) | H7: =IF(G7="","Not Started",IF(G7>=0.9,"Green",IF(G7>=0.75,"Amber","Red"))) -> Not Started | I7: =COUNTIFS(H98:H109,"Critical",I98:I109,"<2")+COUNTIFS(H98:H109,"High",I98:I109,"<2") -> 0 | J7: =COUNTIF(T98:T109,"In Progress")+COUNTIF(T98:T109,"Not Started") -> 0 | K7: =COUNTIFS(P98:P109,"<"&TODAY(),Q98:Q109,"") -> 0
A8: Week 4 | B8: 46044 | E8: =SUMIF(I115:I126,">=0",I115:I126) -> 0 | F8: =COUNT(I115:I126)*2 -> 0 | G8: =IF(F8=0,"",E8/F8) | H8: =IF(G8="","Not Started",IF(G8>=0.9,"Green",IF(G8>=0.75,"Amber","Red"))) -> Not Started | I8: =COUNTIFS(H115:H126,"Critical",I115:I126,"<2")+COUNTIFS(H115:H126,"High",I115:I126,"<2") -> 0 | J8: =COUNTIF(T115:T126,"In Progress")+COUNTIF(T115:T126,"Not Started") -> 0 | K8: =COUNTIFS(P115:P126,"<"&TODAY(),Q115:Q126,"") -> 0
A9: Week 5 | B9: 46051 | E9: =SUMIF(I132:I143,">=0",I132:I143) -> 0 | F9: =COUNT(I132:I143)*2 -> 0 | G9: =IF(F9=0,"",E9/F9) | H9: =IF(G9="","Not Started",IF(G9>=0.9,"Green",IF(G9>=0.75,"Amber","Red"))) -> Not Started | I9: =COUNTIFS(H132:H143,"Critical",I132:I143,"<2")+COUNTIFS(H132:H143,"High",I132:I143,"<2") -> 0 | J9: =COUNTIF(T132:T143,"In Progress")+COUNTIF(T132:T143,"Not Started") -> 0 | K9: =COUNTIFS(P132:P143,"<"&TODAY(),Q132:Q143,"") -> 0
A10: Week 6 | B10: 46058 | E10: =SUMIF(I149:I160,">=0",I149:I160) -> 0 | F10: =COUNT(I149:I160)*2 -> 0 | G10: =IF(F10=0,"",E10/F10) | H10: =IF(G10="","Not Started",IF(G10>=0.9,"Green",IF(G10>=0.75,"Amber","Red"))) -> Not Started | I10: =COUNTIFS(H149:H160,"Critical",I149:I160,"<2")+COUNTIFS(H149:H160,"High",I149:I160,"<2") -> 0 | J10: =COUNTIF(T149:T160,"In Progress")+COUNTIF(T149:T160,"Not Started") -> 0 | K10: =COUNTIFS(P149:P160,"<"&TODAY(),Q149:Q160,"") -> 0
A11: Week 7 | B11: 46065 | E11: =SUMIF(I166:I177,">=0",I166:I177) -> 0 | F11: =COUNT(I166:I177)*2 -> 0 | G11: =IF(F11=0,"",E11/F11) | H11: =IF(G11="","Not Started",IF(G11>=0.9,"Green",IF(G11>=0.75,"Amber","Red"))) -> Not Started | I11: =COUNTIFS(H166:H177,"Critical",I166:I177,"<2")+COUNTIFS(H166:H177,"High",I166:I177,"<2") -> 0 | J11: =COUNTIF(T166:T177,"In Progress")+COUNTIF(T166:T177,"Not Started") -> 0 | K11: =COUNTIFS(P166:P177,"<"&TODAY(),Q166:Q177,"") -> 0
A12: Week 8 | B12: 46072 | E12: =SUMIF(I183:I194,">=0",I183:I194) -> 0 | F12: =COUNT(I183:I194)*2 -> 0 | G12: =IF(F12=0,"",E12/F12) | H12: =IF(G12="","Not Started",IF(G12>=0.9,"Green",IF(G12>=0.75,"Amber","Red"))) -> Not Started | I12: =COUNTIFS(H183:H194,"Critical",I183:I194,"<2")+COUNTIFS(H183:H194,"High",I183:I194,"<2") -> 0 | J12: =COUNTIF(T183:T194,"In Progress")+COUNTIF(T183:T194,"Not Started") -> 0 | K12: =COUNTIFS(P183:P194,"<"&TODAY(),Q183:Q194,"") -> 0
A13: Week 9 | B13: 46079 | E13: =SUMIF(I200:I211,">=0",I200:I211) -> 0 | F13: =COUNT(I200:I211)*2 -> 0 | G13: =IF(F13=0,"",E13/F13) | H13: =IF(G13="","Not Started",IF(G13>=0.9,"Green",IF(G13>=0.75,"Amber","Red"))) -> Not Started | I13: =COUNTIFS(H200:H211,"Critical",I200:I211,"<2")+COUNTIFS(H200:H211,"High",I200:I211,"<2") -> 0 | J13: =COUNTIF(T200:T211,"In Progress")+COUNTIF(T200:T211,"Not Started") -> 0 | K13: =COUNTIFS(P200:P211,"<"&TODAY(),Q200:Q211,"") -> 0
A14: Week 10 | B14: 46086 | E14: =SUMIF(I217:I228,">=0",I217:I228) -> 0 | F14: =COUNT(I217:I228)*2 -> 0 | G14: =IF(F14=0,"",E14/F14) | H14: =IF(G14="","Not Started",IF(G14>=0.9,"Green",IF(G14>=0.75,"Amber","Red"))) -> Not Started | I14: =COUNTIFS(H217:H228,"Critical",I217:I228,"<2")+COUNTIFS(H217:H228,"High",I217:I228,"<2") -> 0 | J14: =COUNTIF(T217:T228,"In Progress")+COUNTIF(T217:T228,"Not Started") -> 0 | K14: =COUNTIFS(P217:P228,"<"&TODAY(),Q217:Q228,"") -> 0
A15: Week 11 | B15: 46093 | E15: =SUMIF(I234:I245,">=0",I234:I245) -> 0 | F15: =COUNT(I234:I245)*2 -> 0 | G15: =IF(F15=0,"",E15/F15) | H15: =IF(G15="","Not Started",IF(G15>=0.9,"Green",IF(G15>=0.75,"Amber","Red"))) -> Not Started | I15: =COUNTIFS(H234:H245,"Critical",I234:I245,"<2")+COUNTIFS(H234:H245,"High",I234:I245,"<2") -> 0 | J15: =COUNTIF(T234:T245,"In Progress")+COUNTIF(T234:T245,"Not Started") -> 0 | K15: =COUNTIFS(P234:P245,"<"&TODAY(),Q234:Q245,"") -> 0
A16: Week 12 | B16: 46100 | E16: =SUMIF(I251:I262,">=0",I251:I262) -> 0 | F16: =COUNT(I251:I262)*2 -> 0 | G16: =IF(F16=0,"",E16/F16) | H16: =IF(G16="","Not Started",IF(G16>=0.9,"Green",IF(G16>=0.75,"Amber","Red"))) -> Not Started | I16: =COUNTIFS(H251:H262,"Critical",I251:I262,"<2")+COUNTIFS(H251:H262,"High",I251:I262,"<2") -> 0 | J16: =COUNTIF(T251:T262,"In Progress")+COUNTIF(T251:T262,"Not Started") -> 0 | K16: =COUNTIFS(P251:P262,"<"&TODAY(),Q251:Q262,"") -> 0
A17: Week 13 | B17: 46107 | E17: =SUMIF(I268:I279,">=0",I268:I279) -> 0 | F17: =COUNT(I268:I279)*2 -> 0 | G17: =IF(F17=0,"",E17/F17) | H17: =IF(G17="","Not Started",IF(G17>=0.9,"Green",IF(G17>=0.75,"Amber","Red"))) -> Not Started | I17: =COUNTIFS(H268:H279,"Critical",I268:I279,"<2")+COUNTIFS(H268:H279,"High",I268:I279,"<2") -> 0 | J17: =COUNTIF(T268:T279,"In Progress")+COUNTIF(T268:T279,"Not Started") -> 0 | K17: =COUNTIFS(P268:P279,"<"&TODAY(),Q268:Q279,"") -> 0
A18: Week 14 | B18: 46114 | E18: =SUMIF(I285:I296,">=0",I285:I296) -> 0 | F18: =COUNT(I285:I296)*2 -> 0 | G18: =IF(F18=0,"",E18/F18) | H18: =IF(G18="","Not Started",IF(G18>=0.9,"Green",IF(G18>=0.75,"Amber","Red"))) -> Not Started | I18: =COUNTIFS(H285:H296,"Critical",I285:I296,"<2")+COUNTIFS(H285:H296,"High",I285:I296,"<2") -> 0 | J18: =COUNTIF(T285:T296,"In Progress")+COUNTIF(T285:T296,"Not Started") -> 0 | K18: =COUNTIFS(P285:P296,"<"&TODAY(),Q285:Q296,"") -> 0
A19: Week 15 | B19: 46121 | E19: =SUMIF(I302:I313,">=0",I302:I313) -> 0 | F19: =COUNT(I302:I313)*2 -> 0 | G19: =IF(F19=0,"",E19/F19) | H19: =IF(G19="","Not Started",IF(G19>=0.9,"Green",IF(G19>=0.75,"Amber","Red"))) -> Not Started | I19: =COUNTIFS(H302:H313,"Critical",I302:I313,"<2")+COUNTIFS(H302:H313,"High",I302:I313,"<2") -> 0 | J19: =COUNTIF(T302:T313,"In Progress")+COUNTIF(T302:T313,"Not Started") -> 0 | K19: =COUNTIFS(P302:P313,"<"&TODAY(),Q302:Q313,"") -> 0
A20: Week 16 | B20: 46128 | E20: =SUMIF(I319:I330,">=0",I319:I330) -> 0 | F20: =COUNT(I319:I330)*2 -> 0 | G20: =IF(F20=0,"",E20/F20) | H20: =IF(G20="","Not Started",IF(G20>=0.9,"Green",IF(G20>=0.75,"Amber","Red"))) -> Not Started | I20: =COUNTIFS(H319:H330,"Critical",I319:I330,"<2")+COUNTIFS(H319:H330,"High",I319:I330,"<2") -> 0 | J20: =COUNTIF(T319:T330,"In Progress")+COUNTIF(T319:T330,"Not Started") -> 0 | K20: =COUNTIFS(P319:P330,"<"&TODAY(),Q319:Q330,"") -> 0
A21: Week 17 | B21: 46135 | E21: =SUMIF(I336:I347,">=0",I336:I347) -> 0 | F21: =COUNT(I336:I347)*2 -> 0 | G21: =IF(F21=0,"",E21/F21) | H21: =IF(G21="","Not Started",IF(G21>=0.9,"Green",IF(G21>=0.75,"Amber","Red"))) -> Not Started | I21: =COUNTIFS(H336:H347,"Critical",I336:I347,"<2")+COUNTIFS(H336:H347,"High",I336:I347,"<2") -> 0 | J21: =COUNTIF(T336:T347,"In Progress")+COUNTIF(T336:T347,"Not Started") -> 0 | K21: =COUNTIFS(P336:P347,"<"&TODAY(),Q336:Q347,"") -> 0
