Workbook

Sheet Lists
A1: Dependency Level | B1: Yes/No/NA | C1: Floor | D1: Evacuation Equipment | E1: Audit Status | F1: Change Trigger
A2: Low | B2: Yes | C2: Ground | D2: Walks independently | E2: Complete | F2: Fall
A3: Medium | B3: No | C3: First | D3: Walking aid | E3: Incomplete | F3: Hospital admission/return
A4: High | B4: N/A | C4: N/A | D4: Wheelchair | E4: Overdue | F4: Pressure damage
A5: Very High | D5: Ski sheet / evacuation sheet | F5: Mobility change
D6: Evacuation chair | F6: Room move
D7: Hoist then evacuation equipment | F7: Medication change
D8: Bariatric equipment required | F8: Behaviour change
D9: Oxygen evacuation consideration | F9: End of life
D10: Other specialist equipment | F10: New equipment

Sheet Dashboard
A1: Swan Care Home - Monthly Dependency & Evacuation Dashboard
A2: Dependency tabs now include category definitions for Low, Medium, High and Very High. Complete monthly and whenever resident needs change.
A4: Month | B4: Dependency Complete | C4: Residents | D4: Low | E4: Medium | F4: High | G4: Very High | H4: Resident Changes | I4: PEEP Bag | J4: First Aid | K4: Emollients | L4: Dependency RAG | M4: Overall Status
A5: ="January" -> January | B5: =IF('January Dependency'!B7="Yes","Yes","No") -> No | C5: ='January Dependency'!B8 -> 0 | D5: ='January Dependency'!B9 -> 0 | E5: ='January Dependency'!B10 -> 0 | F5: ='January Dependency'!B11 -> 0 | G5: ='January Dependency'!B12 -> 0 | H5: ='January Dependency'!B13 -> 0 | I5: =IF('January PEEP Bag'!B7="Yes","Complete","Incomplete") -> Incomplete | J5: =IF('January First Aid'!B7="Yes","Complete","Incomplete") -> Incomplete | K5: =IF('January Emollients'!B7="Yes","Complete","Incomplete") -> Incomplete | L5: =IF(G5>0,"RED",IF(OR(F5>0,H5>0),"AMBER","GREEN")) -> GREEN | M5: =IF(OR(B5<>"Yes",I5<>"Complete",J5<>"Complete",K5<>"Complete",L5="RED"),"RED",IF(L5="AMBER","AMBER","GREEN")) -> RED
A6: ="February" -> February | B6: =IF('February Dependency'!B7="Yes","Yes","No") -> No | C6: ='February Dependency'!B8 -> 0 | D6: ='February Dependency'!B9 -> 0 | E6: ='February Dependency'!B10 -> 0 | F6: ='February Dependency'!B11 -> 0 | G6: ='February Dependency'!B12 -> 0 | H6: ='February Dependency'!B13 -> 0 | I6: =IF('February PEEP Bag'!B7="Yes","Complete","Incomplete") -> Incomplete | J6: =IF('February First Aid'!B7="Yes","Complete","Incomplete") -> Incomplete | K6: =IF('February Emollients'!B7="Yes","Complete","Incomplete") -> Incomplete | L6: =IF(G6>0,"RED",IF(OR(F6>0,H6>0),"AMBER","GREEN")) -> GREEN | M6: =IF(OR(B6<>"Yes",I6<>"Complete",J6<>"Complete",K6<>"Complete",L6="RED"),"RED",IF(L6="AMBER","AMBER","GREEN")) -> RED
A7: ="March" -> March | B7: =IF('March Dependency'!B7="Yes","Yes","No") -> No | C7: ='March Dependency'!B8 -> 0 | D7: ='March Dependency'!B9 -> 0 | E7: ='March Dependency'!B10 -> 0 | F7: ='March Dependency'!B11 -> 0 | G7: ='March Dependency'!B12 -> 0 | H7: ='March Dependency'!B13 -> 0 | I7: =IF('March PEEP Bag'!B7="Yes","Complete","Incomplete") -> Incomplete | J7: =IF('March First Aid'!B7="Yes","Complete","Incomplete") -> Incomplete | K7: =IF('March Emollients'!B7="Yes","Complete","Incomplete") -> Incomplete | L7: =IF(G7>0,"RED",IF(OR(F7>0,H7>0),"AMBER","GREEN")) -> GREEN | M7: =IF(OR(B7<>"Yes",I7<>"Complete",J7<>"Complete",K7<>"Complete",L7="RED"),"RED",IF(L7="AMBER","AMBER","GREEN")) -> RED
A8: ="April" -> April | B8: =IF('April Dependency'!B7="Yes","Yes","No") -> No | C8: ='April Dependency'!B8 -> 0 | D8: ='April Dependency'!B9 -> 0 | E8: ='April Dependency'!B10 -> 0 | F8: ='April Dependency'!B11 -> 0 | G8: ='April Dependency'!B12 -> 0 | H8: ='April Dependency'!B13 -> 0 | I8: =IF('April PEEP Bag'!B7="Yes","Complete","Incomplete") -> Incomplete | J8: =IF('April First Aid'!B7="Yes","Complete","Incomplete") -> Incomplete | K8: =IF('April Emollients'!B7="Yes","Complete","Incomplete") -> Incomplete | L8: =IF(G8>0,"RED",IF(OR(F8>0,H8>0),"AMBER","GREEN")) -> GREEN | M8: =IF(OR(B8<>"Yes",I8<>"Complete",J8<>"Complete",K8<>"Complete",L8="RED"),"RED",IF(L8="AMBER","AMBER","GREEN")) -> RED
A9: ="May" -> May | B9: =IF('May Dependency'!B7="Yes","Yes","No") -> No | C9: ='May Dependency'!B8 -> 0 | D9: ='May Dependency'!B9 -> 0 | E9: ='May Dependency'!B10 -> 0 | F9: ='May Dependency'!B11 -> 0 | G9: ='May Dependency'!B12 -> 0 | H9: ='May Dependency'!B13 -> 0 | I9: =IF('May PEEP Bag'!B7="Yes","Complete","Incomplete") -> Incomplete | J9: =IF('May First Aid'!B7="Yes","Complete","Incomplete") -> Incomplete | K9: =IF('May Emollients'!B7="Yes","Complete","Incomplete") -> Incomplete | L9: =IF(G9>0,"RED",IF(OR(F9>0,H9>0),"AMBER","GREEN")) -> GREEN | M9: =IF(OR(B9<>"Yes",I9<>"Complete",J9<>"Complete",K9<>"Complete",L9="RED"),"RED",IF(L9="AMBER","AMBER","GREEN")) -> RED
A10: ="June" -> June | B10: =IF('June Dependency'!B7="Yes","Yes","No") -> No | C10: ='June Dependency'!B8 -> 0 | D10: ='June Dependency'!B9 -> 0 | E10: ='June Dependency'!B10 -> 0 | F10: ='June Dependency'!B11 -> 0 | G10: ='June Dependency'!B12 -> 0 | H10: ='June Dependency'!B13 -> 0 | I10: =IF('June PEEP Bag'!B7="Yes","Complete","Incomplete") -> Incomplete | J10: =IF('June First Aid'!B7="Yes","Complete","Incomplete") -> Incomplete | K10: =IF('June Emollients'!B7="Yes","Complete","Incomplete") -> Incomplete | L10: =IF(G10>0,"RED",IF(OR(F10>0,H10>0),"AMBER","GREEN")) -> GREEN | M10: =IF(OR(B10<>"Yes",I10<>"Complete",J10<>"Complete",K10<>"Complete",L10="RED"),"RED",IF(L10="AMBER","AMBER","GREEN")) -> RED
A11: ="July" -> July | B11: =IF('July Dependency'!B7="Yes","Yes","No") -> No | C11: ='July Dependency'!B8 -> 0 | D11: ='July Dependency'!B9 -> 0 | E11: ='July Dependency'!B10 -> 0 | F11: ='July Dependency'!B11 -> 0 | G11: ='July Dependency'!B12 -> 0 | H11: ='July Dependency'!B13 -> 0 | I11: =IF('July PEEP Bag'!B7="Yes","Complete","Incomplete") -> Incomplete | J11: =IF('July First Aid'!B7="Yes","Complete","Incomplete") -> Incomplete | K11: =IF('July Emollients'!B7="Yes","Complete","Incomplete") -> Incomplete | L11: =IF(G11>0,"RED",IF(OR(F11>0,H11>0),"AMBER","GREEN")) -> GREEN | M11: =IF(OR(B11<>"Yes",I11<>"Complete",J11<>"Complete",K11<>"Complete",L11="RED"),"RED",IF(L11="AMBER","AMBER","GREEN")) -> RED
A12: ="August" -> August | B12: =IF('August Dependency'!B7="Yes","Yes","No") -> No | C12: ='August Dependency'!B8 -> 0 | D12: ='August Dependency'!B9 -> 0 | E12: ='August Dependency'!B10 -> 0 | F12: ='August Dependency'!B11 -> 0 | G12: ='August Dependency'!B12 -> 0 | H12: ='August Dependency'!B13 -> 0 | I12: =IF('August PEEP Bag'!B7="Yes","Complete","Incomplete") -> Incomplete | J12: =IF('August First Aid'!B7="Yes","Complete","Incomplete") -> Incomplete | K12: =IF('August Emollients'!B7="Yes","Complete","Incomplete") -> Incomplete | L12: =IF(G12>0,"RED",IF(OR(F12>0,H12>0),"AMBER","GREEN")) -> GREEN | M12: =IF(OR(B12<>"Yes",I12<>"Complete",J12<>"Complete",K12<>"Complete",L12="RED"),"RED",IF(L12="AMBER","AMBER","GREEN")) -> RED
A13: ="September" -> September | B13: =IF('September Dependency'!B7="Yes","Yes","No") -> No | C13: ='September Dependency'!B8 -> 0 | D13: ='September Dependency'!B9 -> 0 | E13: ='September Dependency'!B10 -> 0 | F13: ='September Dependency'!B11 -> 0 | G13: ='September Dependency'!B12 -> 0 | H13: ='September Dependency'!B13 -> 0 | I13: =IF('September PEEP Bag'!B7="Yes","Complete","Incomplete") -> Incomplete | J13: =IF('September First Aid'!B7="Yes","Complete","Incomplete") -> Incomplete | K13: =IF('September Emollients'!B7="Yes","Complete","Incomplete") -> Incomplete | L13: =IF(G13>0,"RED",IF(OR(F13>0,H13>0),"AMBER","GREEN")) -> GREEN | M13: =IF(OR(B13<>"Yes",I13<>"Complete",J13<>"Complete",K13<>"Complete",L13="RED"),"RED",IF(L13="AMBER","AMBER","GREEN")) -> RED
A14: ="October" -> October | B14: =IF('October Dependency'!B7="Yes","Yes","No") -> No | C14: ='October Dependency'!B8 -> 0 | D14: ='October Dependency'!B9 -> 0 | E14: ='October Dependency'!B10 -> 0 | F14: ='October Dependency'!B11 -> 0 | G14: ='October Dependency'!B12 -> 0 | H14: ='October Dependency'!B13 -> 0 | I14: =IF('October PEEP Bag'!B7="Yes","Complete","Incomplete") -> Incomplete | J14: =IF('October First Aid'!B7="Yes","Complete","Incomplete") -> Incomplete | K14: =IF('October Emollients'!B7="Yes","Complete","Incomplete") -> Incomplete | L14: =IF(G14>0,"RED",IF(OR(F14>0,H14>0),"AMBER","GREEN")) -> GREEN | M14: =IF(OR(B14<>"Yes",I14<>"Complete",J14<>"Complete",K14<>"Complete",L14="RED"),"RED",IF(L14="AMBER","AMBER","GREEN")) -> RED
A15: ="November" -> November | B15: =IF('November Dependency'!B7="Yes","Yes","No") -> No | C15: ='November Dependency'!B8 -> 0 | D15: ='November Dependency'!B9 -> 0 | E15: ='November Dependency'!B10 -> 0 | F15: ='November Dependency'!B11 -> 0 | G15: ='November Dependency'!B12 -> 0 | H15: ='November Dependency'!B13 -> 0 | I15: =IF('November PEEP Bag'!B7="Yes","Complete","Incomplete") -> Incomplete | J15: =IF('November First Aid'!B7="Yes","Complete","Incomplete") -> Incomplete | K15: =IF('November Emollients'!B7="Yes","Complete","Incomplete") -> Incomplete | L15: =IF(G15>0,"RED",IF(OR(F15>0,H15>0),"AMBER","GREEN")) -> GREEN | M15: =IF(OR(B15<>"Yes",I15<>"Complete",J15<>"Complete",K15<>"Complete",L15="RED"),"RED",IF(L15="AMBER","AMBER","GREEN")) -> RED
A16: ="December" -> December | B16: =IF('December Dependency'!B7="Yes","Yes","No") -> No | C16: ='December Dependency'!B8 -> 0 | D16: ='December Dependency'!B9 -> 0 | E16: ='December Dependency'!B10 -> 0 | F16: ='December Dependency'!B11 -> 0 | G16: ='December Dependency'!B12 -> 0 | H16: ='December Dependency'!B13 -> 0 | I16: =IF('December PEEP Bag'!B7="Yes","Complete","Incomplete") -> Incomplete | J16: =IF('December First Aid'!B7="Yes","Complete","Incomplete") -> Incomplete | K16: =IF('December Emollients'!B7="Yes","Complete","Incomplete") -> Incomplete | L16: =IF(G16>0,"RED",IF(OR(F16>0,H16>0),"AMBER","GREEN")) -> GREEN | M16: =IF(OR(B16<>"Yes",I16<>"Complete",J16<>"Complete",K16<>"Complete",L16="RED"),"RED",IF(L16="AMBER","AMBER","GREEN")) -> RED
A18: Annual Totals | C18: =SUM(C5:C16) -> 0 | D18: =SUM(D5:D16) -> 0 | E18: =SUM(E5:E16) -> 0 | F18: =SUM(F5:F16) -> 0 | G18: =SUM(G5:G16) -> 0 | H18: =SUM(H5:H16) -> 0
A20: Dependency Meaning | B20: Low | C20: Medium | D20: High | E20: Very High
A21: Summary | B21: Mostly independent / prompting only | C21: Regular support or supervision | D21: Two staff, hoist, wheelchair, dementia/falls risk | E21: Fully dependent, complex, bariatric, oxygen, EOL or specialist evacuation
A22: Staffing | B22: Usually one staff supervision only | C22: One staff support often required | D22: Two staff or frequent support likely | E22: Two or more staff / manager review required
A23: Fire Evacuation | B23: Walks out with direction | C23: Walks with aid or wheelchair with support | D23: Evacuation sheet/chair or two staff support likely | E23: Individual specialist PEEP and equipment required
A24: Dashboard RED | B24: Any incomplete monthly review/audit or any Very High resident
A25: Dashboard AMBER | B25: Any High resident or resident change requiring management review
A26: When to update | B26: Monthly and immediately after fall, hospital return, pressure damage, room move, mobility change, behaviour change, new equipment, EOL or PEEP change
A27: Evidence | B27: Keep completed monthly sheets. Do not overwrite previous months.

Sheet Floor Plan Zones
A1: Horizontal Evacuation Floor Plan Zones
A2: Use with each resident PEEP and dependency assessment.
A4: Floor | B4: Rooms/Area | C4: Zone | D4: Primary Evacuation Route | E4: Horizontal Holding/Next Safe Area | F4: Equipment Usually Required | G4: Notes
A5: Ground | B5: Rooms 1-7 / Sluice / Toilet 2 | C5: Ground Zone A | D5: Nearest safe fire exit / conservatory route / rear exit | E5: Next safe compartment or external assembly point | F5: Walking aid, wheelchair, evacuation sheet | G5: Confirm for each resident in PEEP
A6: Ground | B6: Rooms 8-9 / office / clinic / laundry | C6: Ground Zone B | D6: Nearest safe exit / front or side route | E6: Next safe compartment or external assembly point | F6: Wheelchair, evacuation sheet | G6: Confirm for each resident in PEEP
A7: Ground | B7: Lounge / Dining / Kitchen / Conservatory | C7: Ground Communal Zone | D7: Nearest safe exit | E7: External assembly point then Tillingham Church if needed | F7: Grab bag, wheelchairs, staff support | G7: Keep routes clear
A8: First | B8: Rooms 10-14 / bathroom | C8: First Zone C | D8: Main staircase route where safe | E8: Next safe compartment then ground floor | F8: Evacuation chair, ski sheet / evacuation sheet | G8: No lift during fire
A9: First | B9: Rooms 15-20 / sluice / toilet | C9: First Zone D | D9: Back staircase route where safe | E9: Next safe compartment then ground floor | F9: Evacuation chair, ski sheet / evacuation sheet | G9: No lift during fire

Sheet January Dependency
A1: January Dependency Tool - Category-Based Day/Night Assessment
A2: Select Low/Medium/High/Very High in each category. Overall dependency is calculated automatically. Guidance notes are included on this tab.
A4: Review Month | B4: January | D4: Overall Dependency Rule
A5: Review Date | D5: Low Dependency | E5: Resident is independent or requires minimal prompting with activities of daily living. Mobilises independently or with a walking stick/frame. Manages or requires minimal assistance with washing, dressing, toileting and continence. Eats and drinks independently. Medication needs are routine. Cognitively able to understand instructions. Low falls risk. Can evacuate independently with verbal guidance.
A6: Reviewed By | D6: Medium Dependency | E6: Resident requires regular assistance or supervision with one or more activities of daily living. May need assistance with washing, dressing, toileting, continence care or transfers. May require prompting or partial assistance with eating and drinking. Requires staff to administer medication. May have mild to moderate cognitive impairment, dementia or anxiety requiring reassurance. Moderate falls risk. Would require one member of staff during evacuation using a walking aid or wheelchair where appropriate.
A7: Assessment Complete? | D7: High Dependency | E7: Resident requires significant assistance with most aspects of personal care, including washing, dressing, toileting and continence management. May require assistance with eating and drinking or have modified diets. Requires two staff for transfers, personal care or repositioning and may use a hoist, stand aid or wheelchair. High falls risk and/or behaviours associated with dementia that affect safety. Requires regular clinical monitoring, pressure area care or complex medication. Would require two staff and specialist evacuation equipment (e.g. evacuation sheet, wheelchair or evacuation chair) in accordance with their PEEP.
A8: Total Residents | B8: =COUNTA(A18:A117) -> 0 | D8: Very High Dependency | E8: Resident is fully dependent on staff for all activities of daily living, including personal care, toileting, continence management, repositioning, eating and drinking. May receive PEG feeding, oxygen therapy, end-of-life care or have complex clinical conditions requiring continuous monitoring. May be bariatric, bedbound or have severe cognitive impairment or behaviours requiring constant supervision. Requires specialist equipment, multiple staff and an individual evacuation strategy. Cannot evacuate without full staff assistance and appropriate evacuation equipment in accordance with their PEEP.
A9: Low | B9: =COUNTIF(Z18:Z117,"Low") -> 0
A10: Medium | B10: =COUNTIF(Z18:Z117,"Medium") -> 0
A11: High | B11: =COUNTIF(Z18:Z117,"High") -> 0
A12: Very High | B12: =COUNTIF(Z18:Z117,"Very High") -> 0
A13: Residents Changed This Month | B13: =COUNTIF(AD18:AD117,"Yes") -> 0
A14: Manager Monthly Comment
A17: Resident Name | B17: Room | C17: Floor | D17: Zone | E17: PEEP Review Date | F17: Assessor | G17: Review Date | H17: Mobility | I17: Transfers | J17: Personal Care | K17: Washing & Dressing | L17: Continence | M17: Nutrition & Hydration | N17: Medication | O17: Skin Integrity | P17: Falls Risk | Q17: Behaviour | R17: Cognition | S17: Communication | T17: Clinical Needs | U17: Mental Health | V17: Sleep/Night Needs | W17: Fire Evacuation Needs | X17: End of Life Care | Y17: Infection Control | Z17: Overall Dependency | AA17: Day Staffing Note | AB17: Night Staffing Note | AC17: Evacuation Equipment | AD17: Change This Month? | AE17: Date of Change | AF17: What Happened / Impact | AG17: Actions Taken | AH17: Care Plan Updated? | AI17: Risk Assessment Updated? | AJ17: PEEP Updated? | AK17: Manager Initials
Z18: =IF(COUNTA(H18:Y18)=0,"",IF(COUNTIF(H18:Y18,"Very High")>0,"Very High",IF(COUNTIF(H18:Y18,"High")>0,"High",IF(COUNTIF(H18:Y18,"Medium")>0,"Medium","Low")))) | AA18: =IF(Z18="","",IF(Z18="Low","Routine planned support",IF(Z18="Medium","One staff support/supervision likely",IF(Z18="High","Two staff/review staffing and equipment","Manager review: multiple staff/specialist support")))) | AB18: =IF(Z18="","",IF(OR(Z18="High",Z18="Very High",W18="High",W18="Very High"),"Night staffing and evacuation review required","Routine night checks as per care plan")) | AC18: =IF(X18="Very High","Specialist PEEP / equipment",IF(OR(X18="High",Z18="High"),"Evacuation sheet/chair or wheelchair per PEEP",IF(OR(X18="Medium",Z18="Medium"),"Walking aid/wheelchair support per PEEP","Walks with direction"))) -> Walks with direction
Z19: =IF(COUNTA(H19:Y19)=0,"",IF(COUNTIF(H19:Y19,"Very High")>0,"Very High",IF(COUNTIF(H19:Y19,"High")>0,"High",IF(COUNTIF(H19:Y19,"Medium")>0,"Medium","Low")))) | AA19: =IF(Z19="","",IF(Z19="Low","Routine planned support",IF(Z19="Medium","One staff support/supervision likely",IF(Z19="High","Two staff/review staffing and equipment","Manager review: multiple staff/specialist support")))) | AB19: =IF(Z19="","",IF(OR(Z19="High",Z19="Very High",W19="High",W19="Very High"),"Night staffing and evacuation review required","Routine night checks as per care plan")) | AC19: =IF(X19="Very High","Specialist PEEP / equipment",IF(OR(X19="High",Z19="High"),"Evacuation sheet/chair or wheelchair per PEEP",IF(OR(X19="Medium",Z19="Medium"),"Walking aid/wheelchair support per PEEP","Walks with direction"))) -> Walks with direction
Z20: =IF(COUNTA(H20:Y20)=0,"",IF(COUNTIF(H20:Y20,"Very High")>0,"Very High",IF(COUNTIF(H20:Y20,"High")>0,"High",IF(COUNTIF(H20:Y20,"Medium")>0,"Medium","Low")))) | AA20: =IF(Z20="","",IF(Z20="Low","Routine planned support",IF(Z20="Medium","One staff support/supervision likely",IF(Z20="High","Two staff/review staffing and equipment","Manager review: multiple staff/specialist support")))) | AB20: =IF(Z20="","",IF(OR(Z20="High",Z20="Very High",W20="High",W20="Very High"),"Night staffing and evacuation review required","Routine night checks as per care plan")) | AC20: =IF(X20="Very High","Specialist PEEP / equipment",IF(OR(X20="High",Z20="High"),"Evacuation sheet/chair or wheelchair per PEEP",IF(OR(X20="Medium",Z20="Medium"),"Walking aid/wheelchair support per PEEP","Walks with direction"))) -> Walks with direction
Z21: =IF(COUNTA(H21:Y21)=0,"",IF(COUNTIF(H21:Y21,"Very High")>0,"Very High",IF(COUNTIF(H21:Y21,"High")>0,"High",IF(COUNTIF(H21:Y21,"Medium")>0,"Medium","Low")))) | AA21: =IF(Z21="","",IF(Z21="Low","Routine planned support",IF(Z21="Medium","One staff support/supervision likely",IF(Z21="High","Two staff/review staffing and equipment","Manager review: multiple staff/specialist support")))) | AB21: =IF(Z21="","",IF(OR(Z21="High",Z21="Very High",W21="High",W21="Very High"),"Night staffing and evacuation review required","Routine night checks as per care plan")) | AC21: =IF(X21="Very High","Specialist PEEP / equipment",IF(OR(X21="High",Z21="High"),"Evacuation sheet/chair or wheelchair per PEEP",IF(OR(X21="Medium",Z21="Medium"),"Walking aid/wheelchair support per PEEP","Walks with direction"))) -> Walks with direction
Z22: =IF(COUNTA(H22:Y22)=0,"",IF(COUNTIF(H22:Y22,"Very High")>0,"Very High",IF(COUNTIF(H22:Y22,"High")>0,"High",IF(COUNTIF(H22:Y22,"Medium")>0,"Medium","Low")))) | AA22: =IF(Z22="","",IF(Z22="Low","Routine planned support",IF(Z22="Medium","One staff support/supervision likely",IF(Z22="High","Two staff/review staffing and equipment","Manager review: multiple staff/specialist support")))) | AB22: =IF(Z22="","",IF(OR(Z22="High",Z22="Very High",W22="High",W22="Very High"),"Night staffing and evacuation review required","Routine night checks as per care plan")) | AC22: =IF(X22="Very High","Specialist PEEP / equipment",IF(OR(X22="High",Z22="High"),"Evacuation sheet/chair or wheelchair per PEEP",IF(OR(X22="Medium",Z22="Medium"),"Walking aid/wheelchair support per PEEP","Walks with direction"))) -> Walks with direction
Z23: =IF(COUNTA(H23:Y23)=0,"",IF(COUNTIF(H23:Y23,"Very High")>0,"Very High",IF(COUNTIF(H23:Y23,"High")>0,"High",IF(COUNTIF(H23:Y23,"Medium")>0,"Medium","Low")))) | AA23: =IF(Z23="","",IF(Z23="Low","Routine planned support",IF(Z23="Medium","One staff support/supervision likely",IF(Z23="High","Two staff/review staffing and equipment","Manager review: multiple staff/specialist support")))) | AB23: =IF(Z23="","",IF(OR(Z23="High",Z23="Very High",W23="High",W23="Very High"),"Night staffing and evacuation review required","Routine night checks as per care plan")) | AC23: =IF(X23="Very High","Specialist PEEP / equipment",IF(OR(X23="High",Z23="High"),"Evacuation sheet/chair or wheelchair per PEEP",IF(OR(X23="Medium",Z23="Medium"),"Walking aid/wheelchair support per PEEP","Walks with direction"))) -> Walks with direction
Z24: =IF(COUNTA(H24:Y24)=0,"",IF(COUNTIF(H24:Y24,"Very High")>0,"Very High",IF(COUNTIF(H24:Y24,"High")>0,"High",IF(COUNTIF(H24:Y24,"Medium")>0,"Medium","Low")))) | AA24: =IF(Z24="","",IF(Z24="Low","Routine planned support",IF(Z24="Medium","One staff support/supervision likely",IF(Z24="High","Two staff/review staffing and equipment","Manager review: multiple staff/specialist support")))) | AB24: =IF(Z24="","",IF(OR(Z24="High",Z24="Very High",W24="High",W24="Very High"),"Night staffing and evacuation review required","Routine night checks as per care plan")) | AC24: =IF(X24="Very High","Specialist PEEP / equipment",IF(OR(X24="High",Z24="High"),"Evacuation sheet/chair or wheelchair per PEEP",IF(OR(X24="Medium",Z24="Medium"),"Walking aid/wheelchair support per PEEP","Walks with direction"))) -> Walks with direction
Z25: =IF(COUNTA(H25:Y25)=0,"",IF(COUNTIF(H25:Y25,"Very High")>0,"Very High",IF(COUNTIF(H25:Y25,"High")>0,"High",IF(COUNTIF(H25:Y25,"Medium")>0,"Medium","Low")))) | AA25: =IF(Z25="","",IF(Z25="Low","Routine planned support",IF(Z25="Medium","One staff support/supervision likely",IF(Z25="High","Two staff/review staffing and equipment","Manager review: multiple staff/specialist support")))) | AB25: =IF(Z25="","",IF(OR(Z25="High",Z25="Very High",W25="High",W25="Very High"),"Night staffing and evacuation review required","Routine night checks as per care plan")) | AC25: =IF(X25="Very High","Specialist PEEP / equipment",IF(OR(X25="High",Z25="High"),"Evacuation sheet/chair or wheelchair per PEEP",IF(OR(X25="Medium",Z25="Medium"),"Walking aid/wheelchair support per PEEP","Walks with direction"))) -> Walks with direction
Z26: =IF(COUNTA(H26:Y26)=0,"",IF(COUNTIF(H26:Y26,"Very High")>0,"Very High",IF(COUNTIF(H26:Y26,"High")>0,"High",IF(COUNTIF(H26:Y26,"Medium")>0,"Medium","Low")))) | AA26: =IF(Z26="","",IF(Z26="Low","Routine planned support",IF(Z26="Medium","One staff support/supervision likely",IF(Z26="High","Two staff/review staffing and equipment","Manager review: multiple staff/specialist support")))) | AB26: =IF(Z26="","",IF(OR(Z26="High",Z26="Very High",W26="High",W26="Very High"),"Night staffing and evacuation review required","Routine night checks as per care plan")) | AC26: =IF(X26="Very High","Specialist PEEP / equipment",IF(OR(X26="High",Z26="High"),"Evacuation sheet/chair or wheelchair per PEEP",IF(OR(X26="Medium",Z26="Medium"),"Walking aid/wheelchair support per PEEP","Walks with direction"))) -> Walks with direction
Z27: =IF(COUNTA(H27:Y27)=0,"",IF(COUNTIF(H27:Y27,"Very High")>0,"Very High",IF(COUNTIF(H27:Y27,"High")>0,"High",IF(COUNTIF(H27:Y27,"Medium")>0,"Medium","Low")))) | AA27: =IF(Z27="","",IF(Z27="Low","Routine planned support",IF(Z27="Medium","One staff support/supervision likely",IF(Z27="High","Two staff/review staffing and equipment","Manager review: multiple staff/specialist support")))) | AB27: =IF(Z27="","",IF(OR(Z27="High",Z27="Very High",W27="High",W27="Very High"),"Night staffing and evacuation review required","Routine night checks as per care plan")) | AC27: =IF(X27="Very High","Specialist PEEP / equipment",IF(OR(X27="High",Z27="High"),"Evacuation sheet/chair or wheelchair per PEEP",IF(OR(X27="Medium",Z27="Medium"),"Walking aid/wheelchair support per PEEP","Walks with direction"))) -> Walks with direction
Z28: =IF(COUNTA(H28:Y28)=0,"",IF(COUNTIF(H28:Y28,"Very High")>0,"Very High",IF(COUNTIF(H28:Y28,"High")>0,"High",IF(COUNTIF(H28:Y28,"Medium")>0,"Medium","Low")))) | AA28: =IF(Z28="","",IF(Z28="Low","Routine planned support",IF(Z28="Medium","One staff support/supervision likely",IF(Z28="High","Two staff/review staffing and equipment","Manager review: multiple staff/specialist support")))) | AB28: =IF(Z28="","",IF(OR(Z28="High",Z28="Very High",W28="High",W28="Very High"),"Night staffing and evacuation review required","Routine night checks as per care plan")) | AC28: =IF(X28="Very High","Specialist PEEP / equipment",IF(OR(X28="High",Z28="High"),"Evacuation sheet/chair or wheelchair per PEEP",IF(OR(X28="Medium",Z28="Medium"),"Walking aid/wheelchair support per PEEP","Walks with direction"))) -> Walks with direction
Z29: =IF(COUNTA(H29:Y29)=0,"",IF(COUNTIF(H29:Y29,"Very High")>0,"Very High",IF(COUNTIF(H29:Y29,"High")>0,"High",IF(COUNTIF(H29:Y29,"Medium")>0,"Medium","Low")))) | AA29: =IF(Z29="","",IF(Z29="Low","Routine planned support",IF(Z29="Medium","One staff support/supervision likely",IF(Z29="High","Two staff/review staffing and equipment","Manager review: multiple staff/specialist support")))) | AB29: =IF(Z29="","",IF(OR(Z29="High",Z29="Very High",W29="High",W29="Very High"),"Night staffing and evacuation review required","Routine night checks as per care plan")) | AC29: =IF(X29="Very High","Specialist PEEP / equipment",IF(OR(X29="High",Z29="High"),"Evacuation sheet/chair or wheelchair per PEEP",IF(OR(X29="Medium",Z29="Medium"),"Walking aid/wheelchair support per PEEP","Walks with direction"))) -> Walks with direction
... Z117: =IF(COUNTA(H117:Y117)=0,"",IF(COUNTIF(H117:Y117,"Very High")>0,"Very High",IF(COUNTIF(H117:Y117,"High")>0,"High",IF(COUNTIF(H117:Y117,"Medium")>0,"Medium","Low")))) | AA117: =IF(Z117="","",IF(Z117="Low","Routine planned support",IF(Z117="Medium","One staff support/supervision likely",IF(Z117="High","Two staff/review staffing and equipment","Manager review: multiple staff/specialist support")))) | AB117: =IF(Z117="","",IF(OR(Z117="High",Z117="Very High",W117="High",W117="Very High"),"Night staffing and evacuation review required","Routine night checks as per care plan")) | AC117: =IF(X117="Very High","Specialist PEEP / equipment",IF(OR(X117="High",Z117="High"),"Evacuation sheet/chair or wheelchair per PEEP",IF(OR(X117="Medium",Z117="Medium"),"Walking aid/wheelchair support per PEEP","Walks with direction"))) -> Walks with direction
A122: Dependency Category Guidance - use these notes when selecting the resident rating
A123: Category | B123: Low | C123: Medium | D123: High | E123: Very High
A124: Mobility | B124: Walks independently; may need verbal direction only. | C124: Uses walking aid or requires supervision/reassurance. | D124: Wheelchair user or requires one/two staff physical assistance. | E124: Bedbound, unable to mobilise, bariatric mobility or fully dependent.
A125: Transfers | B125: Independent transfers safely. | C125: Supervision, prompt or one staff light support. | D125: Two staff, stand aid, rotunda or high falls risk during transfer. | E125: Hoist, complex transfer, bariatric or unsafe without specialist plan.
A126: Personal Care | B126: Independent or prompting only. | C126: Assistance with some washing, dressing or grooming. | D126: Full assistance from staff for most personal care. | E126: Total care, two staff or complex dignity/skin risks.
A127: Washing & Dressing | B127: Chooses clothes and completes tasks with little/no help. | C127: Prompting, setup or partial assistance. | D127: Requires staff to complete most tasks or two staff for safety. | E127: Fully dependent or distressed/resistive requiring planned approach.
A128: Continence | B128: Continent and manages independently. | C128: Prompting, pad checks or occasional assistance. | D128: Double incontinence, regular toileting programme or staff-led care. | E128: Catheter/stoma/complex continence care or total continence support.
A129: Nutrition & Hydration | B129: Eats/drinks independently; normal diet. | C129: Prompting, monitoring, modified diet or encouragement. | D129: Requires physical assistance, high choking/weight loss/dehydration risk. | E129: PEG, total feeding assistance, severe dysphagia or complex monitoring.
A130: Medication | B130: Routine administration with no additional monitoring concerns. | C130: Needs prompts/standard staff administration. | D130: Medication requires close monitoring or affects falls/behaviour/alertness. | E130: Complex medicines, oxygen, syringe driver, EOL or high-risk monitoring.
A131: Skin Integrity | B131: Skin intact and low risk. | C131: At risk; pressure care prompts or cushion/mattress checks. | D131: Pressure damage risk, repositioning support or wound monitoring. | E131: Grade 3/4 pressure damage, complex wounds or intensive repositioning.
A132: Falls Risk | B132: Low falls risk; mobilises safely. | C132: Moderate risk; walking aid/supervision required. | D132: High risk, recent falls or poor safety awareness. | E132: Frequent falls, unwitnessed falls risk or needs close supervision.
A133: Behaviour | B133: No behaviour affecting care or evacuation. | C133: Occasional anxiety, reassurance required. | D133: Wandering, exit seeking, distress or resistance affecting safety. | E133: Severe distress/aggression/continuous supervision affecting evacuation.
A134: Cognition | B134: Orientated and follows instructions. | C134: Mild impairment; needs reminders/reassurance. | D134: Dementia or confusion affecting risk awareness and evacuation. | E134: Severe dementia/delirium; unable to follow evacuation instructions.
...

Sheet January PEEP Bag
A1: January PEEP Grab Bag Monthly Audit
A2: Check required quantity, actual quantity, condition and actions. Linked to dashboard.
A4: Review Month | B4: January
A5: Review Date
A6: Checked By
A7: Audit Complete?
A8: Total Items | B8: =COUNTA(A14:A60) -> 28
A9: Items Failed / Short | B9: =COUNTIF(H14:H60,"FAIL") -> 28
A10: Overall Status | B10: =IF(AND(B7="Yes",B9=0),"Complete","Incomplete") -> Incomplete
A13: Item | B13: Required Quantity | C13: Actual Quantity | D13: Condition / Currency | E13: Expiry Date if Applicable | F13: Present? | G13: Action Required | H13: Pass/Fail | I13: Comments
A14: Resident PEEP folder | B14: 1 | D14: Folder present, current and accessible | H14: =IF(OR(F14="No",C14<B14),"FAIL","PASS") -> FAIL
A15: Current resident list | B15: 1 | D15: All residents included | H15: =IF(OR(F15="No",C15<B15),"FAIL","PASS") -> FAIL
A16: Current dependency summary | B16: 1 | D16: Matches monthly dependency sheet | H16: =IF(OR(F16="No",C16<B16),"FAIL","PASS") -> FAIL
A17: Emergency contact list | B17: 1 | D17: Current family/NOK and professionals | H17: =IF(OR(F17="No",C17<B17),"FAIL","PASS") -> FAIL
A18: Floor plans - ground and first floor | B18: 2 | D18: Clear routes and exits | H18: =IF(OR(F18="No",C18<B18),"FAIL","PASS") -> FAIL
A19: Horizontal evacuation plan | B19: 1 | D19: Current and signed off | H19: =IF(OR(F19="No",C19<B19),"FAIL","PASS") -> FAIL
A20: Business continuity plan extract | B20: 1 | D20: Emergency accommodation and transport noted | H20: =IF(OR(F20="No",C20<B20),"FAIL","PASS") -> FAIL
A21: Fire action notices | B21: 2 | D21: Clear staff instruction | H21: =IF(OR(F21="No",C21<B21),"FAIL","PASS") -> FAIL
A22: Master keys | B22: 1 | D22: Full set present and labelled | H22: =IF(OR(F22="No",C22<B22),"FAIL","PASS") -> FAIL
A23: Door fobs/codes list | B23: 2 | D23: Working and accessible | H23: =IF(OR(F23="No",C23<B23),"FAIL","PASS") -> FAIL
A24: Walkie-talkies | B24: 2 | D24: Working and charged | H24: =IF(OR(F24="No",C24<B24),"FAIL","PASS") -> FAIL
A25: Spare radio batteries/chargers | B25: 2 | D25: Working | H25: =IF(OR(F25="No",C25<B25),"FAIL","PASS") -> FAIL
... A41: Evacuation equipment checklist | B41: 1 | D41: Current | H41: =IF(OR(F41="No",C41<B41),"FAIL","PASS") -> FAIL

Sheet January First Aid
A1: January First Aid Monthly Audit
A2: Check quantity, expiry and actions. Linked to dashboard.
A4: Review Month | B4: January
A5: Review Date
A6: Checked By
A7: Audit Complete?
A8: Total Lines | B8: =COUNTA(A14:A60) -> 22
A9: Lines Failed / Short | B9: =COUNTIF(G14:G60,"FAIL") -> 22
A10: Overall Status | B10: =IF(AND(B7="Yes",B9=0),"Complete","Incomplete") -> Incomplete
A13: Item | B13: Required Quantity | C13: Actual Quantity | D13: Expiry Date | E13: In Date? | F13: Action Required | G13: Pass/Fail | H13: Comments
A14: Large sterile dressings | B14: 6 | G14: =IF(OR(C14<B14,E14="No"),"FAIL","PASS") -> FAIL
A15: Medium sterile dressings | B15: 8 | G15: =IF(OR(C15<B15,E15="No"),"FAIL","PASS") -> FAIL
A16: Small sterile dressings | B16: 10 | G16: =IF(OR(C16<B16,E16="No"),"FAIL","PASS") -> FAIL
A17: Eye dressings | B17: 4 | G17: =IF(OR(C17<B17,E17="No"),"FAIL","PASS") -> FAIL
A18: Triangular bandages | B18: 6 | G18: =IF(OR(C18<B18,E18="No"),"FAIL","PASS") -> FAIL
A19: Conforming bandages | B19: 6 | G19: =IF(OR(C19<B19,E19="No"),"FAIL","PASS") -> FAIL
A20: Finger dressings | B20: 10 | G20: =IF(OR(C20<B20,E20="No"),"FAIL","PASS") -> FAIL
A21: Burn dressings | B21: 4 | G21: =IF(OR(C21<B21,E21="No"),"FAIL","PASS") -> FAIL
A22: Burn gel sachets/dressings | B22: 4 | G22: =IF(OR(C22<B22,E22="No"),"FAIL","PASS") -> FAIL
A23: Microporous tape | B23: 2 | G23: =IF(OR(C23<B23,E23="No"),"FAIL","PASS") -> FAIL
A24: Disposable gloves - pairs | B24: 50 | G24: =IF(OR(C24<B24,E24="No"),"FAIL","PASS") -> FAIL
A25: CPR face shields | B25: 2 | G25: =IF(OR(C25<B25,E25="No"),"FAIL","PASS") -> FAIL
... A35: AED battery ok if available | B35: 1 | G35: =IF(OR(C35<B35,E35="No"),"FAIL","PASS") -> FAIL

Sheet January Emollients
A1: January Emollient Monthly Audit
A2: Resident-level emollient audit with quantities, MAR/topical chart and fire risk. Linked to dashboard.
A4: Review Month | B4: January
A5: Review Date
A6: Checked By
A7: Audit Complete?
A8: Residents Audited | B8: =COUNTA(A14:A113) -> 0
A9: Failed / Action Required | B9: =COUNTIF(O14:O113,"FAIL") -> 0
A10: Overall Status | B10: =IF(AND(B7="Yes",B9=0),"Complete","Incomplete") -> Incomplete
A13: Resident Name | B13: Room | C13: Prescribed Emollient | D13: Required Quantity | E13: Actual Quantity | F13: In Date? | G13: Opening Date Recorded? | H13: Tub Labelled? | I13: Stored Safely? | J13: Care Plan Updated? | K13: MAR / Topical Chart Signed? | L13: Fire Risk Discussed? | M13: Cross Contamination Controlled? | N13: Action Required | O13: Status
O14: =IF(OR(E14<D14,F14="No",G14="No",H14="No",I14="No",J14="No",K14="No",L14="No",M14="No"),"FAIL","PASS") -> PASS
O15: =IF(OR(E15<D15,F15="No",G15="No",H15="No",I15="No",J15="No",K15="No",L15="No",M15="No"),"FAIL","PASS") -> PASS
O16: =IF(OR(E16<D16,F16="No",G16="No",H16="No",I16="No",J16="No",K16="No",L16="No",M16="No"),"FAIL","PASS") -> PASS
O17: =IF(OR(E17<D17,F17="No",G17="No",H17="No",I17="No",J17="No",K17="No",L17="No",M17="No"),"FAIL","PASS") -> PASS
O18: =IF(OR(E18<D18,F18="No",G18="No",H18="No",I18="No",J18="No",K18="No",L18="No",M18="No"),"FAIL","PASS") -> PASS
O19: =IF(OR(E19<D19,F19="No",G19="No",H19="No",I19="No",J19="No",K19="No",L19="No",M19="No"),"FAIL","PASS") -> PASS
O20: =IF(OR(E20<D20,F20="No",G20="No",H20="No",I20="No",J20="No",K20="No",L20="No",M20="No"),"FAIL","PASS") -> PASS
O21: =IF(OR(E21<D21,F21="No",G21="No",H21="No",I21="No",J21="No",K21="No",L21="No",M21="No"),"FAIL","PASS") -> PASS
O22: =IF(OR(E22<D22,F22="No",G22="No",H22="No",I22="No",J22="No",K22="No",L22="No",M22="No"),"FAIL","PASS") -> PASS
O23: =IF(OR(E23<D23,F23="No",G23="No",H23="No",I23="No",J23="No",K23="No",L23="No",M23="No"),"FAIL","PASS") -> PASS
O24: =IF(OR(E24<D24,F24="No",G24="No",H24="No",I24="No",J24="No",K24="No",L24="No",M24="No"),"FAIL","PASS") -> PASS
O25: =IF(OR(E25<D25,F25="No",G25="No",H25="No",I25="No",J25="No",K25="No",L25="No",M25="No"),"FAIL","PASS") -> PASS
... O113: =IF(OR(E113<D113,F113="No",G113="No",H113="No",I113="No",J113="No",K113="No",L113="No",M113="No"),"FAIL","PASS") -> PASS

Sheet February Dependency
A1: February Dependency Tool - Category-Based Day/Night Assessment
A2: Select Low/Medium/High/Very High in each category. Overall dependency is calculated automatically. Guidance notes are included on this tab.
A4: Review Month | B4: February | D4: Overall Dependency Rule
A5: Review Date | D5: Low | E5: All/mostly low risk; prompting only; walks with direction.
A6: Reviewed By | D6: Medium | E6: Regular one staff support, supervision, reassurance or monitoring.
A7: Assessment Complete? | D7: High | E7: Two staff, hoist/wheelchair, high falls/dementia/behaviour or assisted evacuation.
A8: Total Residents | B8: =COUNTA(A18:A117) -> 0 | D8: Very High | E8: Fully dependent, complex clinical/EOL/bariatric/oxygen or specialist evacuation needs.
A9: Low | B9: =COUNTIF(Z18:Z117,"Low") -> 0
A10: Medium | B10: =COUNTIF(Z18:Z117,"Medium") -> 0
A11: High | B11: =COUNTIF(Z18:Z117,"High") -> 0
A12: Very High | B12: =COUNTIF(Z18:Z117,"Very High") -> 0
A13: Residents Changed This Month | B13: =COUNTIF(AD18:AD117,"Yes") -> 0
A14: Manager Monthly Comment
A17: Resident Name | B17: Room | C17: Floor | D17: Zone | E17: PEEP Review Date | F17: Assessor | G17: Review Date | H17: Mobility | I17: Transfers | J17: Personal Care | K17: Washing & Dressing | L17: Continence | M17: Nutrition & Hydration | N17: Medication | O17: Skin Integrity | P17: Falls Risk | Q17: Behaviour | R17: Cognition | S17: Communication | T17: Clinical Needs | U17: Mental Health | V17: Sleep/Night Needs | W17: Fire Evacuation Needs | X17: End of Life Care | Y17: Infection Control | Z17: Overall Dependency | AA17: Day Staffing Note | AB17: Night Staffing Note | AC17: Evacuation Equipment | AD17: Change This Month? | AE17: Date of Change | AF17: What Happened / Impact | AG17: Actions Taken | AH17: Care Plan Updated? | AI17: Risk Assessment Updated? | AJ17: PEEP Updated? | AK17: Manager Initials
Z18: =IF(COUNTA(H18:Y18)=0,"",IF(COUNTIF(H18:Y18,"Very High")>0,"Very High",IF(COUNTIF(H18:Y18,"High")>0,"High",IF(COUNTIF(H18:Y18,"Medium")>0,"Medium","Low")))) | AA18: =IF(Z18="","",IF(Z18="Low","Routine planned support",IF(Z18="Medium","One staff support/supervision likely",IF(Z18="High","Two staff/review staffing and equipment","Manager review: multiple staff/specialist support")))) | AB18: =IF(Z18="","",IF(OR(Z18="High",Z18="Very High",W18="High",W18="Very High"),"Night staffing and evacuation review required","Routine night checks as per care plan")) | AC18: =IF(X18="Very High","Specialist PEEP / equipment",IF(OR(X18="High",Z18="High"),"Evacuation sheet/chair or wheelchair per PEEP",IF(OR(X18="Medium",Z18="Medium"),"Walking aid/wheelchair support per PEEP","Walks with direction"))) -> Walks with direction
Z19: =IF(COUNTA(H19:Y19)=0,"",IF(COUNTIF(H19:Y19,"Very High")>0,"Very High",IF(COUNTIF(H19:Y19,"High")>0,"High",IF(COUNTIF(H19:Y19,"Medium")>0,"Medium","Low")))) | AA19: =IF(Z19="","",IF(Z19="Low","Routine planned support",IF(Z19="Medium","One staff support/supervision likely",IF(Z19="High","Two staff/review staffing and equipment","Manager review: multiple staff/specialist support")))) | AB19: =IF(Z19="","",IF(OR(Z19="High",Z19="Very High",W19="High",W19="Very High"),"Night staffing and evacuation review required","Routine night checks as per care plan")) | AC19: =IF(X19="Very High","Specialist PEEP / equipment",IF(OR(X19="High",Z19="High"),"Evacuation sheet/chair or wheelchair per PEEP",IF(OR(X19="Medium",Z19="Medium"),"Walking aid/wheelchair support per PEEP","Walks with direction"))) -> Walks with direction
Z20: =IF(COUNTA(H20:Y20)=0,"",IF(COUNTIF(H20:Y20,"Very High")>0,"Very High",IF(COUNTIF(H20:Y20,"High")>0,"High",IF(COUNTIF(H20:Y20,"Medium")>0,"Medium","Low")))) | AA20: =IF(Z20="","",IF(Z20="Low","Routine planned support",IF(Z20="Medium","One staff support/supervision likely",IF(Z20="High","Two staff/review staffing and equipment","Manager review: multiple staff/specialist support")))) | AB20: =IF(Z20="","",IF(OR(Z20="High",Z20="Very High",W20="High",W20="Very High"),"Night staffing and evacuation review required","Routine night checks as per care plan")) | AC20: =IF(X20="Very High","Specialist PEEP / equipment",IF(OR(X20="High",Z20="High"),"Evacuation sheet/chair or wheelchair per PEEP",IF(OR(X20="Medium",Z20="Medium"),"Walking aid/wheelchair support per PEEP","Walks with direction"))) -> Walks with direction
Z21: =IF(COUNTA(H21:Y21)=0,"",IF(COUNTIF(H21:Y21,"Very High")>0,"Very High",IF(COUNTIF(H21:Y21,"High")>0,"High",IF(COUNTIF(H21:Y21,"Medium")>0,"Medium","Low")))) | AA21: =IF(Z21="","",IF(Z21="Low","Routine planned support",IF(Z21="Medium","One staff support/supervision likely",IF(Z21="High","Two staff/review staffing and equipment","Manager review: multiple staff/specialist support")))) | AB21: =IF(Z21="","",IF(OR(Z21="High",Z21="Very High",W21="High",W21="Very High"),"Night staffing and evacuation review required","Routine night checks as per care plan")) | AC21: =IF(X21="Very High","Specialist PEEP / equipment",IF(OR(X21="High",Z21="High"),"Evacuation sheet/chair or wheelchair per PEEP",IF(OR(X21="Medium",Z21="Medium"),"Walking aid/wheelchair support per PEEP","Walks with direction"))) -> Walks with direction
Z22: =IF(COUNTA(H22:Y22)=0,"",IF(COUNTIF(H22:Y22,"Very High")>0,"Very High",IF(COUNTIF(H22:Y22,"High")>0,"High",IF(COUNTIF(H22:Y22,"Medium")>0,"Medium","Low")))) | AA22: =IF(Z22="","",IF(Z22="Low","Routine planned support",IF(Z22="Medium","One staff support/supervision likely",IF(Z22="High","Two staff/review staffing and equipment","Manager review: multiple staff/specialist support")))) | AB22: =IF(Z22="","",IF(OR(Z22="High",Z22="Very High",W22="High",W22="Very High"),"Night staffing and evacuation review required","Routine night checks as per care plan")) | AC22: =IF(X22="Very High","Specialist PEEP / equipment",IF(OR(X22="High",Z22="High"),"Evacuation sheet/chair or wheelchair per PEEP",IF(OR(X22="Medium",Z22="Medium"),"Walking aid/wheelchair support per PEEP","Walks with direction"))) -> Walks with direction
Z23: =IF(COUNTA(H23:Y23)=0,"",IF(COUNTIF(H23:Y23,"Very High")>0,"Very High",IF(COUNTIF(H23:Y23,"High")>0,"High",IF(COUNTIF(H23:Y23,"Medium")>0,"Medium","Low")))) | AA23: =IF(Z23="","",IF(Z23="Low","Routine planned support",IF(Z23="Medium","One staff support/supervision likely",IF(Z23="High","Two staff/review staffing and equipment","Manager review: multiple staff/specialist support")))) | AB23: =IF(Z23="","",IF(OR(Z23="High",Z23="Very High",W23="High",W23="Very High"),"Night staffing and evacuation review required","Routine night checks as per care plan")) | AC23: =IF(X23="Very High","Specialist PEEP / equipment",IF(OR(X23="High",Z23="High"),"Evacuation sheet/chair or wheelchair per PEEP",IF(OR(X23="Medium",Z23="Medium"),"Walking aid/wheelchair support per PEEP","Walks with direction"))) -> Walks with direction
Z24: =IF(COUNTA(H24:Y24)=0,"",IF(COUNTIF(H24:Y24,"Very High")>0,"Very High",IF(COUNTIF(H24:Y24,"High")>0,"High",IF(COUNTIF(H24:Y24,"Medium")>0,"Medium","Low")))) | AA24: =IF(Z24="","",IF(Z24="Low","Routine planned support",IF(Z24="Medium","One staff support/supervision likely",IF(Z24="High","Two staff/review staffing and equipment","Manager review: multiple staff/specialist support")))) | AB24: =IF(Z24="","",IF(OR(Z24="High",Z24="Very High",W24="High",W24="Very High"),"Night staffing and evacuation review required","Routine night checks as per care plan")) | AC24: =IF(X24="Very High","Specialist PEEP / equipment",IF(OR(X24="High",Z24="High"),"Evacuation sheet/chair or wheelchair per PEEP",IF(OR(X24="Medium",Z24="Medium"),"Walking aid/wheelchair support per PEEP","Walks with direction"))) -> Walks with direction
Z25: =IF(COUNTA(H25:Y25)=0,"",IF(COUNTIF(H25:Y25,"Very High")>0,"Very High",IF(COUNTIF(H25:Y25,"High")>0,"High",IF(COUNTIF(H25:Y25,"Medium")>0,"Medium","Low")))) | AA25: =IF(Z25="","",IF(Z25="Low","Routine planned support",IF(Z25="Medium","One staff support/supervision likely",IF(Z25="High","Two staff/review staffing and equipment","Manager review: multiple staff/specialist support")))) | AB25: =IF(Z25="","",IF(OR(Z25="High",Z25="Very High",W25="High",W25="Very High"),"Night staffing and evacuation review required","Routine night checks as per care plan")) | AC25: =IF(X25="Very High","Specialist PEEP / equipment",IF(OR(X25="High",Z25="High"),"Evacuation sheet/chair or wheelchair per PEEP",IF(OR(X25="Medium",Z25="Medium"),"Walking aid/wheelchair support per PEEP","Walks with direction"))) -> Walks with direction
Z26: =IF(COUNTA(H26:Y26)=0,"",IF(COUNTIF(H26:Y26,"Very High")>0,"Very High",IF(COUNTIF(H26:Y26,"High")>0,"High",IF(COUNTIF(H26:Y26,"Medium")>0,"Medium","Low")))) | AA26: =IF(Z26="","",IF(Z26="Low","Routine planned support",IF(Z26="Medium","One staff support/supervision likely",IF(Z26="High","Two staff/review staffing and equipment","Manager review: multiple staff/specialist support")))) | AB26: =IF(Z26="","",IF(OR(Z26="High",Z26="Very High",W26="High",W26="Very High"),"Night staffing and evacuation review required","Routine night checks as per care plan")) | AC26: =IF(X26="Very High","Specialist PEEP / equipment",IF(OR(X26="High",Z26="High"),"Evacuation sheet/chair or wheelchair per PEEP",IF(OR(X26="Medium",Z26="Medium"),"Walking aid/wheelchair support per PEEP","Walks with direction"))) -> Walks with direction
Z27: =IF(COUNTA(H27:Y27)=0,"",IF(COUNTIF(H27:Y27,"Very High")>0,"Very High",IF(COUNTIF(H27:Y27,"High")>0,"High",IF(COUNTIF(H27:Y27,"Medium")>0,"Medium","Low")))) | AA27: =IF(Z27="","",IF(Z27="Low","Routine planned support",IF(Z27="Medium","One staff support/supervision likely",IF(Z27="High","Two staff/review staffing and equipment","Manager review: multiple staff/specialist support")))) | AB27: =IF(Z27="","",IF(OR(Z27="High",Z27="Very High",W27="High",W27="Very High"),"Night staffing and evacuation review required","Routine night checks as per care plan")) | AC27: =IF(X27="Very High","Specialist PEEP / equipment",IF(OR(X27="High",Z27="High"),"Evacuation sheet/chair or wheelchair per PEEP",IF(OR(X27="Medium",Z27="Medium"),"Walking aid/wheelchair support per PEEP","Walks with direction"))) -> Walks with direction
Z28: =IF(COUNTA(H28:Y28)=0,"",IF(COUNTIF(H28:Y28,"Very High")>0,"Very High",IF(COUNTIF(H28:Y28,"High")>0,"High",IF(COUNTIF(H28:Y28,"Medium")>0,"Medium","Low")))) | AA28: =IF(Z28="","",IF(Z28="Low","Routine planned support",IF(Z28="Medium","One staff support/supervision likely",IF(Z28="High","Two staff/review staffing and equipment","Manager review: multiple staff/specialist support")))) | AB28: =IF(Z28="","",IF(OR(Z28="High",Z28="Very High",W28="High",W28="Very High"),"Night staffing and evacuation review required","Routine night checks as per care plan")) | AC28: =IF(X28="Very High","Specialist PEEP / equipment",IF(OR(X28="High",Z28="High"),"Evacuation sheet/chair or wheelchair per PEEP",IF(OR(X28="Medium",Z28="Medium"),"Walking aid/wheelchair support per PEEP","Walks with direction"))) -> Walks with direction
Z29: =IF(COUNTA(H29:Y29)=0,"",IF(COUNTIF(H29:Y29,"Very High")>0,"Very High",IF(COUNTIF(H29:Y29,"High")>0,"High",IF(COUNTIF(H29:Y29,"Medium")>0,"Medium","Low")))) | AA29: =IF(Z29="","",IF(Z29="Low","Routine planned support",IF(Z29="Medium","One staff support/supervision likely",IF(Z29="High","Two staff/review staffing and equipment","Manager review: multiple staff/specialist support")))) | AB29: =IF(Z29="","",IF(OR(Z29="High",Z29="Very High",W29="High",W29="Very High"),"Night staffing and evacuation review required","Routine night checks as per care plan")) | AC29: =IF(X29="Very High","Specialist PEEP / equipment",IF(OR(X29="High",Z29="High"),"Evacuation sheet/chair or wheelchair per PEEP",IF(OR(X29="Medium",Z29="Medium"),"Walking aid/wheelchair support per PEEP","Walks with direction"))) -> Walks with direction
... Z117: =IF(COUNTA(H117:Y117)=0,"",IF(COUNTIF(H117:Y117,"Very High")>0,"Very High",IF(COUNTIF(H117:Y117,"High")>0,"High",IF(COUNTIF(H117:Y117,"Medium")>0,"Medium","Low")))) | AA117: =IF(Z117="","",IF(Z117="Low","Routine planned support",IF(Z117="Medium","One staff support/supervision likely",IF(Z117="High","Two staff/review staffing and equipment","Manager review: multiple staff/specialist support")))) | AB117: =IF(Z117="","",IF(OR(Z117="High",Z117="Very High",W117="High",W117="Very High"),"Night staffing and evacuation review required","Routine night checks as per care plan")) | AC117: =IF(X117="Very High","Specialist PEEP / equipment",IF(OR(X117="High",Z117="High"),"Evacuation sheet/chair or wheelchair per PEEP",IF(OR(X117="Medium",Z117="Medium"),"Walking aid/wheelchair support per PEEP","Walks with direction"))) -> Walks with direction
A122: Dependency Category Guidance - use these notes when selecting the resident rating
A123: Category | B123: Low | C123: Medium | D123: High | E123: Very High
A124: Mobility | B124: Walks independently; may need verbal direction only. | C124: Uses walking aid or requires supervision/reassurance. | D124: Wheelchair user or requires one/two staff physical assistance. | E124: Bedbound, unable to mobilise, bariatric mobility or fully dependent.
A125: Transfers | B125: Independent transfers safely. | C125: Supervision, prompt or one staff light support. | D125: Two staff, stand aid, rotunda or high falls risk during transfer. | E125: Hoist, complex transfer, bariatric or unsafe without specialist plan.
A126: Personal Care | B126: Independent or prompting only. | C126: Assistance with some washing, dressing or grooming. | D126: Full assistance from staff for most personal care. | E126: Total care, two staff or complex dignity/skin risks.
A127: Washing & Dressing | B127: Chooses clothes and completes tasks with little/no help. | C127: Prompting, setup or partial assistance. | D127: Requires staff to complete most tasks or two staff for safety. | E127: Fully dependent or distressed/resistive requiring planned approach.
A128: Continence | B128: Continent and manages independently. | C128: Prompting, pad checks or occasional assistance. | D128: Double incontinence, regular toileting programme or staff-led care. | E128: Catheter/stoma/complex continence care or total continence support.
A129: Nutrition & Hydration | B129: Eats/drinks independently; normal diet. | C129: Prompting, monitoring, modified diet or encouragement. | D129: Requires physical assistance, high choking/weight loss/dehydration risk. | E129: PEG, total feeding assistance, severe dysphagia or complex monitoring.
A130: Medication | B130: Routine administration with no additional monitoring concerns. | C130: Needs prompts/standard staff administration. | D130: Medication requires close monitoring or affects falls/behaviour/alertness. | E130: Complex medicines, oxygen, syringe driver, EOL or high-risk monitoring.
A131: Skin Integrity | B131: Skin intact and low risk. | C131: At risk; pressure care prompts or cushion/mattress checks. | D131: Pressure damage risk, repositioning support or wound monitoring. | E131: Grade 3/4 pressure damage, complex wounds or intensive repositioning.
A132: Falls Risk | B132: Low falls risk; mobilises safely. | C132: Moderate risk; walking aid/supervision required. | D132: High risk, recent falls or poor safety awareness. | E132: Frequent falls, unwitnessed falls risk or needs close supervision.
A133: Behaviour | B133: No behaviour affecting care or evacuation. | C133: Occasional anxiety, reassurance required. | D133: Wandering, exit seeking, distress or resistance affecting safety. | E133: Severe distress/aggression/continuous supervision affecting evacuation.
A134: Cognition | B134: Orientated and follows instructions. | C134: Mild impairment; needs reminders/reassurance. | D134: Dementia or confusion affecting risk awareness and evacuation. | E134: Severe dementia/delirium; unable to follow evacuation instructions.
...

Sheet February PEEP Bag
A1: February PEEP Grab Bag Monthly Audit
A2: Check required quantity, actual quantity, condition and actions. Linked to dashboard.
A4: Review Month | B4: February
A5: Review Date
A6: Checked By
A7: Audit Complete?
A8: Total Items | B8: =COUNTA(A14:A60) -> 28
A9: Items Failed / Short | B9: =COUNTIF(H14:H60,"FAIL") -> 28
A10: Overall Status | B10: =IF(AND(B7="Yes",B9=0),"Complete","Incomplete") -> Incomplete
A13: Item | B13: Required Quantity | C13: Actual Quantity | D13: Condition / Currency | E13: Expiry Date if Applicable | F13: Present? | G13: Action Required | H13: Pass/Fail | I13: Comments
A14: Resident PEEP folder | B14: 1 | D14: Folder present, current and accessible | H14: =IF(OR(F14="No",C14<B14),"FAIL","PASS") -> FAIL
A15: Current resident list | B15: 1 | D15: All residents included | H15: =IF(OR(F15="No",C15<B15),"FAIL","PASS") -> FAIL
A16: Current dependency summary | B16: 1 | D16: Matches monthly dependency sheet | H16: =IF(OR(F16="No",C16<B16),"FAIL","PASS") -> FAIL
A17: Emergency contact list | B17: 1 | D17: Current family/NOK and professionals | H17: =IF(OR(F17="No",C17<B17),"FAIL","PASS") -> FAIL
A18: Floor plans - ground and first floor | B18: 2 | D18: Clear routes and exits | H18: =IF(OR(F18="No",C18<B18),"FAIL","PASS") -> FAIL
A19: Horizontal evacuation plan | B19: 1 | D19: Current and signed off | H19: =IF(OR(F19="No",C19<B19),"FAIL","PASS") -> FAIL
A20: Business continuity plan extract | B20: 1 | D20: Emergency accommodation and transport noted | H20: =IF(OR(F20="No",C20<B20),"FAIL","PASS") -> FAIL
A21: Fire action notices | B21: 2 | D21: Clear staff instruction | H21: =IF(OR(F21="No",C21<B21),"FAIL","PASS") -> FAIL
A22: Master keys | B22: 1 | D22: Full set present and labelled | H22: =IF(OR(F22="No",C22<B22),"FAIL","PASS") -> FAIL
A23: Door fobs/codes list | B23: 2 | D23: Working and accessible | H23: =IF(OR(F23="No",C23<B23),"FAIL","PASS") -> FAIL
A24: Walkie-talkies | B24: 2 | D24: Working and charged | H24: =IF(OR(F24="No",C24<B24),"FAIL","PASS") -> FAIL
A25: Spare radio batteries/chargers | B25: 2 | D25: Working | H25: =IF(OR(F25="No",C25<B25),"FAIL","PASS") -> FAIL
... A41: Evacuation equipment checklist | B41: 1 | D41: Current | H41: =IF(OR(F41="No",C41<B41),"FAIL","PASS") -> FAIL

Sheet February First Aid
A1: February First Aid Monthly Audit
A2: Check quantity, expiry and actions. Linked to dashboard.
A4: Review Month | B4: February
A5: Review Date
A6: Checked By
A7: Audit Complete?
A8: Total Lines | B8: =COUNTA(A14:A60) -> 22
A9: Lines Failed / Short | B9: =COUNTIF(G14:G60,"FAIL") -> 22
A10: Overall Status | B10: =IF(AND(B7="Yes",B9=0),"Complete","Incomplete") -> Incomplete
A13: Item | B13: Required Quantity | C13: Actual Quantity | D13: Expiry Date | E13: In Date? | F13: Action Required | G13: Pass/Fail | H13: Comments
A14: Large sterile dressings | B14: 6 | G14: =IF(OR(C14<B14,E14="No"),"FAIL","PASS") -> FAIL
A15: Medium sterile dressings | B15: 8 | G15: =IF(OR(C15<B15,E15="No"),"FAIL","PASS") -> FAIL
A16: Small sterile dressings | B16: 10 | G16: =IF(OR(C16<B16,E16="No"),"FAIL","PASS") -> FAIL
A17: Eye dressings | B17: 4 | G17: =IF(OR(C17<B17,E17="No"),"FAIL","PASS") -> FAIL
A18: Triangular bandages | B18: 6 | G18: =IF(OR(C18<B18,E18="No"),"FAIL","PASS") -> FAIL
A19: Conforming bandages | B19: 6 | G19: =IF(OR(C19<B19,E19="No"),"FAIL","PASS") -> FAIL
A20: Finger dressings | B20: 10 | G20: =IF(OR(C20<B20,E20="No"),"FAIL","PASS") -> FAIL
A21: Burn dressings | B21: 4 | G21: =IF(OR(C21<B21,E21="No"),"FAIL","PASS") -> FAIL
A22: Burn gel sachets/dressings | B22: 4 | G22: =IF(OR(C22<B22,E22="No"),"FAIL","PASS") -> FAIL
A23: Microporous tape | B23: 2 | G23: =IF(OR(C23<B23,E23="No"),"FAIL","PASS") -> FAIL
A24: Disposable gloves - pairs | B24: 50 | G24: =IF(OR(C24<B24,E24="No"),"FAIL","PASS") -> FAIL
A25: CPR face shields | B25: 2 | G25: =IF(OR(C25<B25,E25="No"),"FAIL","PASS") -> FAIL
... A35: AED battery ok if available | B35: 1 | G35: =IF(OR(C35<B35,E35="No"),"FAIL","PASS") -> FAIL

Sheet February Emollients
A1: February Emollient Monthly Audit
A2: Resident-level emollient audit with quantities, MAR/topical chart and fire risk. Linked to dashboard.
A4: Review Month | B4: February
A5: Review Date
A6: Checked By
A7: Audit Complete?
A8: Residents Audited | B8: =COUNTA(A14:A113) -> 0
A9: Failed / Action Required | B9: =COUNTIF(O14:O113,"FAIL") -> 0
A10: Overall Status | B10: =IF(AND(B7="Yes",B9=0),"Complete","Incomplete") -> Incomplete
A13: Resident Name | B13: Room | C13: Prescribed Emollient | D13: Required Quantity | E13: Actual Quantity | F13: In Date? | G13: Opening Date Recorded? | H13: Tub Labelled? | I13: Stored Safely? | J13: Care Plan Updated? | K13: MAR / Topical Chart Signed? | L13: Fire Risk Discussed? | M13: Cross Contamination Controlled? | N13: Action Required | O13: Status
O14: =IF(OR(E14<D14,F14="No",G14="No",H14="No",I14="No",J14="No",K14="No",L14="No",M14="No"),"FAIL","PASS") -> PASS
O15: =IF(OR(E15<D15,F15="No",G15="No",H15="No",I15="No",J15="No",K15="No",L15="No",M15="No"),"FAIL","PASS") -> PASS
O16: =IF(OR(E16<D16,F16="No",G16="No",H16="No",I16="No",J16="No",K16="No",L16="No",M16="No"),"FAIL","PASS") -> PASS
O17: =IF(OR(E17<D17,F17="No",G17="No",H17="No",I17="No",J17="No",K17="No",L17="No",M17="No"),"FAIL","PASS") -> PASS
O18: =IF(OR(E18<D18,F18="No",G18="No",H18="No",I18="No",J18="No",K18="No",L18="No",M18="No"),"FAIL","PASS") -> PASS
O19: =IF(OR(E19<D19,F19="No",G19="No",H19="No",I19="No",J19="No",K19="No",L19="No",M19="No"),"FAIL","PASS") -> PASS
O20: =IF(OR(E20<D20,F20="No",G20="No",H20="No",I20="No",J20="No",K20="No",L20="No",M20="No"),"FAIL","PASS") -> PASS
O21: =IF(OR(E21<D21,F21="No",G21="No",H21="No",I21="No",J21="No",K21="No",L21="No",M21="No"),"FAIL","PASS") -> PASS
O22: =IF(OR(E22<D22,F22="No",G22="No",H22="No",I22="No",J22="No",K22="No",L22="No",M22="No"),"FAIL","PASS") -> PASS
O23: =IF(OR(E23<D23,F23="No",G23="No",H23="No",I23="No",J23="No",K23="No",L23="No",M23="No"),"FAIL","PASS") -> PASS
O24: =IF(OR(E24<D24,F24="No",G24="No",H24="No",I24="No",J24="No",K24="No",L24="No",M24="No"),"FAIL","PASS") -> PASS
O25: =IF(OR(E25<D25,F25="No",G25="No",H25="No",I25="No",J25="No",K25="No",L25="No",M25="No"),"FAIL","PASS") -> PASS
... O113: =IF(OR(E113<D113,F113="No",G113="No",H113="No",I113="No",J113="No",K113="No",L113="No",M113="No"),"FAIL","PASS") -> PASS

Sheet March Dependency
A1: March Dependency Tool - Category-Based Day/Night Assessment
A2: Select Low/Medium/High/Very High in each category. Overall dependency is calculated automatically. Guidance notes are included on this tab.
A4: Review Month | B4: March | D4: Overall Dependency Rule
A5: Review Date | D5: Low | E5: All/mostly low risk; prompting only; walks with direction.
A6: Reviewed By | D6: Medium | E6: Regular one staff support, supervision, reassurance or monitoring.
A7: Assessment Complete? | D7: High | E7: Two staff, hoist/wheelchair, high falls/dementia/behaviour or assisted evacuation.
A8: Total Residents | B8: =COUNTA(A18:A117) -> 0 | D8: Very High | E8: Fully dependent, complex clinical/EOL/bariatric/oxygen or specialist evacuation needs.
A9: Low | B9: =COUNTIF(Z18:Z117,"Low") -> 0
A10: Medium | B10: =COUNTIF(Z18:Z117,"Medium") -> 0
A11: High | B11: =COUNTIF(Z18:Z117,"High") -> 0
A12: Very High | B12: =COUNTIF(Z18:Z117,"Very High") -> 0
A13: Residents Changed This Month | B13: =COUNTIF(AD18:AD117,"Yes") -> 0
A14: Manager Monthly Comment
