Workbook

Sheet Mandatory Training Dashboard
A1: Training Compliance Dashboard – Consolidated Matrix
A3: Staff Compliance
A4: Staff | B4: Completed | C4: Total | D4: Compliance % | E4: RAG | F4: SW tabs Training % now pulls from this Staff Compliance %
A5: ='Consolidated Matrix'!A4 -> Niranjala Dissanayake | B5: ='Consolidated Matrix'!AG4 -> 23 | C5: ='Consolidated Matrix'!AH4 -> 31 | D5: ='Consolidated Matrix'!AI4 -> 0.74193548 | E5: ='Consolidated Matrix'!AJ4 -> AMBER
A6: ='Consolidated Matrix'!A5 -> Chelsee Booth | B6: ='Consolidated Matrix'!AG5 -> 16 | C6: ='Consolidated Matrix'!AH5 -> 31 | D6: ='Consolidated Matrix'!AI5 -> 0.51612903 | E6: ='Consolidated Matrix'!AJ5 -> RED
A7: ='Consolidated Matrix'!A6 -> Paula Merry | B7: ='Consolidated Matrix'!AG6 -> 22 | C7: ='Consolidated Matrix'!AH6 -> 31 | D7: ='Consolidated Matrix'!AI6 -> 0.70967742 | E7: ='Consolidated Matrix'!AJ6 -> AMBER
A8: ='Consolidated Matrix'!A7 -> Nathan Thomas | B8: ='Consolidated Matrix'!AG7 -> 19 | C8: ='Consolidated Matrix'!AH7 -> 31 | D8: ='Consolidated Matrix'!AI7 -> 0.61290323 | E8: ='Consolidated Matrix'!AJ7 -> AMBER
A9: ='Consolidated Matrix'!A8 -> Joel Jose | B9: ='Consolidated Matrix'!AG8 -> 19 | C9: ='Consolidated Matrix'!AH8 -> 31 | D9: ='Consolidated Matrix'!AI8 -> 0.61290323 | E9: ='Consolidated Matrix'!AJ8 -> AMBER
A10: ='Consolidated Matrix'!A9 -> Firos Latheef | B10: ='Consolidated Matrix'!AG9 -> 24 | C10: ='Consolidated Matrix'!AH9 -> 31 | D10: ='Consolidated Matrix'!AI9 -> 0.77419355 | E10: ='Consolidated Matrix'!AJ9 -> AMBER
A11: ='Consolidated Matrix'!A10 -> Kathleen Evans | B11: ='Consolidated Matrix'!AG10 -> 29 | C11: ='Consolidated Matrix'!AH10 -> 31 | D11: ='Consolidated Matrix'!AI10 -> 0.93548387 | E11: ='Consolidated Matrix'!AJ10 -> GREEN
A12: ='Consolidated Matrix'!A11 -> Sahil Sahil | B12: ='Consolidated Matrix'!AG11 -> 5 | C12: ='Consolidated Matrix'!AH11 -> 31 | D12: ='Consolidated Matrix'!AI11 -> 0.16129032 | E12: ='Consolidated Matrix'!AJ11 -> RED
A13: ='Consolidated Matrix'!A12 -> Haritha Sasidharan | B13: ='Consolidated Matrix'!AG12 -> 29 | C13: ='Consolidated Matrix'!AH12 -> 31 | D13: ='Consolidated Matrix'!AI12 -> 0.93548387 | E13: ='Consolidated Matrix'!AJ12 -> GREEN
A14: ='Consolidated Matrix'!A13 -> Abhina | B14: ='Consolidated Matrix'!AG13 -> 21 | C14: ='Consolidated Matrix'!AH13 -> 31 | D14: ='Consolidated Matrix'!AI13 -> 0.67741935 | E14: ='Consolidated Matrix'!AJ13 -> AMBER
A15: ='Consolidated Matrix'!A14 -> Carol (Domestic) | B15: ='Consolidated Matrix'!AG14 -> 19 | C15: ='Consolidated Matrix'!AH14 -> 31 | D15: ='Consolidated Matrix'!AI14 -> 0.61290323 | E15: ='Consolidated Matrix'!AJ14 -> AMBER
A16: ='Consolidated Matrix'!A15 -> Harry | B16: ='Consolidated Matrix'!AG15 -> 22 | C16: ='Consolidated Matrix'!AH15 -> 31 | D16: ='Consolidated Matrix'!AI15 -> 0.70967742 | E16: ='Consolidated Matrix'!AJ15 -> AMBER
A21: Training Topic Compliance
A22: Training Topic | B22: Completed | C22: Total Staff | D22: Completion % | E22: RAG
A23: ='Consolidated Matrix'!A21 -> Care Certificate | B23: ='Consolidated Matrix'!B21 -> 6 | C23: ='Consolidated Matrix'!C21 -> 12 | D23: ='Consolidated Matrix'!D21 -> 0.5 | E23: ='Consolidated Matrix'!E21 -> RED
A24: ='Consolidated Matrix'!A22 -> Equality, Diversity & Human Rights | B24: ='Consolidated Matrix'!B22 -> 7 | C24: ='Consolidated Matrix'!C22 -> 12 | D24: ='Consolidated Matrix'!D22 -> 0.58333333 | E24: ='Consolidated Matrix'!E22 -> RED
A25: ='Consolidated Matrix'!A23 -> Medication | B25: ='Consolidated Matrix'!B23 -> 5 | C25: ='Consolidated Matrix'!C23 -> 12 | D25: ='Consolidated Matrix'!D23 -> 0.41666667 | E25: ='Consolidated Matrix'!E23 -> RED
A26: ='Consolidated Matrix'!A24 -> Safeguarding Adults | B26: ='Consolidated Matrix'!B24 -> 10 | C26: ='Consolidated Matrix'!C24 -> 12 | D26: ='Consolidated Matrix'!D24 -> 0.83333333 | E26: ='Consolidated Matrix'!E24 -> GREEN
A27: ='Consolidated Matrix'!A25 -> Fire Safety / Fire Warden | B27: ='Consolidated Matrix'!B25 -> 11 | C27: ='Consolidated Matrix'!C25 -> 12 | D27: ='Consolidated Matrix'!D25 -> 0.91666667 | E27: ='Consolidated Matrix'!E25 -> GREEN
A28: ='Consolidated Matrix'!A26 -> Basic Life Support | B28: ='Consolidated Matrix'!B26 -> 10 | C28: ='Consolidated Matrix'!C26 -> 12 | D28: ='Consolidated Matrix'!D26 -> 0.83333333 | E28: ='Consolidated Matrix'!E26 -> GREEN
A29: ='Consolidated Matrix'!A27 -> Emergency First Aid | B29: ='Consolidated Matrix'!B27 -> 7 | C29: ='Consolidated Matrix'!C27 -> 12 | D29: ='Consolidated Matrix'!D27 -> 0.58333333 | E29: ='Consolidated Matrix'!E27 -> RED
A30: ='Consolidated Matrix'!A28 -> Moving & Handling | B30: ='Consolidated Matrix'!B28 -> 11 | C30: ='Consolidated Matrix'!C28 -> 12 | D30: ='Consolidated Matrix'!D28 -> 0.91666667 | E30: ='Consolidated Matrix'!E28 -> GREEN
A31: ='Consolidated Matrix'!A29 -> Infection Prevention & Control | B31: ='Consolidated Matrix'!B29 -> 9 | C31: ='Consolidated Matrix'!C29 -> 12 | D31: ='Consolidated Matrix'!D29 -> 0.75 | E31: ='Consolidated Matrix'!E29 -> AMBER
A32: ='Consolidated Matrix'!A30 -> Mental Capacity & DoLS | B32: ='Consolidated Matrix'!B30 -> 10 | C32: ='Consolidated Matrix'!C30 -> 12 | D32: ='Consolidated Matrix'!D30 -> 0.83333333 | E32: ='Consolidated Matrix'!E30 -> GREEN
A33: ='Consolidated Matrix'!A31 -> GDPR & Information Governance | B33: ='Consolidated Matrix'!B31 -> 5 | C33: ='Consolidated Matrix'!C31 -> 12 | D33: ='Consolidated Matrix'!D31 -> 0.41666667 | E33: ='Consolidated Matrix'!E31 -> RED
A34: ='Consolidated Matrix'!A32 -> Food Hygiene | B34: ='Consolidated Matrix'!B32 -> 10 | C34: ='Consolidated Matrix'!C32 -> 12 | D34: ='Consolidated Matrix'!D32 -> 0.83333333 | E34: ='Consolidated Matrix'!E32 -> GREEN
... A53: ='Consolidated Matrix'!A51 -> Parkinson's | B53: ='Consolidated Matrix'!B51 -> 8 | C53: ='Consolidated Matrix'!C51 -> 12 | D53: ='Consolidated Matrix'!D51 -> 0.66666667 | E53: ='Consolidated Matrix'!E51 -> AMBER

Sheet Training Dashboard
A1: Swan Care Home – Training Compliance Dashboard (June 2026)
A4: Executive KPIs
A6: Total Staff | C6: Total Courses | E6: Completed Results Imported | G6: Overall Compliance | I6: Green Staff | K6: Amber Staff
A7: 12 | C7: 109 | E7: 148 | G7: =IFERROR(SUM(Matrix!DH3:DH14)/SUM(Matrix!DI3:DI14),"") -> 0.25606061 | I7: =COUNTIF(Matrix!DK3:DK14,"GREEN") -> 0 | K7: =COUNTIF(Matrix!DK3:DK14,"AMBER") -> 0
A9: Red Staff | C9: Not Started Items | E9: In Progress Items | G9: CQC Training RAG
A10: =COUNTIF(Matrix!DK3:DK14,"RED") -> 12 | C10: =SUM(Matrix!DL3:DL14) -> 979 | E10: =SUM(Matrix!DM3:DM14) -> 3 | G10: =IF(G7>=0.9,"GREEN",IF(G7>=0.75,"AMBER","RED")) -> RED
A12: RAG Rules | J12: RAG | K12: Count
A13: GREEN | B13: ≥ 80% completed | J13: GREEN | K13: =COUNTIF(E20:E31,"GREEN") -> 0
A14: AMBER | B14: 60% - 79% completed | J14: AMBER | K14: =COUNTIF(E20:E31,"AMBER") -> 0
A15: RED | B15: < 60% completed | J15: RED | K15: =COUNTIF(E20:E31,"RED") -> 12
A18: Staff Compliance
A19: Staff Name | B19: Completed | C19: Total | D19: Compliance % | E19: RAG | F19: Missing/NS | G19: In Progress
A20: =Matrix!A3 -> Niranjala Dissanayake | B20: =Matrix!DH3 -> 30 | C20: =Matrix!DI3 -> 110 | D20: =Matrix!DJ3 -> 0.27272727 | E20: =Matrix!DK3 -> RED | F20: =Matrix!DL3 -> 80 | G20: =Matrix!DM3 -> 0
A21: =Matrix!A4 -> Chelsee Booth | B21: =Matrix!DH4 -> 19 | C21: =Matrix!DI4 -> 110 | D21: =Matrix!DJ4 -> 0.17272727 | E21: =Matrix!DK4 -> RED | F21: =Matrix!DL4 -> 90 | G21: =Matrix!DM4 -> 1
A22: =Matrix!A5 -> Paula Merry | B22: =Matrix!DH5 -> 44 | C22: =Matrix!DI5 -> 110 | D22: =Matrix!DJ5 -> 0.4 | E22: =Matrix!DK5 -> RED | F22: =Matrix!DL5 -> 66 | G22: =Matrix!DM5 -> 0
A23: =Matrix!A6 -> Nathan Thomas | B23: =Matrix!DH6 -> 34 | C23: =Matrix!DI6 -> 110 | D23: =Matrix!DJ6 -> 0.30909091 | E23: =Matrix!DK6 -> RED | F23: =Matrix!DL6 -> 76 | G23: =Matrix!DM6 -> 0
A24: =Matrix!A7 -> Joel Jose | B24: =Matrix!DH7 -> 19 | C24: =Matrix!DI7 -> 110 | D24: =Matrix!DJ7 -> 0.17272727 | E24: =Matrix!DK7 -> RED | F24: =Matrix!DL7 -> 91 | G24: =Matrix!DM7 -> 0
A25: =Matrix!A8 -> Firos Latheef | B25: =Matrix!DH8 -> 27 | C25: =Matrix!DI8 -> 110 | D25: =Matrix!DJ8 -> 0.24545455 | E25: =Matrix!DK8 -> RED | F25: =Matrix!DL8 -> 83 | G25: =Matrix!DM8 -> 0
A26: =Matrix!A9 -> Kathleen Evans | B26: =Matrix!DH9 -> 43 | C26: =Matrix!DI9 -> 110 | D26: =Matrix!DJ9 -> 0.39090909 | E26: =Matrix!DK9 -> RED | F26: =Matrix!DL9 -> 67 | G26: =Matrix!DM9 -> 0
A27: =Matrix!A10 -> Sahil Sahil | B27: =Matrix!DH10 -> 11 | C27: =Matrix!DI10 -> 110 | D27: =Matrix!DJ10 -> 0.1 | E27: =Matrix!DK10 -> RED | F27: =Matrix!DL10 -> 97 | G27: =Matrix!DM10 -> 2
A28: =Matrix!A11 -> Haritha Sasidharan | B28: =Matrix!DH11 -> 45 | C28: =Matrix!DI11 -> 110 | D28: =Matrix!DJ11 -> 0.40909091 | E28: =Matrix!DK11 -> RED | F28: =Matrix!DL11 -> 65 | G28: =Matrix!DM11 -> 0
A29: =Matrix!A12 -> Abhina | B29: =Matrix!DH12 -> 22 | C29: =Matrix!DI12 -> 110 | D29: =Matrix!DJ12 -> 0.2 | E29: =Matrix!DK12 -> RED | F29: =Matrix!DL12 -> 88 | G29: =Matrix!DM12 -> 0
A30: =Matrix!A13 -> Carol (Domestic) | B30: =Matrix!DH13 -> 21 | C30: =Matrix!DI13 -> 110 | D30: =Matrix!DJ13 -> 0.19090909 | E30: =Matrix!DK13 -> RED | F30: =Matrix!DL13 -> 89 | G30: =Matrix!DM13 -> 0
A31: =Matrix!A14 -> Harry | B31: =Matrix!DH14 -> 23 | C31: =Matrix!DI14 -> 110 | D31: =Matrix!DJ14 -> 0.20909091 | E31: =Matrix!DK14 -> RED | F31: =Matrix!DL14 -> 87 | G31: =Matrix!DM14 -> 0
A35: Course Compliance
A36: Course | B36: Completion % | C36: RAG
A37: =Matrix!A19 -> Care Certificate | B37: =Matrix!D19 -> 0.5 | C37: =Matrix!E19 -> RED
A38: =Matrix!A20 -> Food Hygiene | B38: =Matrix!D20 -> 0.66666667 | C38: =Matrix!E20 -> RED
A39: =Matrix!A21 -> Falls Awareness | B39: =Matrix!D21 -> 0.58333333 | C39: =Matrix!E21 -> RED
A40: =Matrix!A22 -> Basic Life Support | B40: =Matrix!D22 -> 0.83333333 | C40: =Matrix!E22 -> GREEN
A41: =Matrix!A23 -> Equality, Diversity, Inclusion | B41: =Matrix!D23 -> 0.58333333 | C41: =Matrix!E23 -> RED
A42: =Matrix!A24 -> PEG Feeding | B42: =Matrix!D24 -> 0.58333333 | C42: =Matrix!E24 -> RED
A43: =Matrix!A25 -> Nutrition and Hydration | B43: =Matrix!D25 -> 0.33333333 | C43: =Matrix!E25 -> RED
A44: =Matrix!A26 -> Duty of Care | B44: =Matrix!D26 -> 0.16666667 | C44: =Matrix!E26 -> RED
A45: =Matrix!A27 -> Health and Safety | B45: =Matrix!D27 -> 0.83333333 | C45: =Matrix!E27 -> GREEN
A46: =Matrix!A28 -> Communication and Record Keeping | B46: =Matrix!D28 -> 0.33333333 | C46: =Matrix!E28 -> RED
A47: =Matrix!A29 -> Risk Assessment | B47: =Matrix!D29 -> 0.25 | C47: =Matrix!E29 -> RED
A48: =Matrix!A30 -> Managing Continence | B48: =Matrix!D30 -> 0.33333333 | C48: =Matrix!E30 -> RED
... A145: =Matrix!A127 -> Food Hygiene in Care | B145: =Matrix!D127 -> 0.083333333 | C145: =Matrix!E127 -> RED

Sheet Workforce Dashboard
A1: People & Workforce Dashboard
A2: This dashboard has been added without changing your existing Training Dashboard. It reads from the new workforce trackers.
A4: Area | B4: Total Records | C4: Completed / Closed | D4: Open / In Progress | E4: Overdue / Red | F4: Compliance % | G4: RAG | H4: Notes
A5: Recruitment | B5: =COUNTIF('Recruitment Matrix'!A5:A29,"?*") -> 0 | C5: =COUNTIF('Recruitment Matrix'!Q5:Q29,"Yes") -> 0 | D5: =COUNTIF('Recruitment Matrix'!Q5:Q29,"In Progress") -> 0 | E5: =COUNTIF('Recruitment Matrix'!U5:U29,"Red") -> 0 | F5: =IFERROR(C5/B5,0) -> 0 | G5: =IF(F5>=0.9,"Green",IF(F5>=0.75,"Amber","Red")) -> Red | H5: Linked to Recruitment Matrix
A6: Induction | B6: =COUNTIF('Induction Employee Register'!E4:E28,"Active") -> 25 | C6: =COUNTIF('Induction Employee Register'!Q4:Q28,"Green") -> 0 | D6: =COUNTIF('Induction Employee Register'!Q4:Q28,"Amber") -> 0 | E6: =COUNTIF('Induction Employee Register'!Q4:Q28,"Red") -> 25 | F6: =IFERROR(AVERAGEIF('Induction Employee Register'!E4:E28,"Active",'Induction Employee Register'!I4:I28),0) -> 0 | G6: =IF(F6>=0.9,"Green",IF(F6>=0.75,"Amber","Red")) -> Red | H6: Linked to Induction Employee Register
A7: Personnel / Staff File | B7: =COUNTIF('Induction Employee Register'!E4:E28,"Active") -> 25 | C7: =COUNTIF('Induction Employee Register'!Q4:Q28,"Green") -> 0 | D7: =COUNTIF('Induction Employee Register'!Q4:Q28,"Amber") -> 0 | E7: =COUNTIF('Induction Employee Register'!Q4:Q28,"Red") -> 25 | F7: =IFERROR(AVERAGEIF('Induction Employee Register'!E4:E28,"Active",'Induction Employee Register'!H4:H28),0) -> 0 | G7: =IF(F7>=0.9,"Green",IF(F7>=0.75,"Amber","Red")) -> Red | H7: Linked to SW001-SW025 staff tabs
A8: DBS | B8: =COUNTIF('Induction Employee Register'!E4:E28,"Active") -> 25 | C8: =COUNTIF('Induction Employee Register'!L4:L28,"Green") -> 0 | D8: =COUNTIF('Induction Employee Register'!L4:L28,"Amber") -> 0 | E8: =COUNTIF('Induction Employee Register'!L4:L28,"Red") -> 0 | F8: =IFERROR(C8/B8,0) -> 0 | G8: =IF(F8>=0.9,"Green",IF(F8>=0.75,"Amber","Red")) -> Red | H8: Linked to staff file DBS Received?
A9: Right to Work | B9: =COUNTIF('Induction Employee Register'!E4:E28,"Active") -> 25 | C9: =COUNTIF('Induction Employee Register'!M4:M28,"Green") -> 0 | D9: =COUNTIF('Induction Employee Register'!M4:M28,"Amber") -> 0 | E9: =COUNTIF('Induction Employee Register'!M4:M28,"Red") -> 0 | F9: =IFERROR(C9/B9,0) -> 0 | G9: =IF(F9>=0.9,"Green",IF(F9>=0.75,"Amber","Red")) -> Red | H9: Linked to staff file RTW Received?
A10: Probation | B10: =COUNTIF('Induction Employee Register'!E4:E28,"Active") -> 25 | C10: =COUNTIF('Induction Employee Register'!N4:N28,"Green") -> 0 | D10: =COUNTIF('Induction Employee Register'!N4:N28,"Amber") -> 0 | E10: =COUNTIF('Induction Employee Register'!N4:N28,"Red") -> 0 | F10: =IFERROR(C10/B10,0) -> 0 | G10: =IF(F10>=0.9,"Green",IF(F10>=0.75,"Amber","Red")) -> Red | H10: Linked to staff file Probation Received?
A11: Sponsorship | B11: =COUNTIF('Induction Employee Register'!W4:W28,"Yes") -> 0 | C11: =COUNTIFS('Induction Employee Register'!W4:W28,"Yes",'Induction Employee Register'!Y4:Y28,"Yes") -> 0 | D11: =COUNTIFS('Induction Employee Register'!W4:W28,"Yes",'Induction Employee Register'!Y4:Y28,"No") -> 0 | E11: =COUNTIFS('Induction Employee Register'!W4:W28,"Yes",'Induction Employee Register'!Y4:Y28,"No") -> 0 | F11: =IFERROR(C11/B11,1) -> 1 | G11: =IF(F11>=0.9,"Green",IF(F11>=0.75,"Amber","Red")) -> Green | H11: Applies only where Sponsorship Required = Yes
A12: Training | B12: =COUNTIF('Induction Employee Register'!E4:E28,"Active") -> 25 | C12: =COUNTIF('Induction Employee Register'!Q4:Q28,"Green") -> 0 | D12: =COUNTIF('Induction Employee Register'!Q4:Q28,"Amber") -> 0 | E12: =COUNTIF('Induction Employee Register'!Q4:Q28,"Red") -> 25 | F12: =IFERROR(AVERAGEIF('Induction Employee Register'!E4:E28,"Active",'Induction Employee Register'!K4:K28),0) -> 0 | G12: =IF(F12>=0.9,"Green",IF(F12>=0.75,"Amber","Red")) -> Red | H12: Linked to existing training dashboard where available
A13: Overall Workforce | B13: =SUM(B5:B12) -> 150 | C13: =SUM(C5:C12) -> 0 | D13: =SUM(D5:D12) -> 0 | E13: =SUM(E5:E12) -> 75 | F13: =IFERROR(AVERAGE(F5:F12),0) -> 0.125 | G13: =IF(F13>=0.9,"Green",IF(F13>=0.75,"Amber","Red")) -> Red | H13: Average of linked compliance areas
A16: Added Workforce Audit Tabs
A17: Recruitment Audit | B17: Added and ready for use
A18: Staff File Audit | B18: Added and ready for use
A19: Training Audit | B19: Added and ready for use
A20: Competency Audit | B20: Added and ready for use
A21: Supervision Audit | B21: Added and ready for use
A22: Observation Audit | B22: Added and ready for use
A23: Appraisal Audit | B23: Added and ready for use

Sheet Workforce Annual Audit Index
A1: Swan Care Home - Workforce Annual Audit Index
A3: Audit Tab | B3: Frequency | C3: Year Covered | D3: Staff Only? | E3: Sponsorship Integrated? | F3: Periods Included | G3: Questions per Period | H3: Notes
A4: Recruitment Audit | B4: Monthly | C4: 2026 | D4: Yes | E4: Yes - Yes/No/N/A | F4: January, February, March, April, May, June, July, August, September, October, November, December | G4: 39 | H4: Full year held in this one tab
A5: Staff File Audit | B5: Quarterly | C5: 2026 | D5: Yes | E5: Yes - Yes/No/N/A | F5: Quarter 1 (Jan-Mar), Quarter 2 (Apr-Jun), Quarter 3 (Jul-Sep), Quarter 4 (Oct-Dec) | G5: 35 | H5: Full year held in this one tab
A6: Training Audit | B6: Monthly | C6: 2026 | D6: Yes | E6: Yes - Yes/No/N/A | F6: January, February, March, April, May, June, July, August, September, October, November, December | G6: 29 | H6: Full year held in this one tab
A7: Induction Audit | B7: Monthly | C7: 2026 | D7: Yes | E7: Yes - Yes/No/N/A | F7: January, February, March, April, May, June, July, August, September, October, November, December | G7: 29 | H7: Full year held in this one tab
A8: Competency Audit | B8: Monthly | C8: 2026 | D8: Yes | E8: Yes - Yes/No/N/A | F8: January, February, March, April, May, June, July, August, September, October, November, December | G8: 27 | H8: Full year held in this one tab
A9: Supervision Audit | B9: Monthly | C9: 2026 | D9: Yes | E9: Yes - Yes/No/N/A | F9: January, February, March, April, May, June, July, August, September, October, November, December | G9: 21 | H9: Full year held in this one tab
A10: Observation Audit | B10: Monthly | C10: 2026 | D10: Yes | E10: Yes - Yes/No/N/A | F10: January, February, March, April, May, June, July, August, September, October, November, December | G10: 21 | H10: Full year held in this one tab
A11: Appraisal Audit | B11: Quarterly | C11: 2026 | D11: Yes | E11: Yes - Yes/No/N/A | F11: Quarter 1 (Jan-Mar), Quarter 2 (Apr-Jun), Quarter 3 (Jul-Sep), Quarter 4 (Oct-Dec) | G11: 19 | H11: Full year held in this one tab
A12: Probation Audit | B12: Monthly | C12: 2026 | D12: Yes | E12: Yes - Yes/No/N/A | F12: January, February, March, April, May, June, July, August, September, October, November, December | G12: 19 | H12: Full year held in this one tab

Sheet Summary
A1: Training Matrix Summary
A3: Total staff | B3: =COUNTA(Matrix!$A$3:$A$14) -> 12
A5: Training Topic | B5: Completion % | C5: Completed / Staff | D5: Notes | AB5: 46155 | BF5: 46157 | DC5: 46155
A6: Safeguarding and Protection of Adults | B6: =Matrix!AB$16 -> 0.83333333 | C6: =Matrix!AB$17 -> 10/12
A7: Fire Safety | B7: =Matrix!BG$16 -> 0.16666667 | C7: =Matrix!BG$17 -> 2/12
A8: Fire Marshal / Fire Warden | B8: =Matrix!DC$16 -> 0.91666667 | C8: =Matrix!DC$17 -> 11/12
A9: Moving and Handling | B9: =Matrix!BF$16 -> 0.91666667 | C9: =Matrix!BF$17 -> 11/12
A10: Basic Life Support | B10: =Matrix!E$16 -> 0.83333333 | C10: =Matrix!E$17 -> 10/12
A11: Infection Control | B11: =Matrix!AK$16 -> 0.75 | C11: =Matrix!AK$17 -> 9/12
A12: Dementia Awareness | B12: =Matrix!AE$16 -> 0.75 | C12: =Matrix!AE$17 -> 9/12
A13: Carol (Domestic) | B13: =Matrix!AQ$16 -> 0.83333333 | C13: =Matrix!AQ$17 -> 10/12
A14: Food Hygiene | B14: =Matrix!C$16 -> 0.66666667 | C14: =Matrix!C$17 -> 8/12
A15: End of Life Care | B15: =Matrix!Q$16 -> 0.91666667 | C15: =Matrix!Q$17 -> 11/12
A16: Diabetes Awareness | B16: =Matrix!AP$16 -> 0.75 | C16: =Matrix!AP$17 -> 9/12
A17: The Oliver McGowan Mandatory Training | B17: =Matrix!O$16 -> 0.66666667 | C17: =Matrix!O$17 -> 8/12
A18: Sepsis | B18: =Matrix!D128 -> 0.083333333 | C18: =Matrix!B128&"/"&Matrix!C128 -> 3/12

Sheet Matrix
A1: Keys | B1: In Progress | C1: Completed | D1: Failed | E1: Expiring Soon | F1: Expired | G1: Not Started
A2: Learner's Name | B2: Care Certificate | C2: Food Hygiene | D2: Falls Awareness | E2: Basic Life Support | F2: Equality, Diversity, Inclusion | G2: PEG Feeding | H2: Nutrition and Hydration | I2: Duty of Care | J2: Health and Safety | K2: Communication and Record Keeping | L2: Risk Assessment | M2: Managing Continence | N2: Constipation Basic Awareness | O2: The Oliver McGowan Mandatory Training | P2: Anxiety | Q2: End of Life Care | R2: Dysphagia | S2: Slips Trips and Falls Awareness | T2: Oral Care | U2: Care Planning | V2: Positive Behaviour Support | W2: Parkinson's | X2: Duty of Candour | Y2: Food Safety Level 3 | Z2: COSHH | AA2: RIDDOR | AB2: Safeguarding and Protection of Adults | AC2: A Care Workers Role | AD2: Recording Information | AE2: Dementia Awareness | AF2: Personal Care | AG2: Behaviours that Challenge | AH2: Person Centred Care | AI2: Pressure Care and Moisture Lesion Awareness | AJ2: Stroke Awareness | AK2: Infection Control | AL2: Bereavement Awareness | AM2: DeChoker | AN2: Continence Promotion | AO2: Catheter Care | AP2: Diabetes Awareness | AQ2: Mental Capacity | AR2: Hand Hygiene | AS2: The Use of PPE | AT2: Wellbeing in the Workplace | AU2: Dignity, Privacy and Respect | AV2: Bullying and Harassment Awareness | AW2: Complaints Handling | AX2: Dignity in Care | AY2: Verification of Death | AZ2: Whistleblowing | BA2: HACCP Awareness | BB2: Communication | BC2: Basic Observations | BD2: Accessible Information | BE2: Bed Rails and Risk Management Awareness | BF2: Moving and Handling | BG2: Fire Safety | BH2: Fire Safety Lite | BI2: First Aid | BJ2: Moving and Handling Lite | BK2: Pressure Area Care | BL2: Professional Boundaries | BM2: Buccal Midazolam | BN2: GDPR 1 | BO2: GDPR 2 | BP2: Induction to Dementia | BQ2: Induction to End of Life Care | BR2: Induction to Mental Health | BS2: Infection Control Lite | BT2: Manual Handling of Objects | BU2: Medication Practice | BV2: Medication Practice Lite | BW2: Motor Neurone Disease | BX2: Multiple Sclerosis | BY2: Sexual Harassment Awareness | BZ2: Information Governance | CA2: Legionnaires Disease | CB2: Lone Working | CC2: Mental Health | CD2: LGBTQ+ Aware for Care | CE2: Epilepsy Awareness | CF2: Emergency First Aid Awareness | CG2: Epilepsy Level 3 | CH2: SALT (Speech And Language Therapy) | CI2: Sensory Impairment Awareness | CJ2: FGM Awareness | CK2: Social Media and Online Privacy | CL2: Stress Awareness | CM2: Stoma Care Awareness | CN2: Allergen Awareness | CO2: Concussion Awareness | CP2: Coronavirus Awareness and Infection Control | CQ2: Disability Awareness | CR2: Information Governance and Data Security | CS2: Internet Safety Awareness | CT2: Interview Skills | CU2: Introduction to Sepsis | CV2: Managing People Awareness | CW2: Moving and Handling of People Awareness Level 2 | CX2: Multiple Sclerosis (MS) | CY2: Palliative and End of Life Care | CZ2: Safeguarding of Adults Level 3 CSTF Aligned | DA2: Bowel Care and Management | DB2: Fluids and Nutrition | DC2: Fire Marshal / Fire Warden | DD2: UK GDPR and Information Sharing | DE2: Working in Person Centred Way | DF2: Food Hygiene in Care | DG2: Sepsis | DH2: Completed Count | DI2: Total Courses | DJ2: Compliance % | DK2: RAG | DL2: Missing / Not Started | DM2: In Progress
A3: Niranjala Dissanayake | B3: 46197 | C3: NS | D3: 46196 | E3: 46197 | F3: 46195 | G3: 46196 | H3: 46197 | I3: 46197 | J3: 46197 | K3: 23/06/2026 | L3: NS | M3: NS | N3: NS | O3: NS | P3: 46196 | Q3: 46194 | R3: 46194 | S3: NS | T3: 46193 | U3: 46193 | V3: 46196 | W3: 46196 | X3: NS | Y3: NS | Z3: 46194 | AA3: 46195 | AB3: 13/04/2026 | AC3: 46193 | AD3: 46196 | AE3: 46194 | AF3: 46195 | AG3: NS | AH3: NS | AI3: 22/06/2026 | AJ3: NS | AK3: 46195 | AL3: NS | AM3: NS | AN3: NS | AO3: NS | AP3: 46194 | AQ3: NS | AR3: NS | AS3: NS | AT3: NS | AU3: NS | AV3: NS | AW3: NS | AX3: NS | AY3: NS | AZ3: NS | BA3: NS | BB3: NS | BC3: NS | BD3: NS | BE3: NS | BF3: 13/04/2026 | BG3: NS | BH3: NS | BI3: NS | BJ3: NS | BK3: 46195 | BL3: NS | BM3: NS | BN3: NS | BO3: NS | BP3: NS | BQ3: NS | BR3: NS | BS3: NS | BT3: NS | BU3: NS | BV3: NS | BW3: NS | BX3: NS | BY3: NS | BZ3: NS | CA3: NS | CB3: NS | CC3: NS | CD3: NS | CE3: NS | CF3: NS | CG3: NS | CH3: NS | CI3: NS | CJ3: NS | CK3: NS | CL3: NS | CM3: NS | CN3: NS | CO3: NS | CP3: NS | CQ3: NS | CR3: NS | CS3: NS | CT3: NS | CU3: NS | CV3: NS | CW3: NS | CX3: NS | CY3: NS | CZ3: NS | DA3: NS | DB3: NS | DC3: 13/04/2026 | DD3: NS | DE3: NS | DF3: NS | DG3: 22/06/2026 | DH3: =SUMPRODUCT(--ISNUMBER(B3:DG3))+COUNTIF(B3:DG3,"??/??/????") -> 30 | DI3: =COLUMNS(B3:DG3) -> 110 | DJ3: =IFERROR(DH3/DI3,0) -> 0.27272727 | DK3: =IF(DJ3>=0.95,"GREEN",IF(DJ3>=0.8,"AMBER","RED")) -> RED | DL3: =COUNTIF(B3:DG3,"NS") -> 80 | DM3: =COUNTIF(B3:DG3,"IP") -> 0
A4: Chelsee Booth | B4: 46198 | C4: IP | D4: 46197 | E4: NS | F4: 46197 | G4: 46197 | H4: NS | I4: NS | J4: 46194 | K4: NS | L4: NS | M4: NS | N4: NS | O4: 46201 | P4: NS | Q4: 46195 | R4: 46195 | S4: NS | T4: 46194 | U4: 46194 | V4: 46198 | W4: NS | X4: 46195 | Y4: 46198 | Z4: NS | AA4: NS | AB4: NS | AC4: NS | AD4: NS | AE4: 46195 | AF4: 46199 | AG4: NS | AH4: NS | AI4: NS | AJ4: NS | AK4: NS | AL4: NS | AM4: NS | AN4: 46194 | AO4: NS | AP4: NS | AQ4: 46192 | AR4: NS | AS4: NS | AT4: NS | AU4: NS | AV4: NS | AW4: NS | AX4: NS | AY4: NS | AZ4: NS | BA4: NS | BB4: NS | BC4: NS | BD4: NS | BE4: NS | BF4: 13/04/2026 | BG4: NS | BH4: NS | BI4: NS | BJ4: NS | BK4: NS | BL4: NS | BM4: NS | BN4: NS | BO4: NS | BP4: NS | BQ4: NS | BR4: NS | BS4: NS | BT4: NS | BU4: NS | BV4: NS | BW4: NS | BX4: NS | BY4: NS | BZ4: NS | CA4: NS | CB4: NS | CC4: NS | CD4: NS | CE4: NS | CF4: NS | CG4: NS | CH4: NS | CI4: NS | CJ4: NS | CK4: NS | CL4: NS | CM4: NS | CN4: NS | CO4: NS | CP4: NS | CQ4: NS | CR4: NS | CS4: NS | CT4: NS | CU4: NS | CV4: NS | CW4: NS | CX4: NS | CY4: NS | CZ4: NS | DA4: NS | DB4: NS | DC4: 13/04/2026 | DD4: NS | DE4: NS | DF4: NS | DG4: NS | DH4: =SUMPRODUCT(--ISNUMBER(B4:DG4))+COUNTIF(B4:DG4,"??/??/????") -> 19 | DI4: =COLUMNS(B4:DG4) -> 110 | DJ4: =IFERROR(DH4/DI4,0) -> 0.17272727 | DK4: =IF(DJ4>=0.95,"GREEN",IF(DJ4>=0.8,"AMBER","RED")) -> RED | DL4: =COUNTIF(B4:DG4,"NS") -> 90 | DM4: =COUNTIF(B4:DG4,"IP") -> 1
A5: Paula Merry | B5: NS | C5: 21/06/2026 | D5: 46193 | E5: 46192 | F5: 46193 | G5: 46195 | H5: 46195 | I5: NS | J5: 46194 | K5: 19/06/2026 | L5: 46196 | M5: 46196 | N5: 46196 | O5: 46196 | P5: NS | Q5: 46194 | R5: 46194 | S5: NS | T5: 46194 | U5: 46192 | V5: 46195 | W5: NS | X5: 46192 | Y5: 46194 | Z5: 46193 | AA5: NS | AB5: 46155 | AC5: 46191 | AD5: 46195 | AE5: 46194 | AF5: 46195 | AG5: 46194 | AH5: 46195 | AI5: NS | AJ5: NS | AK5: 46199 | AL5: 46194 | AM5: 46193 | AN5: NS | AO5: NS | AP5: 46194 | AQ5: 46194 | AR5: NS | AS5: NS | AT5: NS | AU5: 46193 | AV5: 46193 | AW5: 46193 | AX5: 46192 | AY5: NS | AZ5: 46192 | BA5: NS | BB5: 46192 | BC5: 46192 | BD5: 46192 | BE5: 46192 | BF5: 46157 | BG5: NS | BH5: 46200 | BI5: NS | BJ5: NS | BK5: NS | BL5: NS | BM5: NS | BN5: NS | BO5: NS | BP5: NS | BQ5: NS | BR5: NS | BS5: NS | BT5: NS | BU5: NS | BV5: NS | BW5: NS | BX5: NS | BY5: NS | BZ5: NS | CA5: NS | CB5: NS | CC5: NS | CD5: NS | CE5: NS | CF5: NS | CG5: NS | CH5: NS | CI5: NS | CJ5: NS | CK5: NS | CL5: NS | CM5: NS | CN5: NS | CO5: NS | CP5: NS | CQ5: NS | CR5: NS | CS5: NS | CT5: NS | CU5: NS | CV5: NS | CW5: NS | CX5: NS | CY5: NS | CZ5: NS | DA5: NS | DB5: NS | DC5: 46155 | DD5: NS | DE5: NS | DF5: NS | DG5: NS | DH5: =SUMPRODUCT(--ISNUMBER(B5:DG5))+COUNTIF(B5:DG5,"??/??/????") -> 44 | DI5: =COLUMNS(B5:DG5) -> 110 | DJ5: =IFERROR(DH5/DI5,0) -> 0.4 | DK5: =IF(DJ5>=0.95,"GREEN",IF(DJ5>=0.8,"AMBER","RED")) -> RED | DL5: =COUNTIF(B5:DG5,"NS") -> 66 | DM5: =COUNTIF(B5:DG5,"IP") -> 0
A6: Nathan Thomas | B6: 46196 | C6: 21/06/2026 | D6: 46199 | E6: 46184 | F6: 46194 | G6: 46199 | H6: 46195 | I6: NS | J6: NS | K6: NS | L6: NS | M6: 46199 | N6: NS | O6: 46195 | P6: NS | Q6: 46196 | R6: 46196 | S6: 46199 | T6: 46195 | U6: 46196 | V6: 46199 | W6: NS | X6: NS | Y6: 46194 | Z6: NS | AA6: NS | AB6: 46195 | AC6: 46195 | AD6: NS | AE6: NS | AF6: 46199 | AG6: 46195 | AH6: NS | AI6: NS | AJ6: NS | AK6: NS | AL6: 46194 | AM6: NS | AN6: NS | AO6: NS | AP6: NS | AQ6: 31/01/2025 | AR6: NS | AS6: 46199 | AT6: NS | AU6: 46199 | AV6: 46199 | AW6: NS | AX6: NS | AY6: 46199 | AZ6: 46199 | BA6: NS | BB6: NS | BC6: 46199 | BD6: NS | BE6: 46199 | BF6: 13/04/2026 | BG6: NS | BH6: NS | BI6: NS | BJ6: NS | BK6: 46199 | BL6: NS | BM6: NS | BN6: NS | BO6: NS | BP6: NS | BQ6: NS | BR6: NS | BS6: NS | BT6: NS | BU6: NS | BV6: NS | BW6: NS | BX6: NS | BY6: NS | BZ6: NS | CA6: NS | CB6: NS | CC6: NS | CD6: NS | CE6: NS | CF6: NS | CG6: NS | CH6: NS | CI6: NS | CJ6: NS | CK6: NS | CL6: NS | CM6: NS | CN6: NS | CO6: NS | CP6: NS | CQ6: NS | CR6: NS | CS6: NS | CT6: NS | CU6: 46199 | CV6: NS | CW6: NS | CX6: NS | CY6: NS | CZ6: NS | DA6: NS | DB6: NS | DC6: 13/04/2026 | DD6: NS | DE6: NS | DF6: NS | DG6: 26/06/2026 | DH6: =SUMPRODUCT(--ISNUMBER(B6:DG6))+COUNTIF(B6:DG6,"??/??/????") -> 34 | DI6: =COLUMNS(B6:DG6) -> 110 | DJ6: =IFERROR(DH6/DI6,0) -> 0.30909091 | DK6: =IF(DJ6>=0.95,"GREEN",IF(DJ6>=0.8,"AMBER","RED")) -> RED | DL6: =COUNTIF(B6:DG6,"NS") -> 76 | DM6: =COUNTIF(B6:DG6,"IP") -> 0
A7: Joel Jose | B7: NS | C7: 23/02/2026 | D7: NS | E7: NS | F7: NS | G7: NS | H7: NS | I7: NS | J7: 21/01/2026 | K7: NS | L7: NS | M7: NS | N7: NS | O7: NS | P7: NS | Q7: 11/02/2026 | R7: 21/01/2026 | S7: NS | T7: 06/02/2026 | U7: 46199 | V7: NS | W7: 03/03/2026 | X7: NS | Y7: NS | Z7: NS | AA7: NS | AB7: 45985 | AC7: NS | AD7: NS | AE7: 21/01/2026 | AF7: NS | AG7: 23/02/2026 | AH7: NS | AI7: NS | AJ7: NS | AK7: 45987 | AL7: NS | AM7: NS | AN7: NS | AO7: NS | AP7: 12/02/2026 | AQ7: 20/01/2026 | AR7: NS | AS7: NS | AT7: NS | AU7: NS | AV7: NS | AW7: NS | AX7: NS | AY7: NS | AZ7: NS | BA7: NS | BB7: NS | BC7: NS | BD7: NS | BE7: NS | BF7: 45979 | BG7: NS | BH7: NS | BI7: 03/03/2026 | BJ7: NS | BK7: NS | BL7: NS | BM7: NS | BN7: NS | BO7: NS | BP7: NS | BQ7: NS | BR7: NS | BS7: NS | BT7: NS | BU7: NS | BV7: NS | BW7: NS | BX7: NS | BY7: NS | BZ7: NS | CA7: NS | CB7: NS | CC7: NS | CD7: NS | CE7: NS | CF7: NS | CG7: NS | CH7: NS | CI7: NS | CJ7: NS | CK7: NS | CL7: NS | CM7: NS | CN7: NS | CO7: NS | CP7: NS | CQ7: NS | CR7: NS | CS7: NS | CT7: NS | CU7: NS | CV7: NS | CW7: NS | CX7: NS | CY7: NS | CZ7: NS | DA7: 23/02/2026 | DB7: 23/02/2026 | DC7: 46001 | DD7: NS | DE7: 23/02/2026 | DF7: NS | DG7: NS | DH7: =SUMPRODUCT(--ISNUMBER(B7:DG7))+COUNTIF(B7:DG7,"??/??/????") -> 19 | DI7: =COLUMNS(B7:DG7) -> 110 | DJ7: =IFERROR(DH7/DI7,0) -> 0.17272727 | DK7: =IF(DJ7>=0.95,"GREEN",IF(DJ7>=0.8,"AMBER","RED")) -> RED | DL7: =COUNTIF(B7:DG7,"NS") -> 91 | DM7: =COUNTIF(B7:DG7,"IP") -> 0
A8: Firos Latheef | B8: NS | C8: 22/02/2026 | D8: 46199 | E8: 22/02/2026 | F8: NS | G8: 46201 | H8: NS | I8: NS | J8: 11/02/2026 | K8: NS | L8: NS | M8: 46195 | N8: NS | O8: 22/02/2026 | P8: NS | Q8: 11/02/2026 | R8: 23/01/2026 | S8: NS | T8: 46195 | U8: 46193 | V8: 46194 | W8: 22/02/2026 | X8: NS | Y8: 46195 | Z8: 46195 | AA8: NS | AB8: 45994 | AC8: NS | AD8: NS | AE8: 23/01/2026 | AF8: NS | AG8: NS | AH8: 46200 | AI8: NS | AJ8: NS | AK8: 11/02/2026 | AL8: NS | AM8: NS | AN8: NS | AO8: NS | AP8: 11/02/2026 | AQ8: 23/01/2026 | AR8: NS | AS8: NS | AT8: NS | AU8: NS | AV8: NS | AW8: NS | AX8: NS | AY8: NS | AZ8: NS | BA8: NS | BB8: NS | BC8: NS | BD8: NS | BE8: NS | BF8: 45979 | BG8: NS | BH8: NS | BI8: 22/02/2026 | BJ8: NS | BK8: NS | BL8: NS | BM8: NS | BN8: NS | BO8: NS | BP8: NS | BQ8: NS | BR8: NS | BS8: NS | BT8: NS | BU8: NS | BV8: NS | BW8: NS | BX8: NS | BY8: NS | BZ8: NS | CA8: NS | CB8: NS | CC8: NS | CD8: NS | CE8: NS | CF8: NS | CG8: NS | CH8: NS | CI8: NS | CJ8: NS | CK8: NS | CL8: NS | CM8: NS | CN8: NS | CO8: NS | CP8: NS | CQ8: NS | CR8: NS | CS8: NS | CT8: NS | CU8: NS | CV8: NS | CW8: NS | CX8: NS | CY8: NS | CZ8: NS | DA8: 22/02/2026 | DB8: 22/02/2026 | DC8: 46010 | DD8: 22/02/2026 | DE8: NS | DF8: NS | DG8: NS | DH8: =SUMPRODUCT(--ISNUMBER(B8:DG8))+COUNTIF(B8:DG8,"??/??/????") -> 27 | DI8: =COLUMNS(B8:DG8) -> 110 | DJ8: =IFERROR(DH8/DI8,0) -> 0.24545455 | DK8: =IF(DJ8>=0.95,"GREEN",IF(DJ8>=0.8,"AMBER","RED")) -> RED | DL8: =COUNTIF(B8:DG8,"NS") -> 83 | DM8: =COUNTIF(B8:DG8,"IP") -> 0
A9: Kathleen Evans | B9: NS | C9: 11/02/2026 | D9: 46194 | E9: 11/02/2026 | F9: 46195 | G9: 46193 | H9: NS | I9: NS | J9: 46193 | K9: 21/06/2026 | L9: 46200 | M9: 46193 | N9: NS | O9: 22/02/2026 | P9: NS | Q9: 06/02/2026 | R9: 06/02/2026 | S9: 46199 | T9: 06/02/2026 | U9: 46193 | V9: NS | W9: 11/02/2026 | X9: 46193 | Y9: NS | Z9: 09/02/2026 | AA9: 46195 | AB9: 13/07/2024 | AC9: NS | AD9: 46194 | AE9: 09/02/2026 | AF9: 46194 | AG9: 46193 | AH9: NS | AI9: 21/06/2026 | AJ9: 46195 | AK9: 45987 | AL9: 46200 | AM9: NS | AN9: NS | AO9: NS | AP9: 06/02/2026 | AQ9: 09/02/2026 | AR9: 46194 | AS9: 46194 | AT9: NS | AU9: NS | AV9: NS | AW9: NS | AX9: NS | AY9: NS | AZ9: NS | BA9: NS | BB9: NS | BC9: NS | BD9: NS | BE9: NS | BF9: 45979 | BG9: NS | BH9: NS | BI9: 06/03/2025 | BJ9: NS | BK9: 46194 | BL9: NS | BM9: NS | BN9: NS | BO9: NS | BP9: NS | BQ9: NS | BR9: NS | BS9: NS | BT9: NS | BU9: 45981 | BV9: NS | BW9: NS | BX9: NS | BY9: NS | BZ9: NS | CA9: NS | CB9: NS | CC9: NS | CD9: NS | CE9: NS | CF9: NS | CG9: NS | CH9: NS | CI9: NS | CJ9: NS | CK9: NS | CL9: NS | CM9: NS | CN9: 13/02/2026 | CO9: NS | CP9: NS | CQ9: NS | CR9: NS | CS9: NS | CT9: NS | CU9: NS | CV9: NS | CW9: NS | CX9: NS | CY9: NS | CZ9: NS | DA9: 11/02/2026 | DB9: 11/02/2026 | DC9: 46001 | DD9: 11/02/2026 | DE9: 11/02/2026 | DF9: NS | DG9: 20/06/2026 | DH9: =SUMPRODUCT(--ISNUMBER(B9:DG9))+COUNTIF(B9:DG9,"??/??/????") -> 43 | DI9: =COLUMNS(B9:DG9) -> 110 | DJ9: =IFERROR(DH9/DI9,0) -> 0.39090909 | DK9: =IF(DJ9>=0.95,"GREEN",IF(DJ9>=0.8,"AMBER","RED")) -> RED | DL9: =COUNTIF(B9:DG9,"NS") -> 67 | DM9: =COUNTIF(B9:DG9,"IP") -> 0
A10: Sahil Sahil | B10: 30/01/2026 | C10: NS | D10: NS | E10: 46192 | F10: NS | G10: NS | H10: NS | I10: NS | J10: NS | K10: NS | L10: NS | M10: NS | N10: NS | O10: IP | P10: NS | Q10: NS | R10: NS | S10: 46192 | T10: NS | U10: IP | V10: NS | W10: NS | X10: NS | Y10: NS | Z10: NS | AA10: NS | AB10: NS | AC10: NS | AD10: NS | AE10: NS | AF10: NS | AG10: 46192 | AH10: NS | AI10: NS | AJ10: NS | AK10: NS | AL10: NS | AM10: 46194 | AN10: NS | AO10: 46194 | AP10: NS | AQ10: NS | AR10: NS | AS10: NS | AT10: 46194 | AU10: NS | AV10: NS | AW10: NS | AX10: NS | AY10: 46192 | AZ10: 46192 | BA10: 46192 | BB10: NS | BC10: NS | BD10: NS | BE10: NS | BF10: NS | BG10: NS | BH10: NS | BI10: NS | BJ10: NS | BK10: NS | BL10: NS | BM10: NS | BN10: NS | BO10: NS | BP10: NS | BQ10: NS | BR10: NS | BS10: NS | BT10: NS | BU10: 19/04/2026 | BV10: NS | BW10: NS | BX10: NS | BY10: NS | BZ10: NS | CA10: NS | CB10: NS | CC10: NS | CD10: NS | CE10: NS | CF10: NS | CG10: NS | CH10: NS | CI10: NS | CJ10: NS | CK10: NS | CL10: NS | CM10: NS | CN10: NS | CO10: NS | CP10: NS | CQ10: NS | CR10: NS | CS10: NS | CT10: NS | CU10: NS | CV10: NS | CW10: NS | CX10: NS | CY10: NS | CZ10: NS | DA10: NS | DB10: NS | DC10: NS | DD10: NS | DE10: NS | DF10: NS | DG10: NS | DH10: =SUMPRODUCT(--ISNUMBER(B10:DG10))+COUNTIF(B10:DG10,"??/??/????") -> 11 | DI10: =COLUMNS(B10:DG10) -> 110 | DJ10: =IFERROR(DH10/DI10,0) -> 0.1 | DK10: =IF(DJ10>=0.95,"GREEN",IF(DJ10>=0.8,"AMBER","RED")) -> RED | DL10: =COUNTIF(B10:DG10,"NS") -> 97 | DM10: =COUNTIF(B10:DG10,"IP") -> 2
A11: Haritha Sasidharan | B11: 05/10/2025 | C11: 45228 | D11: 28/10/2023 | E11: 46193 | F11: 45227 | G11: 46194 | H11: 45228 | I11: 46193 | J11: 29/10/2023 | K11: 46076 | L11: 20/06/2026 | M11: NS | N11: NS | O11: 23/02/2026 | P11: NS | Q11: 46061 | R11: 20/01/2026 | S11: NS | T11: 07/02/2026 | U11: 16/01/2026 | V11: NS | W11: 23/02/2026 | X11: NS | Y11: NS | Z11: NS | AA11: NS | AB11: 45994 | AC11: NS | AD11: 46076 | AE11: 45228 | AF11: NS | AG11: 46193 | AH11: 46076 | AI11: NS | AJ11: 20/06/2026 | AK11: 45987 | AL11: NS | AM11: NS | AN11: NS | AO11: NS | AP11: 20/06/2026 | AQ11: 46193 | AR11: NS | AS11: NS | AT11: NS | AU11: NS | AV11: NS | AW11: NS | AX11: NS | AY11: NS | AZ11: NS | BA11: NS | BB11: NS | BC11: NS | BD11: NS | BE11: NS | BF11: 45979 | BG11: NS | BH11: NS | BI11: 46193 | BJ11: NS | BK11: NS | BL11: NS | BM11: NS | BN11: 45228 | BO11: 45228 | BP11: 45228 | BQ11: 46061 | BR11: NS | BS11: 45895 | BT11: NS | BU11: 45981 | BV11: NS | BW11: NS | BX11: NS | BY11: NS | BZ11: 45228 | CA11: NS | CB11: NS | CC11: NS | CD11: NS | CE11: NS | CF11: 46194 | CG11: NS | CH11: NS | CI11: NS | CJ11: NS | CK11: NS | CL11: NS | CM11: NS | CN11: NS | CO11: NS | CP11: NS | CQ11: NS | CR11: 45228 | CS11: NS | CT11: NS | CU11: NS | CV11: NS | CW11: NS | CX11: NS | CY11: 46061 | CZ11: 45894 | DA11: 23/02/2026 | DB11: 45228 | DC11: 46001 | DD11: 45228 | DE11: 46076 | DF11: 45228 | DG11: NS | DH11: =SUMPRODUCT(--ISNUMBER(B11:DG11))+COUNTIF(B11:DG11,"??/??/????") -> 45 | DI11: =COLUMNS(B11:DG11) -> 110 | DJ11: =IFERROR(DH11/DI11,0) -> 0.40909091 | DK11: =IF(DJ11>=0.95,"GREEN",IF(DJ11>=0.8,"AMBER","RED")) -> RED | DL11: =COUNTIF(B11:DG11,"NS") -> 65 | DM11: =COUNTIF(B11:DG11,"IP") -> 0
A12: Abhina | B12: NS | C12: 29/09/2025 | D12: NS | E12: 29/09/2025 | F12: NS | G12: NS | H12: NS | I12: NS | J12: 20/01/2026 | K12: NS | L12: NS | M12: NS | N12: NS | O12: 18/02/2026 | P12: NS | Q12: 07/02/2026 | R12: 20/01/2026 | S12: NS | T12: 07/02/2026 | U12: NS | V12: NS | W12: 17/02/2026 | X12: NS | Y12: NS | Z12: NS | AA12: NS | AB12: 45985 | AC12: NS | AD12: NS | AE12: 20/01/2026 | AF12: NS | AG12: NS | AH12: NS | AI12: NS | AJ12: NS | AK12: 45987 | AL12: NS | AM12: NS | AN12: NS | AO12: NS | AP12: 07/02/2026 | AQ12: 27/09/2025 | AR12: NS | AS12: NS | AT12: NS | AU12: NS | AV12: NS | AW12: NS | AX12: NS | AY12: NS | AZ12: NS | BA12: NS | BB12: NS | BC12: NS | BD12: NS | BE12: NS | BF12: 45979 | BG12: 26/09/2025 | BH12: NS | BI12: 26/09/2025 | BJ12: NS | BK12: NS | BL12: NS | BM12: NS | BN12: NS | BO12: NS | BP12: NS | BQ12: NS | BR12: NS | BS12: NS | BT12: NS | BU12: 45981 | BV12: NS | BW12: NS | BX12: NS | BY12: NS | BZ12: NS | CA12: NS | CB12: NS | CC12: NS | CD12: NS | CE12: NS | CF12: NS | CG12: NS | CH12: NS | CI12: NS | CJ12: NS | CK12: NS | CL12: NS | CM12: NS | CN12: NS | CO12: NS | CP12: NS | CQ12: NS | CR12: NS | CS12: NS | CT12: NS | CU12: NS | CV12: NS | CW12: NS | CX12: NS | CY12: NS | CZ12: NS | DA12: 16/02/2026 | DB12: 16/02/2026 | DC12: 05/12/2025 | DD12: 16/02/2026 | DE12: 17/02/2026 | DF12: NS | DG12: NS | DH12: =SUMPRODUCT(--ISNUMBER(B12:DG12))+COUNTIF(B12:DG12,"??/??/????") -> 22 | DI12: =COLUMNS(B12:DG12) -> 110 | DJ12: =IFERROR(DH12/DI12,0) -> 0.2 | DK12: =IF(DJ12>=0.95,"GREEN",IF(DJ12>=0.8,"AMBER","RED")) -> RED | DL12: =COUNTIF(B12:DG12,"NS") -> 88 | DM12: =COUNTIF(B12:DG12,"IP") -> 0
A13: Carol (Domestic) | B13: NS | C13: NS | D13: NS | E13: 11/02/2026 | F13: 15/07/2024 | G13: NS | H13: NS | I13: NS | J13: 06/02/2026 | K13: NS | L13: NS | M13: NS | N13: NS | O13: NS | P13: NS | Q13: 06/02/2026 | R13: 08/02/2026 | S13: NS | T13: 06/02/2026 | U13: NS | V13: NS | W13: 11/02/2026 | X13: NS | Y13: 05/11/2024 | Z13: 02/02/2026 | AA13: NS | AB13: 45985 | AC13: NS | AD13: NS | AE13: 07/02/2026 | AF13: NS | AG13: 15/02/2026 | AH13: NS | AI13: NS | AJ13: NS | AK13: 45987 | AL13: NS | AM13: NS | AN13: NS | AO13: NS | AP13: 06/02/2026 | AQ13: 26/02/2026 | AR13: NS | AS13: NS | AT13: NS | AU13: NS | AV13: NS | AW13: NS | AX13: NS | AY13: NS | AZ13: NS | BA13: NS | BB13: NS | BC13: NS | BD13: NS | BE13: NS | BF13: 45979 | BG13: NS | BH13: NS | BI13: 26/02/2025 | BJ13: NS | BK13: NS | BL13: NS | BM13: NS | BN13: NS | BO13: NS | BP13: NS | BQ13: NS | BR13: NS | BS13: NS | BT13: NS | BU13: NS | BV13: NS | BW13: NS | BX13: NS | BY13: NS | BZ13: NS | CA13: NS | CB13: NS | CC13: 08/02/2026 | CD13: NS | CE13: NS | CF13: NS | CG13: NS | CH13: NS | CI13: NS | CJ13: NS | CK13: NS | CL13: NS | CM13: NS | CN13: NS | CO13: NS | CP13: NS | CQ13: NS | CR13: NS | CS13: NS | CT13: NS | CU13: NS | CV13: NS | CW13: NS | CX13: NS | CY13: NS | CZ13: NS | DA13: NS | DB13: 11/02/2026 | DC13: 05/12/2025 | DD13: NS | DE13: 11/02/2026 | DF13: NS | DG13: NS | DH13: =SUMPRODUCT(--ISNUMBER(B13:DG13))+COUNTIF(B13:DG13,"??/??/????") -> 21 | DI13: =COLUMNS(B13:DG13) -> 110 | DJ13: =IFERROR(DH13/DI13,0) -> 0.19090909 | DK13: =IF(DJ13>=0.95,"GREEN",IF(DJ13>=0.8,"AMBER","RED")) -> RED | DL13: =COUNTIF(B13:DG13,"NS") -> 89 | DM13: =COUNTIF(B13:DG13,"IP") -> 0
A14: Harry | B14: 20/01/2026 | C14: 12/10/2025 | D14: NS | E14: 25/09/2025 | F14: NS | G14: NS | H14: NS | I14: NS | J14: 20/01/2026 | K14: NS | L14: NS | M14: NS | N14: NS | O14: 18/02/2026 | P14: NS | Q14: 07/02/2026 | R14: 20/01/2026 | S14: NS | T14: 07/02/2026 | U14: NS | V14: NS | W14: 18/02/2026 | X14: NS | Y14: NS | Z14: NS | AA14: NS | AB14: 45985 | AC14: NS | AD14: NS | AE14: NS | AF14: NS | AG14: 20/01/2026 | AH14: NS | AI14: NS | AJ14: NS | AK14: 11/10/2025 | AL14: NS | AM14: NS | AN14: NS | AO14: NS | AP14: 07/02/2026 | AQ14: 03/11/2025 | AR14: NS | AS14: NS | AT14: NS | AU14: NS | AV14: NS | AW14: NS | AX14: NS | AY14: NS | AZ14: NS | BA14: NS | BB14: NS | BC14: NS | BD14: NS | BE14: NS | BF14: 45979 | BG14: 11/10/2025 | BH14: NS | BI14: 07/10/2025 | BJ14: NS | BK14: NS | BL14: NS | BM14: NS | BN14: NS | BO14: NS | BP14: NS | BQ14: NS | BR14: NS | BS14: NS | BT14: NS | BU14: 45981 | BV14: NS | BW14: NS | BX14: NS | BY14: NS | BZ14: NS | CA14: NS | CB14: NS | CC14: NS | CD14: NS | CE14: NS | CF14: NS | CG14: NS | CH14: NS | CI14: NS | CJ14: NS | CK14: NS | CL14: NS | CM14: NS | CN14: NS | CO14: NS | CP14: NS | CQ14: NS | CR14: NS | CS14: NS | CT14: NS | CU14: NS | CV14: NS | CW14: NS | CX14: NS | CY14: NS | CZ14: NS | DA14: 18/02/2026 | DB14: 18/02/2026 | DC14: 46010 | DD14: 17/02/2026 | DE14: 18/02/2026 | DF14: NS | DG14: NS | DH14: =SUMPRODUCT(--ISNUMBER(B14:DG14))+COUNTIF(B14:DG14,"??/??/????") -> 23 | DI14: =COLUMNS(B14:DG14) -> 110 | DJ14: =IFERROR(DH14/DI14,0) -> 0.20909091 | DK14: =IF(DJ14>=0.95,"GREEN",IF(DJ14>=0.8,"AMBER","RED")) -> RED | DL14: =COUNTIF(B14:DG14,"NS") -> 87 | DM14: =COUNTIF(B14:DG14,"IP") -> 0
A16: Completion % by Training Topic | B16: =IFERROR(COUNTIFS(B$3:B$14,"<>NS",B$3:B$14,"<>IP",B$3:B$14,"<>",B$3:B$14,"<>Failed",B$3:B$14,"<>F")/COUNTA($A$3:$A$14),0) -> 0.5 | C16: =IFERROR(COUNTIFS(C$3:C$14,"<>NS",C$3:C$14,"<>IP",C$3:C$14,"<>",C$3:C$14,"<>Failed",C$3:C$14,"<>F")/COUNTA($A$3:$A$14),0) -> 0.66666667 | D16: =IFERROR(COUNTIFS(D$3:D$14,"<>NS",D$3:D$14,"<>IP",D$3:D$14,"<>",D$3:D$14,"<>Failed",D$3:D$14,"<>F")/COUNTA($A$3:$A$14),0) -> 0.58333333 | E16: =IFERROR(COUNTIFS(E$3:E$14,"<>NS",E$3:E$14,"<>IP",E$3:E$14,"<>",E$3:E$14,"<>Failed",E$3:E$14,"<>F")/COUNTA($A$3:$A$14),0) -> 0.83333333 | F16: =IFERROR(COUNTIFS(F$3:F$14,"<>NS",F$3:F$14,"<>IP",F$3:F$14,"<>",F$3:F$14,"<>Failed",F$3:F$14,"<>F")/COUNTA($A$3:$A$14),0) -> 0.58333333 | G16: =IFERROR(COUNTIFS(G$3:G$14,"<>NS",G$3:G$14,"<>IP",G$3:G$14,"<>",G$3:G$14,"<>Failed",G$3:G$14,"<>F")/COUNTA($A$3:$A$14),0) -> 0.58333333 | H16: =IFERROR(COUNTIFS(H$3:H$14,"<>NS",H$3:H$14,"<>IP",H$3:H$14,"<>",H$3:H$14,"<>Failed",H$3:H$14,"<>F")/COUNTA($A$3:$A$14),0) -> 0.33333333 | I16: =IFERROR(COUNTIFS(I$3:I$14,"<>NS",I$3:I$14,"<>IP",I$3:I$14,"<>",I$3:I$14,"<>Failed",I$3:I$14,"<>F")/COUNTA($A$3:$A$14),0) -> 0.16666667 | ... DF16: =IFERROR(COUNTIFS(DF$3:DF$14,"<>NS",DF$3:DF$14,"<>IP",DF$3:DF$14,"<>",DF$3:DF$14,"<>Failed",DF$3:DF$14,"<>F")/COUNTA($A$3:$A$14),0) -> 0.083333333
A17: Course Compliance Summary | B17: =COUNTIFS(B$3:B$14,"<>NS",B$3:B$14,"<>IP",B$3:B$14,"<>",B$3:B$14,"<>Failed",B$3:B$14,"<>F")&"/"&COUNTA($A$3:$A$14) -> 6/12 | C17: =COUNTIFS(C$3:C$14,"<>NS",C$3:C$14,"<>IP",C$3:C$14,"<>",C$3:C$14,"<>Failed",C$3:C$14,"<>F")&"/"&COUNTA($A$3:$A$14) -> 8/12 | D17: =COUNTIFS(D$3:D$14,"<>NS",D$3:D$14,"<>IP",D$3:D$14,"<>",D$3:D$14,"<>Failed",D$3:D$14,"<>F")&"/"&COUNTA($A$3:$A$14) -> 7/12 | E17: =COUNTIFS(E$3:E$14,"<>NS",E$3:E$14,"<>IP",E$3:E$14,"<>",E$3:E$14,"<>Failed",E$3:E$14,"<>F")&"/"&COUNTA($A$3:$A$14) -> 10/12 | F17: =COUNTIFS(F$3:F$14,"<>NS",F$3:F$14,"<>IP",F$3:F$14,"<>",F$3:F$14,"<>Failed",F$3:F$14,"<>F")&"/"&COUNTA($A$3:$A$14) -> 7/12 | G17: =COUNTIFS(G$3:G$14,"<>NS",G$3:G$14,"<>IP",G$3:G$14,"<>",G$3:G$14,"<>Failed",G$3:G$14,"<>F")&"/"&COUNTA($A$3:$A$14) -> 7/12 | H17: =COUNTIFS(H$3:H$14,"<>NS",H$3:H$14,"<>IP",H$3:H$14,"<>",H$3:H$14,"<>Failed",H$3:H$14,"<>F")&"/"&COUNTA($A$3:$A$14) -> 4/12 | I17: =COUNTIFS(I$3:I$14,"<>NS",I$3:I$14,"<>IP",I$3:I$14,"<>",I$3:I$14,"<>Failed",I$3:I$14,"<>F")&"/"&COUNTA($A$3:$A$14) -> 2/12 | ... DF17: =COUNTIFS(DF$3:DF$14,"<>NS",DF$3:DF$14,"<>IP",DF$3:DF$14,"<>",DF$3:DF$14,"<>Failed",DF$3:DF$14,"<>F")&"/"&COUNTA($A$3:$A$14) -> 1/12
A18: Course | B18: Completed | C18: Total Staff | D18: Completion % | E18: RAG
A19: Care Certificate | B19: {=SUMPRODUCT(--ISNUMBER(INDEX($B$3:$ZZ$14,0,ROWS($A$1:A1))))+COUNTIF(INDEX($B$3:$ZZ$14,0,ROWS($A$1:A1)),"??/??/????")} -> 6 | C19: 12 | D19: =IF(C19=0,"",B19/C19) -> 0.5 | E19: =IF(D19="","",IF(D19>=0.8,"GREEN",IF(D19>=0.7,"AMBER","RED"))) -> RED
A20: Food Hygiene | B20: {=SUMPRODUCT(--ISNUMBER(INDEX($B$3:$ZZ$14,0,ROWS($A$1:A2))))+COUNTIF(INDEX($B$3:$ZZ$14,0,ROWS($A$1:A2)),"??/??/????")} -> 8 | C20: 12 | D20: =IF(C20=0,"",B20/C20) -> 0.66666667 | E20: =IF(D20="","",IF(D20>=0.8,"GREEN",IF(D20>=0.7,"AMBER","RED"))) -> RED
A21: Falls Awareness | B21: {=SUMPRODUCT(--ISNUMBER(INDEX($B$3:$ZZ$14,0,ROWS($A$1:A3))))+COUNTIF(INDEX($B$3:$ZZ$14,0,ROWS($A$1:A3)),"??/??/????")} -> 7 | C21: 12 | D21: =IF(C21=0,"",B21/C21) -> 0.58333333 | E21: =IF(D21="","",IF(D21>=0.8,"GREEN",IF(D21>=0.7,"AMBER","RED"))) -> RED
A22: Basic Life Support | B22: {=SUMPRODUCT(--ISNUMBER(INDEX($B$3:$ZZ$14,0,ROWS($A$1:A4))))+COUNTIF(INDEX($B$3:$ZZ$14,0,ROWS($A$1:A4)),"??/??/????")} -> 10 | C22: 12 | D22: =IF(C22=0,"",B22/C22) -> 0.83333333 | E22: =IF(D22="","",IF(D22>=0.8,"GREEN",IF(D22>=0.7,"AMBER","RED"))) -> GREEN
A23: Equality, Diversity, Inclusion | B23: {=SUMPRODUCT(--ISNUMBER(INDEX($B$3:$ZZ$14,0,ROWS($A$1:A5))))+COUNTIF(INDEX($B$3:$ZZ$14,0,ROWS($A$1:A5)),"??/??/????")} -> 7 | C23: 12 | D23: =IF(C23=0,"",B23/C23) -> 0.58333333 | E23: =IF(D23="","",IF(D23>=0.8,"GREEN",IF(D23>=0.7,"AMBER","RED"))) -> RED
A24: PEG Feeding | B24: {=SUMPRODUCT(--ISNUMBER(INDEX($B$3:$ZZ$14,0,ROWS($A$1:A6))))+COUNTIF(INDEX($B$3:$ZZ$14,0,ROWS($A$1:A6)),"??/??/????")} -> 7 | C24: 12 | D24: =IF(C24=0,"",B24/C24) -> 0.58333333 | E24: =IF(D24="","",IF(D24>=0.8,"GREEN",IF(D24>=0.7,"AMBER","RED"))) -> RED
A25: Nutrition and Hydration | B25: {=SUMPRODUCT(--ISNUMBER(INDEX($B$3:$ZZ$14,0,ROWS($A$1:A7))))+COUNTIF(INDEX($B$3:$ZZ$14,0,ROWS($A$1:A7)),"??/??/????")} -> 4 | C25: 12 | D25: =IF(C25=0,"",B25/C25) -> 0.33333333 | E25: =IF(D25="","",IF(D25>=0.8,"GREEN",IF(D25>=0.7,"AMBER","RED"))) -> RED
A26: Duty of Care | B26: {=SUMPRODUCT(--ISNUMBER(INDEX($B$3:$ZZ$14,0,ROWS($A$1:A8))))+COUNTIF(INDEX($B$3:$ZZ$14,0,ROWS($A$1:A8)),"??/??/????")} -> 2 | C26: 12 | D26: =IF(C26=0,"",B26/C26) -> 0.16666667 | E26: =IF(D26="","",IF(D26>=0.8,"GREEN",IF(D26>=0.7,"AMBER","RED"))) -> RED
A27: Health and Safety | B27: {=SUMPRODUCT(--ISNUMBER(INDEX($B$3:$ZZ$14,0,ROWS($A$1:A9))))+COUNTIF(INDEX($B$3:$ZZ$14,0,ROWS($A$1:A9)),"??/??/????")} -> 10 | C27: 12 | D27: =IF(C27=0,"",B27/C27) -> 0.83333333 | E27: =IF(D27="","",IF(D27>=0.8,"GREEN",IF(D27>=0.7,"AMBER","RED"))) -> GREEN
A28: Communication and Record Keeping | B28: {=SUMPRODUCT(--ISNUMBER(INDEX($B$3:$ZZ$14,0,ROWS($A$1:A10))))+COUNTIF(INDEX($B$3:$ZZ$14,0,ROWS($A$1:A10)),"??/??/????")} -> 4 | C28: 12 | D28: =IF(C28=0,"",B28/C28) -> 0.33333333 | E28: =IF(D28="","",IF(D28>=0.8,"GREEN",IF(D28>=0.7,"AMBER","RED"))) -> RED
A29: Risk Assessment | B29: {=SUMPRODUCT(--ISNUMBER(INDEX($B$3:$ZZ$14,0,ROWS($A$1:A11))))+COUNTIF(INDEX($B$3:$ZZ$14,0,ROWS($A$1:A11)),"??/??/????")} -> 3 | C29: 12 | D29: =IF(C29=0,"",B29/C29) -> 0.25 | E29: =IF(D29="","",IF(D29>=0.8,"GREEN",IF(D29>=0.7,"AMBER","RED"))) -> RED
A30: Managing Continence | B30: {=SUMPRODUCT(--ISNUMBER(INDEX($B$3:$ZZ$14,0,ROWS($A$1:A12))))+COUNTIF(INDEX($B$3:$ZZ$14,0,ROWS($A$1:A12)),"??/??/????")} -> 4 | C30: 12 | D30: =IF(C30=0,"",B30/C30) -> 0.33333333 | E30: =IF(D30="","",IF(D30>=0.8,"GREEN",IF(D30>=0.7,"AMBER","RED"))) -> RED
... A127: Food Hygiene in Care | B127: {=SUMPRODUCT(--ISNUMBER(INDEX($B$3:$ZZ$14,0,ROWS($A$1:A109))))+COUNTIF(INDEX($B$3:$ZZ$14,0,ROWS($A$1:A109)),"??/??/????")} -> 1 | C127: 12 | D127: =IF(C127=0,"",B127/C127) -> 0.083333333 | E127: =IF(D127="","",IF(D127>=0.8,"GREEN",IF(D127>=0.7,"AMBER","RED"))) -> RED
A128: Introduction to Sepsis | B128: {=SUMPRODUCT(--ISNUMBER(INDEX($B$3:$ZZ$14,0,ROWS($A$1:A110))))+COUNTIF(INDEX($B$3:$ZZ$14,0,ROWS($A$1:A110)),"??/??/????")} -> 3 | C128: 12 | D128: 0.083333333 | E128: =IF(D128="","",IF(D128>=0.8,"GREEN",IF(D128>=0.7,"AMBER","RED"))) -> RED

Sheet Keys
A1: Key | B1: Description
A2: In Progress | B2: Training session that has been started but are not completed
A3: Completed | B3: Date of when the last training session was completed and is still current
A4: Failed | B4: Date of latest training session where the test attempt failed
A5: Expiring Soon | B5: Date of completed training session that will expire in the next 30 days
A6: Expired | B6: Date the training session expired
A7: Not Started | B7: Enrolled in a training session but has not started

Sheet Completed Results
A1: Staff Name | B1: Course | C1: Completion Date | D1: Previous Matrix Value | E1: Import Note
A2: Firos Latheef | B2: PEG Feeding | C2: 46201 | D2: NS
A3: Firos Latheef | B3: Person Centred Care | C3: 46200 | D3: NS
A4: Firos Latheef | B4: Care Planning | C4: 46193 | D4: 20/06/2026
A5: Firos Latheef | B5: Falls Awareness | C5: 46199 | D5: NS
A6: Firos Latheef | B6: Food Safety Level 3 | C6: 46195 | D6: 22/06/2026
A7: Firos Latheef | B7: Positive Behaviour Support | C7: 46194 | D7: 21/06/2026
A8: Firos Latheef | B8: Managing Continence | C8: 46195 | D8: 22/06/2026
A9: Firos Latheef | B9: Oral Care | C9: 46195 | D9: 22/06/2026
A10: Firos Latheef | B10: COSHH | C10: 46195 | D10: 22/06/2026
A11: Chelsee Booth | B11: PEG Feeding | C11: 46197 | D11: 24/06/2026
A12: Chelsee Booth | B12: The Oliver McGowan Mandatory Training | C12: 46201 | D12: NS
A13: Chelsee Booth | B13: Care Planning | C13: 46194 | D13: 21/06/2026
... A75: Paula Merry | B75: A Care Workers Role | C75: 46191 | D75: 18/06/2026
A76: Paula Merry | B76: Recording Information | C76: 46195 | D76: 46192
A77: Paula Merry | B77: Dementia Awareness | C77: 46194 | D77: 21/06/2026
A78: Paula Merry | B78: Behaviours that Challenge | C78: 46194 | D78: 21/06/2026
A79: Paula Merry | B79: DeChoker | C79: 46193 | D79: 20/06/2026
A80: Paula Merry | B80: Diabetes Awareness | C80: 46194 | D80: 21/06/2026
A81: Paula Merry | B81: Mental Capacity | C81: 46194 | D81: 21/06/2026
A82: Paula Merry | B82: Complaints Handling | C82: 46193 | D82: 20/06/2026
A83: Paula Merry | B83: Dignity in Care | C83: 46192 | D83: 19/06/2026
A84: Paula Merry | B84: Communication | C84: 46192 | D84: 19/06/2026
A85: Paula Merry | B85: Accessible Information | C85: 46192 | D85: 19/06/2026
A86: Joel Jose | B86: Care Planning | C86: 46199 | D86: NS
A87: Nathan Thomas | B87: PEG Feeding | C87: 46199 | D87: NS
A88: Nathan Thomas | B88: The Oliver McGowan Mandatory Training | C88: 46195 | D88: 22/06/2026
... A106: Nathan Thomas | B106: Managing Continence | C106: 46199 | D106: NS
A107: Nathan Thomas | B107: Food Safety Level 3 | C107: 46194 | D107: 46199
A108: Nathan Thomas | B108: Basic Life Support | C108: 46184 | D108: 11/06/2026
A109: Nathan Thomas | B109: Equality, Diversity, Inclusion | C109: 46194 | D109: 21/06/2026
A110: Nathan Thomas | B110: Nutrition and Hydration | C110: 46195 | D110: 22/06/2026
A111: Nathan Thomas | B111: End of Life Care | C111: 46196 | D111: 23/06/2026
A112: Nathan Thomas | B112: Dysphagia | C112: 46196 | D112: 23/06/2026
A113: Nathan Thomas | B113: Oral Care | C113: 46195 | D113: 22/06/2026
A114: Nathan Thomas | B114: Safeguarding and Protection of Adults | C114: 46195 | D114: 22/06/2026
A115: Nathan Thomas | B115: A Care Workers Role | C115: 46195 | D115: 22/06/2026
A116: Nathan Thomas | B116: Behaviours that Challenge | C116: 46195 | D116: 22/06/2026
A117: Niranjala Dissanayake | B117: PEG Feeding | C117: 46196 | D117: 23/06/2026
A118: Niranjala Dissanayake | B118: Care Planning | C118: 46193 | D118: 20/06/2026
...

Sheet Renewal Rules
A1: Course | B1: Renewal Frequency (Months) | C1: Notes
A2: Care Certificate | B2: 36 | C2: Validity set to 36 months; next due date calculated automatically
A3: Food Hygiene | B3: 36 | C3: Validity set to 36 months; next due date calculated automatically
A4: Falls Awareness | B4: 12 | C4: Editable - used to support renewal/expiry review
A5: Basic Life Support | B5: 36 | C5: Validity set to 36 months; next due date calculated automatically
A6: Equality, Diversity, Inclusion | B6: 36 | C6: Validity set to 36 months; next due date calculated automatically
A7: PEG Feeding | B7: 12 | C7: Validity set to 12 months; next due date calculated automatically
A8: Nutrition and Hydration | B8: 36 | C8: Validity set to 36 months; next due date calculated automatically
A9: Duty of Care | B9: 36 | C9: Validity set to 36 months; next due date calculated automatically
A10: Health and Safety | B10: 12 | C10: Validity set to 12 months; next due date calculated automatically
A11: Communication and Record Keeping | B11: 36 | C11: Validity set to 36 months; next due date calculated automatically
A12: Risk Assessment | B12: 12 | C12: Validity set to 12 months; next due date calculated automatically
A13: Managing Continence | B13: 12 | C13: Validity set to 12 months; next due date calculated automatically
... A111: Sepsis | B111: 12 | C111: Validity set to 12 months; next due date calculated automatically

Sheet Training Due & RAG
A1: Training Due Date & RAG Tracker
A2: Staff Name | B2: Course | C2: Completed Date | D2: Validity (Months) | E2: Next Course Due | F2: Days Until Due | G2: RAG | H2: Status | I2: Evidence / Notes
A3: Niranjala Dissanayake | B3: Care Certificate | C3: =Matrix!B3 -> 46197 | D3: =IFERROR(VLOOKUP(B3,'Renewal Rules'!$A:$B,2,FALSE),"") -> 36 | E3: =IF(OR(C3="",C3="NS",C3="IP",C3="Failed"),"",IFERROR(EDATE(IF(ISNUMBER(C3),C3,IFERROR(DATEVALUE(C3),DATE(VALUE(RIGHT(C3,4)),VALUE(MID(C3,4,2)),VALUE(LEFT(C3,2))))),D3),"")) -> 47293 | F3: =IF(E3="","",E3-TODAY()) -> 1090 | G3: =IF(C3="NS","RED",IF(C3="IP","AMBER",IF(E3="","",IF(E3<TODAY(),"RED",IF(E3<=TODAY()+30,"AMBER","GREEN"))))) -> GREEN | H3: =IF(C3="NS","Not Started",IF(C3="IP","In Progress",IF(E3="","Check",IF(E3<TODAY(),"Expired",IF(E3<=TODAY()+30,"Expiring Soon","Current"))))) -> Current
A4: Niranjala Dissanayake | B4: Food Hygiene | C4: =Matrix!C3 -> NS | D4: =IFERROR(VLOOKUP(B4,'Renewal Rules'!$A:$B,2,FALSE),"") -> 36 | E4: =IF(OR(C4="",C4="NS",C4="IP",C4="Failed"),"",IFERROR(EDATE(IF(ISNUMBER(C4),C4,IFERROR(DATEVALUE(C4),DATE(VALUE(RIGHT(C4,4)),VALUE(MID(C4,4,2)),VALUE(LEFT(C4,2))))),D4),"")) | F4: =IF(E4="","",E4-TODAY()) | G4: =IF(C4="NS","RED",IF(C4="IP","AMBER",IF(E4="","",IF(E4<TODAY(),"RED",IF(E4<=TODAY()+30,"AMBER","GREEN"))))) -> RED | H4: =IF(C4="NS","Not Started",IF(C4="IP","In Progress",IF(E4="","Check",IF(E4<TODAY(),"Expired",IF(E4<=TODAY()+30,"Expiring Soon","Current"))))) -> Not Started
A5: Niranjala Dissanayake | B5: Falls Awareness | C5: =Matrix!D3 -> 46196 | D5: =IFERROR(VLOOKUP(B5,'Renewal Rules'!$A:$B,2,FALSE),"") -> 12 | E5: =IF(OR(C5="",C5="NS",C5="IP",C5="Failed"),"",IFERROR(EDATE(IF(ISNUMBER(C5),C5,IFERROR(DATEVALUE(C5),DATE(VALUE(RIGHT(C5,4)),VALUE(MID(C5,4,2)),VALUE(LEFT(C5,2))))),D5),"")) -> 46561 | F5: =IF(E5="","",E5-TODAY()) -> 358 | G5: =IF(C5="NS","RED",IF(C5="IP","AMBER",IF(E5="","",IF(E5<TODAY(),"RED",IF(E5<=TODAY()+30,"AMBER","GREEN"))))) -> GREEN | H5: =IF(C5="NS","Not Started",IF(C5="IP","In Progress",IF(E5="","Check",IF(E5<TODAY(),"Expired",IF(E5<=TODAY()+30,"Expiring Soon","Current"))))) -> Current
A6: Niranjala Dissanayake | B6: Basic Life Support | C6: =Matrix!E3 -> 46197 | D6: =IFERROR(VLOOKUP(B6,'Renewal Rules'!$A:$B,2,FALSE),"") -> 36 | E6: =IF(OR(C6="",C6="NS",C6="IP",C6="Failed"),"",IFERROR(EDATE(IF(ISNUMBER(C6),C6,IFERROR(DATEVALUE(C6),DATE(VALUE(RIGHT(C6,4)),VALUE(MID(C6,4,2)),VALUE(LEFT(C6,2))))),D6),"")) -> 47293 | F6: =IF(E6="","",E6-TODAY()) -> 1090 | G6: =IF(C6="NS","RED",IF(C6="IP","AMBER",IF(E6="","",IF(E6<TODAY(),"RED",IF(E6<=TODAY()+30,"AMBER","GREEN"))))) -> GREEN | H6: =IF(C6="NS","Not Started",IF(C6="IP","In Progress",IF(E6="","Check",IF(E6<TODAY(),"Expired",IF(E6<=TODAY()+30,"Expiring Soon","Current"))))) -> Current
A7: Niranjala Dissanayake | B7: Equality, Diversity, Inclusion | C7: =Matrix!F3 -> 46195 | D7: =IFERROR(VLOOKUP(B7,'Renewal Rules'!$A:$B,2,FALSE),"") -> 36 | E7: =IF(OR(C7="",C7="NS",C7="IP",C7="Failed"),"",IFERROR(EDATE(IF(ISNUMBER(C7),C7,IFERROR(DATEVALUE(C7),DATE(VALUE(RIGHT(C7,4)),VALUE(MID(C7,4,2)),VALUE(LEFT(C7,2))))),D7),"")) -> 47291 | F7: =IF(E7="","",E7-TODAY()) -> 1088 | G7: =IF(C7="NS","RED",IF(C7="IP","AMBER",IF(E7="","",IF(E7<TODAY(),"RED",IF(E7<=TODAY()+30,"AMBER","GREEN"))))) -> GREEN | H7: =IF(C7="NS","Not Started",IF(C7="IP","In Progress",IF(E7="","Check",IF(E7<TODAY(),"Expired",IF(E7<=TODAY()+30,"Expiring Soon","Current"))))) -> Current
A8: Niranjala Dissanayake | B8: PEG Feeding | C8: =Matrix!G3 -> 46196 | D8: =IFERROR(VLOOKUP(B8,'Renewal Rules'!$A:$B,2,FALSE),"") -> 12 | E8: =IF(OR(C8="",C8="NS",C8="IP",C8="Failed"),"",IFERROR(EDATE(IF(ISNUMBER(C8),C8,IFERROR(DATEVALUE(C8),DATE(VALUE(RIGHT(C8,4)),VALUE(MID(C8,4,2)),VALUE(LEFT(C8,2))))),D8),"")) -> 46561 | F8: =IF(E8="","",E8-TODAY()) -> 358 | G8: =IF(C8="NS","RED",IF(C8="IP","AMBER",IF(E8="","",IF(E8<TODAY(),"RED",IF(E8<=TODAY()+30,"AMBER","GREEN"))))) -> GREEN | H8: =IF(C8="NS","Not Started",IF(C8="IP","In Progress",IF(E8="","Check",IF(E8<TODAY(),"Expired",IF(E8<=TODAY()+30,"Expiring Soon","Current"))))) -> Current
A9: Niranjala Dissanayake | B9: Nutrition and Hydration | C9: =Matrix!H3 -> 46197 | D9: =IFERROR(VLOOKUP(B9,'Renewal Rules'!$A:$B,2,FALSE),"") -> 36 | E9: =IF(OR(C9="",C9="NS",C9="IP",C9="Failed"),"",IFERROR(EDATE(IF(ISNUMBER(C9),C9,IFERROR(DATEVALUE(C9),DATE(VALUE(RIGHT(C9,4)),VALUE(MID(C9,4,2)),VALUE(LEFT(C9,2))))),D9),"")) -> 47293 | F9: =IF(E9="","",E9-TODAY()) -> 1090 | G9: =IF(C9="NS","RED",IF(C9="IP","AMBER",IF(E9="","",IF(E9<TODAY(),"RED",IF(E9<=TODAY()+30,"AMBER","GREEN"))))) -> GREEN | H9: =IF(C9="NS","Not Started",IF(C9="IP","In Progress",IF(E9="","Check",IF(E9<TODAY(),"Expired",IF(E9<=TODAY()+30,"Expiring Soon","Current"))))) -> Current
A10: Niranjala Dissanayake | B10: Duty of Care | C10: =Matrix!I3 -> 46197 | D10: =IFERROR(VLOOKUP(B10,'Renewal Rules'!$A:$B,2,FALSE),"") -> 36 | E10: =IF(OR(C10="",C10="NS",C10="IP",C10="Failed"),"",IFERROR(EDATE(IF(ISNUMBER(C10),C10,IFERROR(DATEVALUE(C10),DATE(VALUE(RIGHT(C10,4)),VALUE(MID(C10,4,2)),VALUE(LEFT(C10,2))))),D10),"")) -> 47293 | F10: =IF(E10="","",E10-TODAY()) -> 1090 | G10: =IF(C10="NS","RED",IF(C10="IP","AMBER",IF(E10="","",IF(E10<TODAY(),"RED",IF(E10<=TODAY()+30,"AMBER","GREEN"))))) -> GREEN | H10: =IF(C10="NS","Not Started",IF(C10="IP","In Progress",IF(E10="","Check",IF(E10<TODAY(),"Expired",IF(E10<=TODAY()+30,"Expiring Soon","Current"))))) -> Current
A11: Niranjala Dissanayake | B11: Health and Safety | C11: =Matrix!J3 -> 46197 | D11: =IFERROR(VLOOKUP(B11,'Renewal Rules'!$A:$B,2,FALSE),"") -> 12 | E11: =IF(OR(C11="",C11="NS",C11="IP",C11="Failed"),"",IFERROR(EDATE(IF(ISNUMBER(C11),C11,IFERROR(DATEVALUE(C11),DATE(VALUE(RIGHT(C11,4)),VALUE(MID(C11,4,2)),VALUE(LEFT(C11,2))))),D11),"")) -> 46562 | F11: =IF(E11="","",E11-TODAY()) -> 359 | G11: =IF(C11="NS","RED",IF(C11="IP","AMBER",IF(E11="","",IF(E11<TODAY(),"RED",IF(E11<=TODAY()+30,"AMBER","GREEN"))))) -> GREEN | H11: =IF(C11="NS","Not Started",IF(C11="IP","In Progress",IF(E11="","Check",IF(E11<TODAY(),"Expired",IF(E11<=TODAY()+30,"Expiring Soon","Current"))))) -> Current
A12: Niranjala Dissanayake | B12: Communication and Record Keeping | C12: =Matrix!K3 -> 23/06/2026 | D12: =IFERROR(VLOOKUP(B12,'Renewal Rules'!$A:$B,2,FALSE),"") -> 36 | E12: =IF(OR(C12="",C12="NS",C12="IP",C12="Failed"),"",IFERROR(EDATE(IF(ISNUMBER(C12),C12,IFERROR(DATEVALUE(C12),DATE(VALUE(RIGHT(C12,4)),VALUE(MID(C12,4,2)),VALUE(LEFT(C12,2))))),D12),"")) -> 47292 | F12: =IF(E12="","",E12-TODAY()) -> 1089 | G12: =IF(C12="NS","RED",IF(C12="IP","AMBER",IF(E12="","",IF(E12<TODAY(),"RED",IF(E12<=TODAY()+30,"AMBER","GREEN"))))) -> GREEN | H12: =IF(C12="NS","Not Started",IF(C12="IP","In Progress",IF(E12="","Check",IF(E12<TODAY(),"Expired",IF(E12<=TODAY()+30,"Expiring Soon","Current"))))) -> Current
